Workbook

Sheet Index
B1: Index
B3: 구분 | C3: Sheet | D3: Link
B4: Overall | C4: Index | D4: Link
C5: Control
C6: DCF | D6: Link
B7: Sales | C7: Sales | D7: Link
C8: Sales Bridge | D8: Link
B9: Cost | C9: Cost | D9: Link
B10: Others | C10: CapEx, D&A | D10: Link
C11: Labor | D11: Link
C12: NWC | D12: Link
C13: BS | D13: Link
B14: Raw | C14: Dart_FS | D14: Link
C15: Dart_시장리서치 | D15: Link
C16: Dart_Labor | D16: Link
C17: Dart_Cost | D17: Link
C18: Dart_Sales | D18: Link
C19: Dart_중고차 Sales | D19: Link
C20: Dart_Capture | D20: Link

Sheet Control
B1: Control
B3: Equity Value | C3: =DCF!E39 -> 1786998.3
B4: per Share | C4: =DCF!E43 -> 38115.011
D6: Historical | J6: Forecast
B7: KRW in millions | D7: 2018 | E7: 2019 | F7: 2020 | G7: 2021.1H | H7: 2021.2H | I7: 2021 | J7: 2022 | K7: =J7+1 -> 2023 | L7: =K7+1 -> 2024 | M7: =L7+1 -> 2025 | N7: =M7+1 -> 2026
B8: Sales | D8: =DCF!D5 -> 742803 | E8: =DCF!E5 -> 1185356 | F8: =DCF!F5 -> 1323114 | G8: =DCF!G5 -> 910585 | H8: =DCF!H5 -> 910585 | I8: =DCF!I5 -> 1821170 | J8: =DCF!J5 -> 1902459 | K8: =DCF!K5 -> 2256380 | ... N8: =DCF!N5 -> 3792952.9
B9: EBITDA | D9: =DCF!D14 -> 18098.116 | E9: =DCF!E14 -> 42742.643 | F9: =DCF!F14 -> 53572.583 | G9: =DCF!G14 -> 58203.291 | H9: =DCF!H14 -> 58203.291 | I9: =DCF!I14 -> 116406.58 | J9: =DCF!J14 -> 149588.77 | K9: =DCF!K14 -> 175638.61 | ... N9: =DCF!N14 -> 282570.99
B10: FCFF | D10: =DCF!D23 -> 9548.2327 | E10: =DCF!E23 -> 8606.395 | F10: =DCF!F23 -> 33697.41 | G10: =DCF!G23 -> 53519.88 | H10: =DCF!H23 -> 46847.13 | I10: =DCF!I23 -> 100367.01 | J10: =DCF!J23 -> 46648.239 | K10: =DCF!K23 -> 113334.54 | ... N10: =DCF!N23 -> 150980.08
B13: Sales_이커머스 중고차판매 | J13: 2022 | K13: =J13+1 -> 2023 | L13: =K13+1 -> 2024 | M13: =L13+1 -> 2025 | N13: =M13+1 -> 2026
B15: SUV(이커머스) P growth | J15: 0.01 | K15: 0.01 | L15: 0.01 | M15: 0.01 | N15: 0.01
B16: SUV(이커머스) 시장 Q growth | J16: 0.1 | K16: 0.1 | L16: 0.1 | M16: 0.1 | N16: 0.1
B17: SUV(이커머스) 케이카 점유율 | J17: 0.6 | K17: 0.6 | L17: 0.6 | M17: 0.6 | N17: 0.6
B18: 대형(이커머스) P growth | J18: 0.01 | K18: 0.01 | L18: 0.01 | M18: 0.01 | N18: 0.01
B19: 대형(이커머스) 시장 Q growth | J19: 0.1 | K19: 0.1 | L19: 0.1 | M19: 0.1 | N19: 0.1
B20: 대형(이커머스) 케이카 점유율 | J20: 0.6 | K20: 0.6 | L20: 0.6 | M20: 0.6 | N20: 0.6
B21: 중형(이커머스) P growth | J21: 0.01 | K21: 0.01 | L21: 0.01 | M21: 0.01 | N21: 0.01
B22: 중형(이커머스) 시장 Q growth | J22: 0.1 | K22: 0.1 | L22: 0.1 | M22: 0.1 | N22: 0.1
B23: 중형(이커머스) 케이카 점유율 | J23: 0.6 | K23: 0.6 | L23: 0.6 | M23: 0.6 | N23: 0.6
B24: 준중형(이커머스) P growth | J24: 0.01 | K24: 0.01 | L24: 0.01 | M24: 0.01 | N24: 0.01
B25: 준중형(이커머스) 시장 Q growth | J25: 0.2 | K25: 0.2 | L25: 0.2 | M25: 0.2 | N25: 0.2
B26: 준중형(이커머스) 케이카 점유율 | J26: 0.6 | K26: 0.6 | L26: 0.6 | M26: 0.6 | N26: 0.6
... B35: 기타(이커머스) 케이카 점유율 | J35: 0.6 | K35: 0.6 | L35: 0.6 | M35: 0.6 | N35: 0.6
B37: Sales_지점내방 중고차판매 | J37: 2022 | K37: =J37+1 -> 2023 | L37: =K37+1 -> 2024 | M37: =L37+1 -> 2025 | N37: =M37+1 -> 2026
B39: SUV(지점내방) P growth | J39: 0.01 | K39: 0.01 | L39: 0.01 | M39: 0.01 | N39: 0.01
B40: SUV(지점내방) 시장 Q growth | J40: 0.2 | K40: 0.2 | L40: 0.2 | M40: 0.2 | N40: 0.2
B41: SUV(지점내방) 케이카 점유율 | J41: 0.02 | K41: 0.02 | L41: 0.02 | M41: 0.02 | N41: 0.02
B42: 대형(지점내방) P growth | J42: 0.01 | K42: 0.01 | L42: 0.01 | M42: 0.01 | N42: 0.01
B43: 대형(지점내방) 시장 Q growth | J43: 0.2 | K43: 0.2 | L43: 0.2 | M43: 0.2 | N43: 0.2
B44: 대형(지점내방) 케이카 점유율 | J44: 0.02 | K44: 0.02 | L44: 0.02 | M44: 0.02 | N44: 0.02
B45: 중형(지점내방) P growth | J45: 0.01 | K45: 0.01 | L45: 0.01 | M45: 0.01 | N45: 0.01
B46: 중형(지점내방) 시장 Q growth | J46: 0.2 | K46: 0.2 | L46: 0.2 | M46: 0.2 | N46: 0.2
B47: 중형(지점내방) 케이카 점유율 | J47: 0.02 | K47: 0.02 | L47: 0.02 | M47: 0.02 | N47: 0.02
B48: 준중형(지점내방) P growth | J48: 0.01 | K48: 0.01 | L48: 0.01 | M48: 0.01 | N48: 0.01
B49: 준중형(지점내방) 시장 Q growth | J49: 0.2 | K49: 0.2 | L49: 0.2 | M49: 0.2 | N49: 0.2
B50: 준중형(지점내방) 케이카 점유율 | J50: 0.02 | K50: 0.02 | L50: 0.02 | M50: 0.02 | N50: 0.02
... B59: 기타(지점내방) 케이카 점유율 | J59: 0.02 | K59: 0.02 | L59: 0.02 | M59: 0.02 | N59: 0.02
B61: Sales_기타가정 | J61: 2022 | K61: =J61+1 -> 2023 | L61: =K61+1 -> 2024 | M61: =L61+1 -> 2025 | N61: =M61+1 -> 2026
B63: 경매(상품)매출 성장률 | J63: 0.2 | K63: 0.2 | L63: 0.2 | M63: 0.2 | N63: 0.2
B64: 경매(용역)매출 성장률 | J64: 0.2 | K64: 0.2 | L64: 0.2 | M64: 0.2 | N64: 0.2
B65: 렌터카 매각 매출 성장률 | J65: 0.2 | K65: 0.2 | L65: 0.2 | M65: 0.2 | N65: 0.2
...

Sheet DCF
B1: DCF_케이카 | E1: Index
D3: Historical | H3: - | I3: Forecast
B4: KRW in millions | D4: =Sales!I4 -> 2018 | E4: =Sales!J4 -> 2019 | F4: =Sales!K4 -> 2020 | G4: =Sales!L4 -> 2021.1H | H4: =Sales!M4 -> 2021.2H | I4: =Sales!N4 -> 2021 | J4: =Sales!O4 -> 2022 | K4: =Sales!P4 -> 2023 | ... N4: =Sales!S4 -> 2026
B5: Sales | D5: =Sales!I160 -> 742803 | E5: =Sales!J160 -> 1185356 | F5: =Sales!K160 -> 1323114 | G5: =Sales!L160 -> 910585 | H5: =Sales!M160 -> 910585 | I5: =Sales!N160 -> 1821170 | J5: =Sales!O160 -> 1902459 | K5: =Sales!P160 -> 2256380 | ... N5: =Sales!S160 -> 3792952.9
C6: %YoY | E6: =E5/D5-1 -> 0.59578785 | F6: =F5/E5-1 -> 0.11621656 | G6: =G5/F5-1 -> -0.31178644 | H6: =H5/G5-1 -> 0 | I6: =I5/H5-1 -> 1 | J6: =J5/I5-1 -> 0.044635601 | K6: =K5/J5-1 -> 0.18603344 | L6: =L5/K5-1 -> 0.18757189 | ... N6: =N5/M5-1 -> 0.19044206
B7: Cost | D7: =Cost!E57 -> 732137.26 | E7: =Cost!F57 -> 1156150.8 | F7: =Cost!G57 -> 1285415.4 | G7: =Cost!H57 -> 872106.02 | H7: =Cost!I57 -> 872106.02 | I7: =Cost!J57 -> 1744212 | J7: =Cost!K57 -> 1786540 | K7: =Cost!L57 -> 2111660.9 | ... N7: =Cost!O57 -> 3536128.4
C8: % of Sales | D8: =D7/D$5 -> 0.98564123 | E8: =E7/E$5 -> 0.97536167 | F8: =F7/F$5 -> 0.97150766 | G8: =G7/G$5 -> 0.95774258 | H8: =H7/H$5 -> 0.95774258 | I8: =I7/I$5 -> 0.95774258 | J8: =J7/J$5 -> 0.93906886 | K8: =K7/K$5 -> 0.93586227 | ... N8: =N7/N$5 -> 0.93228901
B9: EBIT | D9: =D5-D7 -> 10665.739 | E9: =E5-E7 -> 29205.187 | F9: =F5-F7 -> 37698.611 | G9: =G5-G7 -> 38478.975 | H9: =H5-H7 -> 38478.975 | I9: =I5-I7 -> 76957.95 | J9: =J5-J7 -> 115919 | K9: =K5-K7 -> 144719.1 | ... N9: =N5-N7 -> 256824.59
C10: % of Sales | D10: =D9/D$5 -> 0.014358772 | E10: =E9/E$5 -> 0.024638326 | F10: =F9/F$5 -> 0.028492338 | G10: =G9/G$5 -> 0.042257423 | H10: =H9/H$5 -> 0.042257423 | I10: =I9/I$5 -> 0.042257423 | J10: =J9/J$5 -> 0.060931142 | K10: =K9/K$5 -> 0.064137735 | ... N10: =N9/N$5 -> 0.067710987
B11: D&A | D11: =D12+D13 -> 7432.3771 | E11: =E12+E13 -> 13537.456 | F11: =F12+F13 -> 15873.972 | G11: =G12+G13 -> 19724.316 | H11: =H12+H13 -> 19724.316 | I11: =I12+I13 -> 39448.632 | J11: =J12+J13 -> 33669.772 | K11: =K12+K13 -> 30919.503 | ... N11: =N12+N13 -> 25746.402
C12: Depreciation | D12: ='CapEx,D&A'!F9 -> 6680.6336 | E12: ='CapEx,D&A'!G9 -> 12256.755 | F12: ='CapEx,D&A'!H9 -> 14214.472 | G12: ='CapEx,D&A'!I9 -> 18802.028 | H12: ='CapEx,D&A'!J9 -> 18802.028 | I12: ='CapEx,D&A'!K9 -> 37604.056 | J12: ='CapEx,D&A'!L9 -> 32110.436 | K12: ='CapEx,D&A'!M9 -> 29350.294 | ... N12: ='CapEx,D&A'!P9 -> 24142.297
C13: Amortizaton | D13: ='CapEx,D&A'!F10 -> 751.74352 | E13: ='CapEx,D&A'!G10 -> 1280.7009 | F13: ='CapEx,D&A'!H10 -> 1659.4994 | G13: ='CapEx,D&A'!I10 -> 922.28807 | H13: ='CapEx,D&A'!J10 -> 922.28807 | I13: ='CapEx,D&A'!K10 -> 1844.5761 | J13: ='CapEx,D&A'!L10 -> 1559.336 | K13: ='CapEx,D&A'!M10 -> 1569.2089 | ... N13: ='CapEx,D&A'!P10 -> 1604.1048
B14: EBITDA | D14: =D9+D11 -> 18098.116 | E14: =E9+E11 -> 42742.643 | F14: =F9+F11 -> 53572.583 | G14: =G9+G11 -> 58203.291 | H14: =H9+H11 -> 58203.291 | I14: =I9+I11 -> 116406.58 | J14: =J9+J11 -> 149588.77 | K14: =K9+K11 -> 175638.61 | ... N14: =N9+N11 -> 282570.99
C15: % of Sales | D15: =D14/D$5 -> 0.024364624 | E15: =E14/E$5 -> 0.036058908 | F15: =F14/F$5 -> 0.040489771 | G15: =G14/G$5 -> 0.06391857 | H15: =H14/H$5 -> 0.06391857 | I15: =I14/I$5 -> 0.06391857 | J15: =J14/J$5 -> 0.07862917 | K15: =K14/K$5 -> 0.07784088 | ... N15: =N14/N$5 -> 0.074498944
B16: Tax | D16: =D9*D17 -> 2346.4626 | E16: =E9*E17 -> 7067.6553 | F16: =F9*F17 -> 9123.0639 | G16: =G9*G17 -> 9311.912 | H16: =H9*H17 -> 9311.912 | I16: =I9*I17 -> 18623.824 | J16: =J9*J17 -> 28052.398 | K16: =K9*K17 -> 35022.023 | ... N16: =N9*N17 -> 62151.55
C17: Marginal tax rate | D17: =IF(D9<=200, 11%, IF(D9<=20000, 22%, IF(D9<300000, 24.2%, 27.5%))) -> 0.22 | E17: =IF(E9<=200, 11%, IF(E9<=20000, 22%, IF(E9<300000, 24.2%, 27.5%))) -> 0.242 | F17: =IF(F9<=200, 11%, IF(F9<=20000, 22%, IF(F9<300000, 24.2%, 27.5%))) -> 0.242 | G17: =IF(G9<=200, 11%, IF(G9<=20000, 22%, IF(G9<300000, 24.2%, 27.5%))) -> 0.242 | H17: =IF(H9<=200, 11%, IF(H9<=20000, 22%, IF(H9<300000, 24.2%, 27.5%))) -> 0.242 | I17: =IF(I9<=200, 11%, IF(I9<=20000, 22%, IF(I9<300000, 24.2%, 27.5%))) -> 0.242 | J17: =IF(J9<=200, 11%, IF(J9<=20000, 22%, IF(J9<300000, 24.2%, 27.5%))) -> 0.242 | K17: =IF(K9<=200, 11%, IF(K9<=20000, 22%, IF(K9<300000, 24.2%, 27.5%))) -> 0.242 | ... N17: =IF(N9<=200, 11%, IF(N9<=20000, 22%, IF(N9<300000, 24.2%, 27.5%))) -> 0.242
B18: EBIT(1-t) | D18: =D9-D16 -> 8319.2763 | E18: =E9-E16 -> 22137.532 | F18: =F9-F16 -> 28575.547 | G18: =G9-G16 -> 29167.063 | H18: =H9-H16 -> 29167.063 | I18: =I9-I16 -> 58334.126 | J18: =J9-J16 -> 87866.603 | K18: =K9-K16 -> 109697.08 | ... N18: =N9-N16 -> 194673.04
C19: % of Sales | D19: =D18/D$5 -> 0.011199842 | E19: =E18/E$5 -> 0.018675851 | F19: =F18/F$5 -> 0.021597192 | G19: =G18/G$5 -> 0.032031126 | H19: =H18/H$5 -> 0.032031126 | I19: =I18/I$5 -> 0.032031126 | J19: =J18/J$5 -> 0.046185806 | K19: =K18/K$5 -> 0.048616403 | ... N19: =N18/N$5 -> 0.051324928
C20: (+) D&A | D20: =D11 -> 7432.3771 | E20: =E11 -> 13537.456 | F20: =F11 -> 15873.972 | G20: =G11 -> 19724.316 | H20: =H11 -> 19724.316 | I20: =I11 -> 39448.632 | J20: =J11 -> 33669.772 | K20: =K11 -> 30919.503 | ... N20: =N11 -> 25746.402
C21: (-) CapEx | D21: ='CapEx,D&A'!F5 -> 6203.4207 | E21: ='CapEx,D&A'!G5 -> 4496.4141 | F21: ='CapEx,D&A'!H5 -> 2238.3799 | G21: ='CapEx,D&A'!I5 -> 2044.2493 | H21: ='CapEx,D&A'!J5 -> 2044.2493 | I21: ='CapEx,D&A'!K5 -> 4088.4986 | J21: ='CapEx,D&A'!L5 -> 4256.2992 | K21: ='CapEx,D&A'!M5 -> 4469.1141 | ... N21: ='CapEx,D&A'!P5 -> 5173.5582
C22: (-) △NWC | E22: =NWC!F22 -> 22572.179 | F22: =NWC!G22 -> 8513.7289 | G22: =NWC!H22 -> -6672.7502 | H22: =NWC!I22 -> 0 | I22: =NWC!J22 -> -6672.7502 | J22: =NWC!K22 -> 70631.837 | K22: =NWC!L22 -> 22812.933 | L22: =NWC!M22 -> 44703.84 | ... N22: =NWC!O22 -> 64265.799
B23: FCFF | D23: =D18+D20-D21-D22 -> 9548.2327 | E23: =E18+E20-E21-E22 -> 8606.395 | F23: =F18+F20-F21-F22 -> 33697.41 | G23: =G18+G20-G21-G22 -> 53519.88 | H23: =H18+H20-H21-H22 -> 46847.13 | I23: =I18+I20-I21-I22 -> 100367.01 | J23: =J18+J20-J21-J22 -> 46648.239 | K23: =K18+K20-K21-K22 -> 113334.54 | ... N23: =N18+N20-N21-N22 -> 150980.08
C24: Partial Period Factor | H24: 0.5 | J24: 1 | K24: 1 | L24: 1 | M24: 1 | N24: 1
C25: Mid-year convention | H25: =H24/2 -> 0.25 | J25: =SUM($H$24:I24)+J24/2 -> 1 | K25: =SUM($H$24:J24)+K24/2 -> 2 | L25: =SUM($H$24:K24)+L24/2 -> 3 | M25: =SUM($H$24:L24)+M24/2 -> 4 | N25: =SUM($H$24:M24)+N24/2 -> 5
C26: Present value factor | H26: =1/(1+$E$29)^H25 -> 0.97645409 | J26: =1/(1+$E$29)^J25 -> 0.90909091 | K26: =1/(1+$E$29)^K25 -> 0.82644628 | L26: =1/(1+$E$29)^L25 -> 0.7513148 | M26: =1/(1+$E$29)^M25 -> 0.68301346 | N26: =1/(1+$E$29)^N25 -> 0.62092132
B27: Discounted FCFF | H27: =H23*H26 -> 45744.071 | J27: =J23*J26 -> 42407.49 | K27: =K23*K26 -> 93664.906 | L27: =L23*L26 -> 85320.773 | M27: =M23*M26 -> 89196.319 | N27: =N23*N26 -> 93746.752
B29: WACC | E29: 0.1
B30: Terminal growth rate | E30: 0.02
B32: Equity value | G32: Sensitivity Analysis
B33: KRW in millions | I33: WACC
B34: Present Values of Free Cash Flow | E34: =SUM(H27:N27) -> 450080.31 | H34: =E43 -> 38115.011 | I34: 0.08 | J34: 0.09 | K34: 0.1 | L34: 0.11 | M34: 0.12
B35: Terminal Values | E35: =N18/(E29-E30)*N26 -> 1510958 | H35: 0.01 | I35: 46793.795 | J35: 39882.807 | K35: 34534.197 | L35: 30277.91 | M35: 26814.902
B36: Operating Business Value | E36: =E34+E35 -> 1961038.3 | G36: Terminal | H36: 0.015 | I36: 49899.195 | J36: 42131.675 | K36: 36219.286 | L36: 31574.819 | M36: 27834.845
B37: Plus: Non-operating Assets | G37: growth ratio | H37: 0.02 | I37: 53522.162 | J37: 44701.811 | K37: 38115.011 | L37: 33015.828 | M37: 28956.781
B38: Less: Net debt | E38: =BS!H24+BS!H26+BS!H28+BS!H31+BS!H34-BS!H6-BS!H8 -> 174040.05 | H38: 0.025 | I38: 57803.85 | J38: 47667.351 | K38: 40263.5 | L38: 34626.367 | M38: 30196.817
B39: Equity value | E39: =E36+E37-E38 -> 1786998.3 | H39: 0.03 | I39: 62941.876 | J39: 51127.148 | K39: 42718.916 | L39: 36438.224 | M39: 31574.633
B40: 유통주식수(주) | E40: =E41-E42 -> 46884369
C41: 총발행주식수(주) | E41: 46884369
C42: 자기주식수(주) | E42: 0
B43: per share(KRW) | E43: =(E39*10^6/E40) -> 38115.011

Sheet Sales
B1: Sales_bottom up | I1: Index
I3: Historical | N3: Forecast
B4: KRW in millions | I4: 2018 | J4: 2019 | K4: 2020 | L4: 2021.1H | M4: 2021.2H | N4: 2021 | O4: 2022 | P4: =O4+1 -> 2023 | Q4: =P4+1 -> 2024 | R4: =Q4+1 -> 2025 | S4: =R4+1 -> 2026
B5: 중고차 | I5: =I8+I74 -> 674404 | J5: =J8+J74 -> 1070801 | K5: =K8+K74 -> 1184650 | L5: =L8+L74 -> 792061 | M5: =M8+M74 -> 792061 | N5: =N8+N74 -> 1584122 | O5: =O8+O74 -> 1630322.7 | P5: =P8+P74 -> 1930634.3 | ... S5: =S8+S74 -> 3233329.1
C6: % YoY | J6: =J5/(I5/9*12)-1 -> 0.19083035 | K6: =K5/J5-1 -> 0.10632134 | L6: =(L5*2)/K5-1 -> 0.33720677 | M6: =L6 -> 0.33720677 | N6: =N5/K5-1 -> 0.33720677 | O6: =O5/N5-1 -> 0.029164866 | P6: =P5/O5-1 -> 0.18420375 | Q6: =Q5/P5-1 -> 0.18592203 | R6: =R5/Q5-1 -> 0.18756954 | S6: =S5/R5-1 -> 0.18914471
C7: 중고차 판매대수 | I7: =I10+I76 -> 52196 | J7: =J10+J76 -> 84328 | K7: =K10+K76 -> 90149 | L7: =L10+L76 -> 54426 | M7: =M10+M76 -> 54426 | N7: =N10+N76 -> 108852 | O7: =O10+O76 -> 111343.67 | P7: =P10+P76 -> 131007.24 | ... S7: =S10+S76 -> 215003.75
C8: 이커머스 중고차판매 | I8: =I11+I20+I29+I38+I47+I56+I65 -> 155662 | J8: =J11+J20+J29+J38+J47+J56+J65 -> 284782 | K8: =K11+K20+K29+K38+K47+K56+K65 -> 408225 | L8: =L11+L20+L29+L38+L47+L56+L65 -> 322919 | M8: =M11+M20+M29+M38+M47+M56+M65 -> 322919 | N8: =N11+N20+N29+N38+N47+N56+N65 -> 645838 | O8: =O11+O20+O29+O38+O47+O56+O65 -> 645658.78 | P8: =P11+P20+P29+P38+P47+P56+P65 -> 737221.59 | ... S8: =S11+S20+S29+S38+S47+S56+S65 -> 1108624.7
D9: % YoY | J9: =J8/(I8/9*12)-1 -> 0.37211715 | K9: =K8/J8-1 -> 0.4334649 | L9: =(L8*2)/K8-1 -> 0.58206381 | M9: =L9 -> 0.58206381 | N9: =N8/K8-1 -> 0.58206381 | O9: =O8/N8-1 -> -0.00027750151 | P9: =P8/O8-1 -> 0.141813 | Q9: =Q8/P8-1 -> 0.14370707 | R9: =R8/Q8-1 -> 0.14566007 | S9: =S8/R8-1 -> 0.14766708
D10: 이커머스 판매대수 | I10: =I15+I24+I33+I42+I51+I60+I69 -> 12700 | J10: =J15+J24+J33+J42+J51+J60+J69 -> 22554 | K10: =K15+K24+K33+K42+K51+K60+K69 -> 31274 | L10: =L15+L24+L33+L42+L51+L60+L69 -> 22920 | M10: =M15+M24+M33+M42+M51+M60+M69 -> 22920 | N10: =N15+N24+N33+N42+N51+N60+N69 -> 45840 | O10: =O15+O24+O33+O42+O51+O60+O69 -> 45871.669 | P10: =P15+P24+P33+P42+P51+P60+P69 -> 52440.838 | ... S10: =S15+S24+S33+S42+S51+S60+S69 -> 79241.014
D11: SUV(이커머스) | I11: =I15*I13/1000 -> 41558 | J11: =J15*J13/1000 -> 81857 | K11: =K15*K13/1000 -> 120580 | L11: =L15*L13/1000 -> 98632 | M11: =M15*M13/1000 -> 98632 | N11: =N15*N13/1000 -> 197264 | O11: =O15*O13/1000 -> 192195.55 | P11: =P15*P13/1000 -> 213529.26 | ... S11: =S15*S13/1000 -> 292819.22
E12: % YoY | J12: =J11/(I11/9*12)-1 -> 0.47727874 | K12: =K11/J11-1 -> 0.47305667 | L12: =(L11*2)/K11-1 -> 0.63595953 | M12: =L12 -> 0.63595953 | N12: =N11/K11-1 -> 0.63595953 | O12: =O11/N11-1 -> -0.025693717 | P12: =P11/O11-1 -> 0.111 | Q12: =Q11/P11-1 -> 0.111 | R12: =R11/Q11-1 -> 0.111 | S12: =S11/R11-1 -> 0.111
E13: 가격(천원) | I13: ='Dart_중고차 Sales'!D47 -> 15767.147 | J13: ='Dart_중고차 Sales'!E47 -> 15772.841 | K13: ='Dart_중고차 Sales'!F47 -> 16122.497 | L13: ='Dart_중고차 Sales'!G47 -> 17629.367 | M13: =L13 -> 17629.367 | N13: =M13 -> 17629.367 | O13: =(1+Control!J15)*N13 -> 17805.661 | P13: =(1+Control!K15)*O13 -> 17983.717 | Q13: =(1+Control!L15)*P13 -> 18163.554 | R13: =(1+Control!M15)*Q13 -> 18345.19 | S13: =(1+Control!N15)*R13 -> 18528.642
F14: % YoY | J14: =J13/(I13)-1 -> 0.00036115145 | K14: =K13/J13-1 -> 0.022168189 | L14: =(L13)/K13-1 -> 0.093463827 | M14: =L14 -> 0.093463827 | N14: =N13/K13-1 -> 0.093463827 | O14: =O13/N13-1 -> 0.01 | P14: =P13/O13-1 -> 0.01 | Q14: =Q13/P13-1 -> 0.01 | R14: =R13/Q13-1 -> 0.01 | S14: =S13/R13-1 -> 0.01
E15: 판매대수(대) | I15: ='Dart_중고차 Sales'!D36 -> 2635.7336 | J15: ='Dart_중고차 Sales'!E36 -> 5189.7434 | K15: ='Dart_중고차 Sales'!F36 -> 7478.9905 | L15: ='Dart_중고차 Sales'!G36 -> 5594.7556 | M15: =L15 -> 5594.7556 | N15: =L15+M15 -> 11189.511 | O15: =O17*O19 -> 10794.07 | P15: =P17*P19 -> 11873.477 | Q15: =Q17*Q19 -> 13060.825 | R15: =R17*R19 -> 14366.908 | S15: =S17*S19 -> 15803.598
F16: % YoY | J16: =J15/(I15/9*12)-1 -> 0.47674541 | K16: =K15/J15-1 -> 0.44110988 | L16: =(L15*2)/K15-1 -> 0.49612588 | M16: =L16 -> 0.49612588 | N16: =N15/K15-1 -> 0.49612588 | O16: =O15/N15-1 -> -0.035340314 | P16: =P15/O15-1 -> 0.1 | Q16: =Q15/P15-1 -> 0.1 | R16: =R15/Q15-1 -> 0.1 | S16: =S15/R15-1 -> 0.1
G17: 시장판매대수(대) | I17: =I15/I19 -> 3528.1474 | J17: =J15/J19 -> 5522.4724 | K17: =K15/K19 -> 9565.7613 | L17: =L15/L19 -> 8177.326 | M17: =M15/M19 -> 8177.326 | N17: =L17+M17 -> 16354.652 | O17: =(1+Control!J16)*N17 -> 17990.117 | P17: =(1+Control!K16)*O17 -> 19789.129 | Q17: =(1+Control!L16)*P17 -> 21768.042 | R17: =(1+Control!M16)*Q17 -> 23944.846 | S17: =(1+Control!N16)*R17 -> 26339.331
H18: % YoY | J18: =J17/I17-1 -> 0.56526125 | K18: =K17/J17-1 -> 0.73215196 | L18: =(L17*2)/K17-1 -> 0.70970731 | M18: =L18 -> 0.70970731 | N18: =N17/K17-1 -> 0.70970731 | O18: =O17/N17-1 -> 0.1 | P18: =P17/O17-1 -> 0.1 | Q18: =Q17/P17-1 -> 0.1 | R18: =R17/Q17-1 -> 0.1 | S18: =S17/R17-1 -> 0.1
G19: 점유율 | I19: =Dart_시장리서치!F$43 -> 0.74705882 | J19: =Dart_시장리서치!G$43 -> 0.93975 | K19: =Dart_시장리서치!H$43 -> 0.78185 | L19: =Dart_시장리서치!I$43 -> 0.6841791 | M19: =L19 -> 0.6841791 | N19: =M19 -> 0.6841791 | O19: =Control!J17 -> 0.6 | P19: =Control!K17 -> 0.6 | Q19: =Control!L17 -> 0.6 | R19: =Control!M17 -> 0.6 | S19: =Control!N17 -> 0.6
D20: 대형(이커머스) | I20: =I24*I22/1000 -> 32669 | J20: =J24*J22/1000 -> 59689 | K20: =K24*K22/1000 -> 82519 | L20: =L24*L22/1000 -> 68474 | M20: =M24*M22/1000 -> 68474 | N20: =N24*N22/1000 -> 136948 | O20: =O24*O22/1000 -> 133429.3 | P20: =P24*P22/1000 -> 148239.95 | ... S20: =S24*S22/1000 -> 203285.98
E21: % YoY | J21: =J20/(I20/9*12)-1 -> 0.37031283 | K21: =K20/J20-1 -> 0.38248253 | L21: =(L20*2)/K20-1 -> 0.65959355 | M21: =L21 -> 0.65959355 | N21: =N20/K20-1 -> 0.65959355 | O21: =O20/N20-1 -> -0.025693717 | P21: =P20/O20-1 -> 0.111 | Q21: =Q20/P20-1 -> 0.111 | R21: =R20/Q20-1 -> 0.111 | S21: =S20/R20-1 -> 0.111
E22: 가격(천원) | I22: ='Dart_중고차 Sales'!D48 -> 17143.606 | J22: ='Dart_중고차 Sales'!E48 -> 17814.302 | K22: ='Dart_중고차 Sales'!F48 -> 18333.616 | L22: ='Dart_중고차 Sales'!G48 -> 19158.988 | M22: =L22 -> 19158.988 | N22: =M22 -> 19158.988 | O22: =(1+Control!J18)*N22 -> 19350.578 | P22: =(1+Control!K18)*O22 -> 19544.084 | Q22: =(1+Control!L18)*P22 -> 19739.525 | R22: =(1+Control!M18)*Q22 -> 19936.92 | S22: =(1+Control!N18)*R22 -> 20136.289
F23: % YoY | J23: =J22/(I22)-1 -> 0.039122183 | K23: =K22/J22-1 -> 0.029151541 | L23: =(L22)/K22-1 -> 0.045019596 | M23: =L23 -> 0.045019596 | N23: =N22/K22-1 -> 0.045019596 | O23: =O22/N22-1 -> 0.01 | P23: =P22/O22-1 -> 0.01 | Q23: =Q22/P22-1 -> 0.01 | R23: =R22/Q22-1 -> 0.01 | S23: =S22/R22-1 -> 0.01
E24: 판매대수(대) | I24: ='Dart_중고차 Sales'!D37 -> 1905.6084 | J24: ='Dart_중고차 Sales'!E37 -> 3350.6225 | K24: ='Dart_중고차 Sales'!F37 -> 4500.9669 | L24: ='Dart_중고차 Sales'!G37 -> 3573.9883 | M24: =L24 -> 3573.9883 | N24: =L24+M24 -> 7147.9767 | O24: =O26*O28 -> 6895.3649 | P24: =P26*P28 -> 7584.9014 | Q24: =Q26*Q28 -> 8343.3916 | R24: =R26*R28 -> 9177.7307 | S24: =S26*S28 -> 10095.504
F25: % YoY | J25: =J24/(I24/9*12)-1 -> 0.31872157 | K25: =K24/J24-1 -> 0.34332261 | L25: =(L24*2)/K24-1 -> 0.58809802 | M25: =L25 -> 0.58809802 | N25: =N24/K24-1 -> 0.58809802 | O25: =O24/N24-1 -> -0.035340314 | P25: =P24/O24-1 -> 0.1 | Q25: =Q24/P24-1 -> 0.1 | R25: =R24/Q24-1 -> 0.1 | S25: =S24/R24-1 -> 0.1
G26: 시장판매대수(대) | I26: =I24/I28 -> 2550.8144 | J26: =J24/J28 -> 3565.4403 | K26: =K24/K28 -> 5756.8165 | L26: =L24/L28 -> 5223.7613 | M26: =M24/M28 -> 5223.7613 | N26: =L26+M26 -> 10447.523 | O26: =(1+Control!J19)*N26 -> 11492.275 | P26: =(1+Control!K19)*O26 -> 12641.502 | Q26: =(1+Control!L19)*P26 -> 13905.653 | R26: =(1+Control!M19)*Q26 -> 15296.218 | S26: =(1+Control!N19)*R26 -> 16825.84
H27: % YoY | J27: =J26/I26-1 -> 0.39776548 | K27: =K26/J26-1 -> 0.61461588 | L27: =(L26*2)/K26-1 -> 0.81480906 | M27: =L27 -> 0.81480906 | N27: =N26/K26-1 -> 0.81480906 | O27: =O26/N26-1 -> 0.1 | P27: =P26/O26-1 -> 0.1 | Q27: =Q26/P26-1 -> 0.1 | R27: =R26/Q26-1 -> 0.1 | S27: =S26/R26-1 -> 0.1
G28: 점유율 | I28: =Dart_시장리서치!F$43 -> 0.74705882 | J28: =Dart_시장리서치!G$43 -> 0.93975 | K28: =Dart_시장리서치!H$43 -> 0.78185 | L28: =Dart_시장리서치!I$43 -> 0.6841791 | M28: =L28 -> 0.6841791 | N28: =M28 -> 0.6841791 | O28: =Control!J20 -> 0.6 | P28: =Control!K20 -> 0.6 | Q28: =Control!L20 -> 0.6 | R28: =Control!M20 -> 0.6 | S28: =Control!N20 -> 0.6
D29: 중형(이커머스) | I29: =I33*I31/1000 -> 31693 | J29: =J33*J31/1000 -> 55817 | K29: =K33*K31/1000 -> 82069 | L29: =L33*L31/1000 -> 63151 | M29: =M33*M31/1000 -> 63151 | N29: =N33*N31/1000 -> 126302 | O29: =O33*O31/1000 -> 123056.83 | P29: =P33*P31/1000 -> 136716.14 | ... S29: =S33*S31/1000 -> 187483.03
E30: % YoY | J30: =J29/(I29/9*12)-1 -> 0.32088316 | K30: =K29/J29-1 -> 0.47032266 | L30: =(L29*2)/K29-1 -> 0.5389733 | M30: =L30 -> 0.5389733 | N30: =N29/K29-1 -> 0.5389733 | O30: =O29/N29-1 -> -0.025693717 | P30: =P29/O29-1 -> 0.111 | Q30: =Q29/P29-1 -> 0.111 | R30: =R29/Q29-1 -> 0.111 | S30: =S29/R29-1 -> 0.111
E31: 가격(천원) | I31: ='Dart_중고차 Sales'!D49 -> 12395.723 | J31: ='Dart_중고차 Sales'!E49 -> 12891.131 | K31: ='Dart_중고차 Sales'!F49 -> 13679.935 | L31: ='Dart_중고차 Sales'!G49 -> 14570.125 | M31: =L31 -> 14570.125 | N31: =M31 -> 14570.125 | O31: =(1+Control!J21)*N31 -> 14715.826 | P31: =(1+Control!K21)*O31 -> 14862.984 | Q31: =(1+Control!L21)*P31 -> 15011.614 | R31: =(1+Control!M21)*Q31 -> 15161.73 | S31: =(1+Control!N21)*R31 -> 15313.348
F32: % YoY | J32: =J31/(I31)-1 -> 0.039966029 | K32: =K31/J31-1 -> 0.061189687 | L32: =(L31)/K31-1 -> 0.065072664 | M32: =L32 -> 0.065072664 | N32: =N31/K31-1 -> 0.065072664 | O32: =O31/N31-1 -> 0.01 | P32: =P31/O31-1 -> 0.01 | Q32: =Q31/P31-1 -> 0.01 | R32: =R31/Q31-1 -> 0.01 | S32: =S31/R31-1 -> 0.01
E33: 판매대수(대) | I33: ='Dart_중고차 Sales'!D38 -> 2556.769 | J33: ='Dart_중고차 Sales'!E38 -> 4329.8762 | K33: ='Dart_중고차 Sales'!F38 -> 5999.2244 | L33: ='Dart_중고차 Sales'!G38 -> 4334.28 | M33: =L33 -> 4334.28 | N33: =L33+M33 -> 8668.5599 | O33: =O35*O37 -> 8362.2103 | P33: =P35*P37 -> 9198.4313 | Q33: =Q35*Q37 -> 10118.274 | R33: =R35*R37 -> 11130.102 | S33: =S35*S37 -> 12243.112
F34: % YoY | J34: =J33/(I33/9*12)-1 -> 0.27012145 | K34: =K33/J33-1 -> 0.38554179 | L34: =(L33*2)/K33-1 -> 0.44494677 | M34: =L34 -> 0.44494677 | N34: =N33/K33-1 -> 0.44494677 | O34: =O33/N33-1 -> -0.035340314 | P34: =P33/O33-1 -> 0.1 | Q34: =Q33/P33-1 -> 0.1 | R34: =R33/Q33-1 -> 0.1 | S34: =S33/R33-1 -> 0.1
G35: 시장판매대수(대) | I35: =I33/I37 -> 3422.4467 | J35: =J33/J37 -> 4607.4766 | K35: =K33/K37 -> 7673.1143 | L35: =L33/L37 -> 6335.0078 | M35: =M33/M37 -> 6335.0078 | N35: =L35+M35 -> 12670.016 | O35: =(1+Control!J22)*N35 -> 13937.017 | P35: =(1+Control!K22)*O35 -> 15330.719 | Q35: =(1+Control!L22)*P35 -> 16863.791 | R35: =(1+Control!M22)*Q35 -> 18550.17 | S35: =(1+Control!N22)*R35 -> 20405.187
H36: % YoY | J36: =J35/I35-1 -> 0.34625228 | K36: =K35/J35-1 -> 0.66536151 | L36: =(L35*2)/K35-1 -> 0.65122206 | M36: =L36 -> 0.65122206 | N36: =N35/K35-1 -> 0.65122206 | O36: =O35/N35-1 -> 0.1 | P36: =P35/O35-1 -> 0.1 | Q36: =Q35/P35-1 -> 0.1 | R36: =R35/Q35-1 -> 0.1 | S36: =S35/R35-1 -> 0.1
G37: 점유율 | I37: =Dart_시장리서치!F$43 -> 0.74705882 | J37: =Dart_시장리서치!G$43 -> 0.93975 | K37: =Dart_시장리서치!H$43 -> 0.78185 | L37: =Dart_시장리서치!I$43 -> 0.6841791 | M37: =L37 -> 0.6841791 | N37: =M37 -> 0.6841791 | O37: =Control!J23 -> 0.6 | P37: =Control!K23 -> 0.6 | Q37: =Control!L23 -> 0.6 | R37: =Control!M23 -> 0.6 | S37: =Control!N23 -> 0.6
D38: 준중형(이커머스) | I38: =I42*I40/1000 -> 21892 | J38: =J42*J40/1000 -> 35300 | K38: =K42*K40/1000 -> 51859 | L38: =L42*L40/1000 -> 37193 | M38: =M42*M40/1000 -> 37193 | N38: =N42*N40/1000 -> 74386 | O38: =O42*O40/1000 -> 79063.361 | P38: =P42*P40/1000 -> 95824.793 | ... S38: =S42*S40/1000 -> 170602.64
E39: % YoY | J39: =J38/(I38/9*12)-1 -> 0.20934588 | K39: =K38/J38-1 -> 0.46909348 | L39: =(L38*2)/K38-1 -> 0.4343894 | M39: =L39 -> 0.4343894 | N39: =N38/K38-1 -> 0.4343894 | O39: =O38/N38-1 -> 0.062879581 | P39: =P38/O38-1 -> 0.212 | Q39: =Q38/P38-1 -> 0.212 | R39: =R38/Q38-1 -> 0.212 | S39: =S38/R38-1 -> 0.212
E40: 가격(천원) | I40: ='Dart_중고차 Sales'!D50 -> 8863.9807 | J40: ='Dart_중고차 Sales'!E50 -> 9073.7094 | K40: ='Dart_중고차 Sales'!F50 -> 9386.8273 | L40: ='Dart_중고차 Sales'!G50 -> 10130.351 | M40: =L40 -> 10130.351 | N40: =M40 -> 10130.351 | O40: =(1+Control!J24)*N40 -> 10231.655 | P40: =(1+Control!K24)*O40 -> 10333.971 | Q40: =(1+Control!L24)*P40 -> 10437.311 | R40: =(1+Control!M24)*Q40 -> 10541.684 | S40: =(1+Control!N24)*R40 -> 10647.101
F41: % YoY | J41: =J40/(I40)-1 -> 0.023660782 | K41: =K40/J40-1 -> 0.034508264 | L41: =(L40)/K40-1 -> 0.07920929 | M41: =L41 -> 0.07920929 | N41: =N40/K40-1 -> 0.07920929 | O41: =O40/N40-1 -> 0.01 | P41: =P40/O40-1 -> 0.01 | Q41: =Q40/P40-1 -> 0.01 | R41: =R40/Q40-1 -> 0.01 | S41: =S40/R40-1 -> 0.01
...

Sheet Sales Bridge
B1: Sales bridge | D1: Index
B3: KRW in millions | D3: 2018 | E3: 2019 | F3: 2020 | G3: 2021.1H
B4: 이커머스 판매매출 | D4: =Sales!I8 -> 155662 | E4: =Sales!J8 -> 284782 | F4: =Sales!K8 -> 408225 | G4: =Sales!L8 -> 322919
C5: 이커머스 총 판매대수 | D5: =Dart_시장리서치!F40 -> 17000 | E5: =Dart_시장리서치!G40 -> 24000 | F5: =Dart_시장리서치!H40 -> 40000 | G5: =Dart_시장리서치!I40/2 -> 33500
C6: 케이카 이커머스 점유율 | D6: =D7/D5 -> 0.74705882 | E6: =E7/E5 -> 0.93975 | F6: =F7/F5 -> 0.78185 | G6: =G7/G5 -> 0.6841791
C7: 케이카 이커머스 판매대수 | D7: =Dart_시장리서치!F42 -> 12700 | E7: =Dart_시장리서치!G42 -> 22554 | F7: =Dart_시장리서치!H42 -> 31274 | G7: =Dart_시장리서치!I42/2 -> 22920
C8: 이커머스 평균판매가격(천원) | D8: =D4*10^6/D7/1000 -> 12256.85 | E8: =E4*10^6/E7/1000 -> 12626.674 | F8: =F4*10^6/F7/1000 -> 13053.175 | G8: =G4*10^6/G7/1000 -> 14088.962
B9: 지점내방 판매매출 | D9: =Sales!I74 -> 518742 | E9: =Sales!J74 -> 786019 | F9: =Sales!K74 -> 776425 | G9: =Sales!L74 -> 469142
C10: 지점내방 총 판매대수 | D10: =Dart_시장리서치!F45 -> 2554000 | E10: =Dart_시장리서치!G45 -> 2473000 | F10: =Dart_시장리서치!H45 -> 2629000 | G10: =Dart_시장리서치!I45/2 -> 1364000
C11: 케이카 지점내방 점유율 | D11: =D12/D10 -> 0.01546437 | E11: =E12/E10 -> 0.024979377 | F11: =F12/F10 -> 0.022394447 | G11: =G12/G10 -> 0.02309824
C12: 케이카 지점내방 판매대수 | D12: =Dart_시장리서치!F47 -> 39496 | E12: =Dart_시장리서치!G47 -> 61774 | F12: =Dart_시장리서치!H47 -> 58875 | G12: =Dart_시장리서치!I47/2 -> 31506
C13: 지점내방 평균판매가격(천원) | D13: =D9*10^6/D12/1000 -> 13134.039 | E13: =E9*10^6/E12/1000 -> 12724.107 | F13: =F9*10^6/F12/1000 -> 13187.686 | G13: =G9*10^6/G12/1000 -> 14890.561
B14: 경매 | D14: =Sales!I140 -> 50546 | E14: =Sales!J140 -> 80966 | F14: =Sales!K140 -> 98049 | G14: =Sales!L140 -> 69172
B15: 렌터카 | D15: =Sales!I146 -> 0 | E15: =Sales!J146 -> 0 | F15: =Sales!K146 -> 0 | G15: =Sales!L146 -> 22392
B16: 기타 | D16: =Sales!I152 -> 17853 | E16: =Sales!J152 -> 33589 | F16: =Sales!K152 -> 40415 | G16: =Sales!L152 -> 26960
B17: 총매출 | D17: =D4+D9+D14+D15+D16 -> 742803 | E17: =E4+E9+E14+E15+E16 -> 1185356 | F17: =F4+F9+F14+F15+F16 -> 1323114 | G17: =G4+G9+G14+G15+G16 -> 910585
C20: 2018 Sales | D20: =D17 -> 742803
C21: 이커머스 시장 △Q | D21: =(E5-D5)*D6*D8*1000/10^6 -> 64096.118
C22: 이커머스 △점유율 | D22: =D5*(E6-D6)*D8*1000/10^6 -> 40150.378
C23: 이커머스 △가격 | D23: =D5*D6*(E8-D8)*1000/10^6 -> 4696.7568
C24: 이커머스 복합효과 | D24: =Sales!J8-(Sales!I8+D21+D22+D23) -> 20176.748
C25: 지점내방 시장 △Q | D25: =(E10-D10)*D11*D13*1000/10^6 -> -16451.88
C26: 지점내방 △점유율 | D26: =D10*(E11-D11)*D13*1000/10^6 -> 319174.61
C27: 지점내방 △가격 | D27: =D10*D11*(E13-D13)*1000/10^6 -> -16190.661
C28: 지점내방 복합효과 | D28: =Sales!J74-(Sales!I74+D25+D26+D27) -> -19255.066
C29: △경매매출 | D29: =E14-D14 -> 30420
C30: △렌터카매출 | D30: =E15-D15 -> 0
C31: △기타매출 | D31: =E16-D16 -> 15736
C32: 2019 Sales | D32: =E17 -> 1185356
C33: 이커머스 시장 △Q | D33: =(F5-E5)*E6*E8*1000/10^6 -> 189854.67
C34: 이커머스 △점유율 | D34: =E5*(F6-E6)*E8*1000/10^6 -> -47850.043
C35: 이커머스 △가격 | D35: =E5*E6*(F8-E8)*1000/10^6 -> 9619.3126
C36: 이커머스 복합효과 | D36: =Sales!K8-(Sales!J8+D33+D34+D35) -> -28180.936
C37: 지점내방 시장 △Q | D37: =(F10-E10)*E11*E13*1000/10^6 -> 49583.083
C38: 지점내방 △점유율 | D38: =E10*(F11-E11)*E13*1000/10^6 -> -81339.284
C39: 지점내방 △가격 | D39: =E10*E11*(F13-E13)*1000/10^6 -> 28637.101
C40: 지점내방 복합효과 | D40: =Sales!K74-(Sales!J74+D37+D38+D39) -> -6474.9002
C41: △경매매출 | D41: =F14-E14 -> 17083
C42: △렌터카매출 | D42: =F15-E15 -> 0
C43: △기타매출 | D43: =F16-E16 -> 6826
...

Sheet Cost
B1: Cost | E1: Index
E3: Historical | J3: Forecast
B4: KRW in millions | E4: 2018 | F4: 2019 | G4: 2020 | H4: 2021.1H | I4: 2021.2H | J4: 2021 | K4: 2022 | L4: =K4+1 -> 2023 | M4: =L4+1 -> 2024 | N4: =M4+1 -> 2025 | O4: =N4+1 -> 2026
B5: 중고차 판매대수 | E5: =Sales!I7 -> 52196 | F5: =Sales!J7 -> 84328 | G5: =Sales!K7 -> 90149 | H5: =Sales!L7 -> 54426 | I5: =Sales!M7 -> 54426 | J5: =Sales!N7 -> 108852 | K5: =Sales!O7 -> 111343.67 | L5: =Sales!P7 -> 131007.24 | ... O5: =Sales!S7 -> 215003.75
B6: Total Sales | E6: =Sales!I160 -> 742803 | F6: =Sales!J160 -> 1185356 | G6: =Sales!K160 -> 1323114 | H6: =Sales!L160 -> 910585 | I6: =Sales!M160 -> 910585 | J6: =Sales!N160 -> 1821170 | K6: =Sales!O160 -> 1902459 | L6: =Sales!P160 -> 2256380 | ... O6: =Sales!S160 -> 3792952.9
B7: 중고차 Sales | E7: =Sales!I5 -> 674404 | F7: =Sales!J5 -> 1070801 | G7: =Sales!K5 -> 1184650 | H7: =Sales!L5 -> 792061 | I7: =Sales!M5 -> 792061 | J7: =Sales!N5 -> 1584122 | K7: =Sales!O5 -> 1630322.7 | L7: =Sales!P5 -> 1930634.3 | ... O7: =Sales!S5 -> 3233329.1
B8: 렌터카 매각 Sales | E8: =Sales!I148 -> 0 | F8: =Sales!J148 -> 0 | G8: =Sales!K148 -> 0 | H8: =Sales!L148 -> 5615 | I8: =Sales!M148 -> 5615 | J8: =Sales!N148 -> 11230 | K8: =Sales!O148 -> 13476 | L8: =Sales!P148 -> 16171.2 | ... O8: =Sales!S148 -> 27943.834
B9: 인건비 | E9: =SUM(E11:E13) -> 30994.723 | F9: =SUM(F11:F13) -> 48926.557 | G9: =SUM(G11:G13) -> 54031.414 | H9: =SUM(H11:H13) -> 33044.704 | I9: =SUM(I11:I13) -> 33044.704 | J9: =SUM(J11:J13) -> 66089.408 | K9: =SUM(K11:K13) -> 68601.231 | L9: =SUM(L11:L13) -> 81184.55 | ... O9: =SUM(O11:O13) -> 137055.76
C10: % of Sales | E10: =E9/E6 -> 0.041726707 | F10: =F9/F6 -> 0.041275834 | G10: =G9/G6 -> 0.040836552 | H10: =H9/H6 -> 0.036289533 | I10: =I9/I6 -> 0.036289533 | J10: =J9/J6 -> 0.036289533 | K10: =K9/K6 -> 0.036059242 | L10: =L9/L6 -> 0.035979999 | ... O10: =O9/O6 -> 0.036134317
C11: 종업원급여 | E11: =Labor!G9 -> 25858.31 | F11: =Labor!H9 -> 40917.289 | G11: =Labor!I9 -> 44758.009 | H11: =Labor!J9 -> 27738.124 | I11: =Labor!K9 -> 27738.124 | J11: =Labor!L9 -> 55476.248 | K11: =Labor!M9 -> 58729.897 | L11: =Labor!N9 -> 69817.432 | ... O11: =Labor!Q9 -> 118344.84
C12: 퇴직급여 | E12: =Labor!G58 -> 2136.705 | F12: =Labor!H58 -> 3125.462 | G12: =Labor!I58 -> 4481.863 | H12: =Labor!J58 -> 2195.341 | I12: =Labor!K58 -> 2195.341 | J12: =Labor!L58 -> 4390.682 | K12: =Labor!M58 -> 4967.0347 | L12: =Labor!N58 -> 5904.7542 | ... O12: =Labor!Q58 -> 10008.921
C13: 복리후생비 | E13: =Labor!G60 -> 2999.708 | F13: =Labor!H60 -> 4883.806 | G13: =Labor!I60 -> 4791.542 | H13: =Labor!J60 -> 3111.239 | I13: =Labor!K60 -> 3111.239 | J13: =Labor!L60 -> 6222.478 | K13: =Labor!M60 -> 4904.2994 | L13: =Labor!N60 -> 5462.364 | ... O13: =Labor!Q60 -> 8702.0035
B14: 주식보상비용 | E14: =Dart_Cost!C25/1000 -> 0 | F14: =Dart_Cost!D25/1000 -> 0 | G14: =Dart_Cost!E25/1000 -> 0 | H14: =Dart_Cost!F25/1000 -> 975.474 | I14: =H14 -> 975.474 | J14: =H14+I14 -> 1950.948 | K14: =K9*Control!J73 -> 2058.0369 | L14: =L9*Control!K73 -> 2435.5365 | M14: =M9*Control!L73 -> 2897.1162 | N14: =N9*Control!M73 -> 3458.893 | O14: =O9*Control!N73 -> 4111.6729
D15: % of Labor | E15: =E14/E9 -> 0 | F15: =F14/F9 -> 0 | G15: =G14/G9 -> 0 | H15: =H14/H9 -> 0.029519829 | I15: =I14/I9 -> 0.029519829 | J15: =J14/J9 -> 0.029519829 | K15: =K14/K9 -> 0.03 | L15: =L14/L9 -> 0.03 | ... O15: =O14/O9 -> 0.03
B16: 상각비 | E16: =SUM(E17:E18) -> 7432.3771 | F16: =SUM(F17:F18) -> 13537.456 | G16: =SUM(G17:G18) -> 15873.972 | H16: =SUM(H17:H18) -> 19724.316 | I16: =SUM(I17:I18) -> 19724.316 | J16: =SUM(J17:J18) -> 39448.632 | K16: =SUM(K17:K18) -> 33669.772 | L16: =SUM(L17:L18) -> 30919.503 | ... O16: =SUM(O17:O18) -> 25746.402
C17: 감가상각비 | E17: ='CapEx,D&A'!F9 -> 6680.6336 | F17: ='CapEx,D&A'!G9 -> 12256.755 | G17: ='CapEx,D&A'!H9 -> 14214.472 | H17: ='CapEx,D&A'!I9 -> 18802.028 | I17: ='CapEx,D&A'!J9 -> 18802.028 | J17: ='CapEx,D&A'!K9 -> 37604.056 | K17: ='CapEx,D&A'!L9 -> 32110.436 | L17: ='CapEx,D&A'!M9 -> 29350.294 | ... O17: ='CapEx,D&A'!P9 -> 24142.297
C18: 무형자산상각비 | E18: ='CapEx,D&A'!F10 -> 751.74352 | F18: ='CapEx,D&A'!G10 -> 1280.7009 | G18: ='CapEx,D&A'!H10 -> 1659.4994 | H18: ='CapEx,D&A'!I10 -> 922.28807 | I18: ='CapEx,D&A'!J10 -> 922.28807 | J18: ='CapEx,D&A'!K10 -> 1844.5761 | K18: ='CapEx,D&A'!L10 -> 1559.336 | L18: ='CapEx,D&A'!M10 -> 1569.2089 | ... O18: ='CapEx,D&A'!P10 -> 1604.1048
B19: 변동비 | E19: =E21+E24+E27+E31+E33+E35+E37+E39+E41+E29 -> 688489.81 | F19: =F21+F24+F27+F31+F33+F35+F37+F39+F41+F29 -> 1088832.5 | G19: =G21+G24+G27+G31+G33+G35+G37+G39+G41+G29 -> 1210703.1 | H19: =H21+H24+H27+H31+H33+H35+H37+H39+H41+H29 -> 812768.74 | I19: =I21+I24+I27+I31+I33+I35+I37+I39+I41+I29 -> 812768.74 | J19: =J21+J24+J27+J31+J33+J35+J37+J39+J41+J29 -> 1625537.5 | K19: =K21+K24+K27+K31+K33+K35+K37+K39+K41+K29 -> 1670801.7 | L19: =L21+L24+L27+L31+L33+L35+L37+L39+L41+L29 -> 1985483.9 | ... O19: =O21+O24+O27+O31+O33+O35+O37+O39+O41+O29 -> 3356864.7
C20: % of Total Sales | E20: =E19/E$6 -> 0.92688076 | F20: =F19/F$6 -> 0.91857004 | G20: =G19/G$6 -> 0.91504064 | H20: =H19/H$6 -> 0.89257866 | I20: =I19/I$6 -> 0.89257866 | J20: =J19/J$6 -> 0.89257866 | K20: =K19/K$6 -> 0.87823268 | L20: =L19/L$6 -> 0.87994214 | ... O20: =O19/O$6 -> 0.88502673
C21: 재고자산원가 | E21: =(Dart_Cost!C6+Dart_Cost!C7)/1000 -> 663748.17 | F21: =(Dart_Cost!D6+Dart_Cost!D7)/1000 -> 1053521.7 | G21: =(Dart_Cost!E6+Dart_Cost!E7)/1000 -> 1170061.6 | H21: =(Dart_Cost!F6+Dart_Cost!F7)/1000 -> 784113.35 | I21: =H21 -> 784113.35 | J21: =H21+I21 -> 1568226.7 | K21: =K5*Control!J74 -> 1604124.1 | L21: =L5*Control!K74 -> 1906290.6 | M21: =M5*Control!L74 -> 2268308.6 | N21: =N5*Control!M74 -> 2702399.5 | O21: =O5*Control!N74 -> 3223324.1
D22: 중고차 1대당 원가 | E22: =E21/E$5 -> 12.716457 | F22: =F21/F5 -> 12.493142 | G22: =G21/G5 -> 12.979196 | H22: =H21/H5 -> 14.406963 | I22: =H22 -> 14.406963 | J22: =I22 -> 14.406963 | K22: =K21/K5 -> 14.406963 | L22: =L21/L5 -> 14.551032 | M22: =M21/M5 -> 14.696543 | N22: =N21/N5 -> 14.843508 | O22: =O21/O5 -> 14.991943
D23: % of 중고차 Sales | E23: =E21/E$7 -> 0.98419963 | F23: =F21/F$7 -> 0.98386317 | G23: =G21/G$7 -> 0.98768544 | H23: =H21/H$7 -> 0.98996587 | I23: =I21/I$7 -> 0.98996587 | J23: =J21/J$7 -> 0.98996587 | K23: =K21/K$7 -> 0.98393041 | L23: =L21/L$7 -> 0.98739082 | ... O23: =O21/O$7 -> 0.99690566
C24: 판매보증비 | E24: =Dart_Cost!C24/1000 -> 3856.243 | F24: =Dart_Cost!D24/1000 -> 4812.931 | G24: =Dart_Cost!E24/1000 -> 3766.917 | H24: =Dart_Cost!F24/1000 -> 1813.818 | I24: =H24 -> 1813.818 | J24: =H24+I24 -> 3627.636 | K24: =K5*Control!J$75 -> 3710.6741 | L24: =L5*Control!K$75 -> 4365.9884 | M24: =M5*Control!L$75 -> 5143.6835 | N24: =N5*Control!M$75 -> 6067.3674 | O24: =O5*Control!N$75 -> 7165.2827
D25: 중고차 1대당 보증비 | E25: =E24/E$5 -> 0.073880048 | F25: =F24/F$5 -> 0.057073937 | G25: =G24/G$5 -> 0.041785455 | H25: =H24/H$5 -> 0.033326315 | I25: =I24/I$5 -> 0.033326315 | J25: =J24/J$5 -> 0.033326315 | K25: =K24/K$5 -> 0.033326315 | L25: =L24/L$5 -> 0.033326315 | ... O25: =O24/O$5 -> 0.033326315
D26: % of 중고차 Sales | E26: =E24/E$7 -> 0.0057180014 | F26: =F24/F$7 -> 0.0044947016 | G26: =G24/G$7 -> 0.0031797721 | H26: =H24/H$7 -> 0.0022899979 | I26: =I24/I$7 -> 0.0022899979 | J26: =J24/J$7 -> 0.0022899979 | K26: =K24/K$7 -> 0.0022760366 | L26: =L24/L$7 -> 0.002261427 | ... O26: =O24/O$7 -> 0.0022160697
C27: 차량매각원가 | E27: =Dart_Cost!C26/1000 -> 0 | F27: =Dart_Cost!D26/1000 -> 0 | G27: =Dart_Cost!E26/1000 -> 0 | H27: =Dart_Cost!F26/1000 -> 4368.328 | I27: =H27 -> 4368.328 | J27: =H27+I27 -> 8736.656 | K27: =K$8*Control!J76 -> 10483.987 | L27: =L$8*Control!K76 -> 12580.785 | M27: =M$8*Control!L76 -> 15096.942 | N27: =N$8*Control!M76 -> 18116.33 | O27: =O$8*Control!N76 -> 21739.596
D28: % of 렌터카매각 Sales | H28: =H27/H$8 -> 0.77797471 | I28: =I27/I$8 -> 0.77797471 | J28: =J27/J$8 -> 0.77797471 | K28: =K27/K$8 -> 0.77797471 | L28: =L27/L$8 -> 0.77797471 | M28: =M27/M$8 -> 0.77797471 | N28: =N27/N$8 -> 0.77797471 | O28: =O27/O$8 -> 0.77797471
C29: 지급수수료 | E29: =Dart_Cost!C19/1000 -> 6038.554 | F29: =Dart_Cost!D19/1000 -> 9360.366 | G29: =Dart_Cost!E19/1000 -> 10811.345 | H29: =Dart_Cost!F19/1000 -> 7607.318 | I29: =H29 -> 7607.318 | J29: =H29+I29 -> 15214.636 | K29: =K$6*Control!J77 -> 15481.994 | L29: =L$6*Control!K77 -> 18362.162 | M29: =M$6*Control!L77 -> 21806.388 | N29: =N$6*Control!M77 -> 25928.701 | O29: =O$6*Control!N77 -> 30866.617
D30: % of Total Sales | E30: =E29/E$6 -> 0.0081294152 | F30: =F29/F$6 -> 0.0078966707 | G30: =G29/G$6 -> 0.0081711364 | H30: =H29/H$6 -> 0.0083543195 | I30: =I29/I$6 -> 0.0083543195 | J30: =J29/J$6 -> 0.0083543195 | K30: =K29/K$6 -> 0.0081378855 | L30: =L29/L$6 -> 0.0081378855 | ... O30: =O29/O$6 -> 0.0081378855
C31: 부품비 | E31: =Dart_Cost!C23/1000 -> 468.221 | F31: =Dart_Cost!D23/1000 -> 594.292 | G31: =Dart_Cost!E23/1000 -> 693.463 | H31: =Dart_Cost!F23/1000 -> 349.912 | I31: =H31 -> 349.912 | J31: =H31+I31 -> 699.824 | K31: =K$6*Control!J78 -> 970.2974 | L31: =L$6*Control!K78 -> 1150.8052 | M31: =M$6*Control!L78 -> 1366.6639 | N31: =N$6*Control!M78 -> 1625.0201 | O31: =O$6*Control!N78 -> 1934.4923
D32: % of Total Sales | E32: =E31/E$6 -> 0.00063034344 | F32: =F31/F$6 -> 0.00050136162 | G32: =G31/G$6 -> 0.00052411432 | H32: =H31/H$6 -> 0.00038427165 | I32: =I31/I$6 -> 0.00038427165 | J32: =J31/J$6 -> 0.00038427165 | K32: =K31/K$6 -> 0.00051002276 | L32: =L31/L$6 -> 0.00051002276 | ... O32: =O31/O$6 -> 0.00051002276
C33: 세금과공과 | E33: =Dart_Cost!C12/1000 -> 1802.771 | F33: =Dart_Cost!D12/1000 -> 3765.01 | G33: =Dart_Cost!E12/1000 -> 5220.383 | H33: =Dart_Cost!F12/1000 -> 2969.282 | I33: =H33 -> 2969.282 | J33: =H33+I33 -> 5938.564 | K33: =K$6*Control!J79 -> 6092.45 | L33: =L$6*Control!K79 -> 7225.8495 | M33: =M$6*Control!L79 -> 8581.2158 | N33: =N$6*Control!M79 -> 10203.422 | O33: =O$6*Control!N79 -> 12146.583
D34: % of Total Sales | E34: =E33/E$6 -> 0.002426984 | F34: =F33/F$6 -> 0.0031762694 | G34: =G33/G$6 -> 0.0039455277 | H34: =H33/H$6 -> 0.003260851 | I34: =I33/I$6 -> 0.003260851 | J34: =J33/J$6 -> 0.003260851 | K34: =K33/K$6 -> 0.003202408 | L34: =L33/L$6 -> 0.003202408 | ... O34: =O33/O$6 -> 0.003202408
C35: 위탁차량비 | E35: =Dart_Cost!C22/1000 -> 232.945 | F35: =Dart_Cost!D22/1000 -> 267.44 | G35: =Dart_Cost!E22/1000 -> 376.683 | H35: =Dart_Cost!F22/1000 -> 153.236 | I35: =H35 -> 153.236 | J35: =H35+I35 -> 306.472 | K35: =K$6*Control!J80 -> 471.90494 | L35: =L$6*Control!K80 -> 559.69504 | M35: =M$6*Control!L80 -> 664.6781 | N35: =N$6*Control!M80 -> 790.32989 | O35: =O$6*Control!N80 -> 940.84194
D36: % of Total Sales | E36: =E35/E$6 -> 0.00031360266 | F36: =F35/F$6 -> 0.00022561998 | G36: =G35/G$6 -> 0.00028469429 | H36: =H35/H$6 -> 0.00016828303 | I36: =I35/I$6 -> 0.00016828303 | J36: =J35/J$6 -> 0.00016828303 | K36: =K35/K$6 -> 0.00024804999 | L36: =L35/L$6 -> 0.00024804999 | ... O36: =O35/O$6 -> 0.00024804999
C37: 소모품비 | E37: =Dart_Cost!C21/1000 -> 413.477 | F37: =Dart_Cost!D21/1000 -> 504.02 | G37: =Dart_Cost!E21/1000 -> 618.27 | H37: =Dart_Cost!F21/1000 -> 315.982 | I37: =H37 -> 315.982 | J37: =H37+I37 -> 631.964 | K37: =K$6*Control!J81 -> 854.27245 | L37: =L$6*Control!K81 -> 1013.1957 | M37: =M$6*Control!L81 -> 1203.2427 | N37: =N$6*Control!M81 -> 1430.7056 | O37: =O$6*Control!N81 -> 1703.1721
D38: % of Total Sales | E38: =E37/E$6 -> 0.00055664422 | F38: =F37/F$6 -> 0.00042520559 | G38: =G37/G$6 -> 0.000467284 | H38: =H37/H$6 -> 0.00034700989 | I38: =I37/I$6 -> 0.00034700989 | J38: =J37/J$6 -> 0.00034700989 | K38: =K37/K$6 -> 0.00044903593 | L38: =L37/L$6 -> 0.00044903593 | ... O38: =O37/O$6 -> 0.00044903593
C39: 보험료 | E39: =Dart_Cost!C16/1000 -> 235.401 | F39: =Dart_Cost!D16/1000 -> 341.832 | G39: =Dart_Cost!E16/1000 -> 349.413 | H39: =Dart_Cost!F16/1000 -> 1572.558 | I39: =H39 -> 1572.558 | J39: =H39+I39 -> 3145.116 | K39: =K$6*Control!J82 -> 1234.8612 | L39: =L$6*Control!K82 -> 1464.5867 | M39: =M$6*Control!L82 -> 1739.302 | N39: =N$6*Control!M82 -> 2068.1024 | O39: =O$6*Control!N82 -> 2461.9561
D40: % of Total Sales | E40: =E39/E$6 -> 0.00031690906 | F40: =F39/F$6 -> 0.00028837919 | G40: =G39/G$6 -> 0.00026408382 | H40: =H39/H$6 -> 0.0017269755 | I40: =I39/I$6 -> 0.0017269755 | J40: =J39/J$6 -> 0.0017269755 | K40: =K39/K$6 -> 0.0006490869 | L40: =L39/L$6 -> 0.0006490869 | ... O40: =O39/O$6 -> 0.0006490869
C41: 기타비용 | E41: =Dart_Cost!C27/1000 -> 11694.027 | F41: =Dart_Cost!D27/1000 -> 15664.953 | G41: =Dart_Cost!E27/1000 -> 18805.05 | H41: =Dart_Cost!F27/1000 -> 9504.955 | I41: =H41 -> 9504.955 | J41: =H41+I41 -> 19009.91 | K41: =K$6*Control!J83 -> 27377.163 | L41: =L$6*Control!K83 -> 32470.232 | M41: =M$6*Control!L83 -> 38560.734 | N41: =N$6*Control!M83 -> 45850.316 | O41: =O$6*Control!N83 -> 54582.144
...

Sheet CapEx,D&A
B1: CapEx, D&A | F1: Index
F3: Historical | K3: Forecast
B4: KRW in millions | F4: 2018 | G4: 2019 | H4: 2020 | I4: 2021.1H | J4: 2021.2H | K4: 2021 | L4: 2022 | M4: 2023 | N4: 2024 | O4: 2025 | P4: 2016
B5: CapEx | F5: =F6+F7 -> 6203.4207 | G5: =G6+G7 -> 4496.4141 | H5: =H6+H7 -> 2238.3799 | I5: =I6+I7 -> 2044.2493 | J5: =J6+J7 -> 2044.2493 | K5: =K6+K7 -> 4088.4986 | L5: =L6+L7 -> 4256.2992 | M5: =M6+M7 -> 4469.1141 | ... P5: =P6+P7 -> 5173.5582
C6: 유형자산(사용권) | F6: =Dart_FS!C138/10^6 -> 4767.0067 | G6: =Dart_FS!D138/10^6 -> 3551.6559 | H6: =Dart_FS!E138/10^6 -> 1190.6147 | I6: =Dart_FS!F138/10^6 -> 1704.1197 | J6: =I6 -> 1704.1197 | K6: =I6+J6 -> 3408.2394 | L6: =Control!J96 -> 3229 | M6: =Control!K96 -> 3390.45 | N6: =Control!L96 -> 3559.9725 | O6: =Control!M96 -> 3737.9711 | P6: =Control!N96 -> 3924.8697
C7: 무형자산 | F7: =Dart_FS!C139/10^6 -> 1436.414 | G7: =Dart_FS!D139/10^6 -> 944.75825 | H7: =Dart_FS!E139/10^6 -> 1047.7652 | I7: =Dart_FS!F139/10^6 -> 340.1296 | J7: =I7 -> 340.1296 | K7: =I7+J7 -> 680.2592 | L7: =Control!J97 -> 1027.2992 | M7: =Control!K97 -> 1078.6641 | N7: =Control!L97 -> 1132.5973 | O7: =Control!M97 -> 1189.2272 | P7: =Control!N97 -> 1248.6885
B8: D&A | F8: =F9+F10 -> 7432.3771 | G8: =G9+G10 -> 13537.456 | H8: =H9+H10 -> 15873.972 | I8: =I9+I10 -> 19724.316 | J8: =J9+J10 -> 19724.316 | K8: =K9+K10 -> 39448.632 | L8: =L9+L10 -> 33669.772 | M8: =M9+M10 -> 30919.503 | ... P8: =P9+P10 -> 25746.402
C9: 유형자산 | F9: =Dart_FS!C82/10^6 -> 6680.6336 | G9: =Dart_FS!D82/10^6 -> 12256.755 | H9: =Dart_FS!E82/10^6 -> 14214.472 | I9: =Dart_FS!F82/10^6 -> 18802.028 | J9: =I9 -> 18802.028 | K9: =I9+J9 -> 37604.056 | L9: =AVERAGE(K15,K15+L6+L12)*L18 -> 32110.436 | M9: =AVERAGE(L15,L15+M6+M12)*M18 -> 29350.294 | N9: =AVERAGE(M15,M15+N6+N12)*N18 -> 27175.277 | O9: =AVERAGE(N15,N15+O6+O12)*O18 -> 25470.016 | P9: =AVERAGE(O15,O15+P6+P12)*P18 -> 24142.297
C10: 무형자산 | F10: =Dart_FS!C84/10^6 -> 751.74352 | G10: =Dart_FS!D84/10^6 -> 1280.7009 | H10: =Dart_FS!E84/10^6 -> 1659.4994 | I10: =Dart_FS!F84/10^6 -> 922.28807 | J10: =I10 -> 922.28807 | K10: =I10+J10 -> 1844.5761 | L10: =AVERAGE(K16,K16+L7+L13)*L19 -> 1559.336 | M10: =AVERAGE(L16,L16+M7+M13)*M19 -> 1569.2089 | N10: =AVERAGE(M16,M16+N7+N13)*N19 -> 1579.9373 | O10: =AVERAGE(N16,N16+O7+O13)*O19 -> 1591.5568 | P10: =AVERAGE(O16,O16+P7+P13)*P19 -> 1604.1048
B11: 기타변동 | F11: =F12+F13 -> 0 | G11: =G12+G13 -> 9963.1981 | H11: =H12+H13 -> 14308.68 | I11: =I12+I13 -> 112172.86 | J11: =J12+J13 -> 11905.699 | K11: =K12+K13 -> 124078.55 | L11: =L12+L13 -> 16000 | M11: =M12+M13 -> 16000 | ... P11: =P12+P13 -> 16000
C12: 유형자산 | F12: 0 | G12: =G15-(F15+G6-G9) -> 9963.1981 | H12: =H15-(G15+H6-H9) -> 13421.956 | I12: =I15-(H15+I6-I9) -> 111959.73 | J12: =AVERAGE(G12:H12) -> 11692.577 | K12: =I12+J12 -> 123652.31 | L12: =Control!J98 -> 15000 | M12: =Control!K98 -> 15000 | N12: =Control!L98 -> 15000 | O12: =Control!M98 -> 15000 | P12: =Control!N98 -> 15000
C13: 무형자산 | F13: 0 | G13: =G16-(F16+G7-G10) -> 0 | H13: =H16-(G16+H7-H10) -> 886.72391 | I13: =I16-(H16+I7-I10) -> 213.12179 | J13: =I13 -> 213.12179 | K13: =I13+J13 -> 426.24359 | L13: =Control!J99 -> 1000 | M13: =Control!K99 -> 1000 | N13: =Control!L99 -> 1000 | O13: =Control!M99 -> 1000 | P13: =Control!N99 -> 1000
B14: 장부가액 | F14: =F15+F16 -> 138077.16 | G14: =G15+G16 -> 138999.32 | H14: =H15+H16 -> 139672.41 | I14: =I15+I16 -> 234165.2 | J14: =J15+J16 -> 228390.83 | K14: =K15+K16 -> 228390.83 | L14: =L15+L16 -> 214977.36 | M14: =M15+M16 -> 204526.97 | ... P14: =P15+P16 -> 185757.1
C15: 유형자산(사용권) | F15: =(Dart_FS!C17 + Dart_FS!C19 ) /10^6 -> 60324.988 | G15: =(Dart_FS!D17 + Dart_FS!D19 ) /10^6 -> 61583.087 | H15: =(Dart_FS!E17 + Dart_FS!E19 ) /10^6 -> 61981.185 | I15: =(Dart_FS!F17 + Dart_FS!F19 ) /10^6 -> 156843.01 | J15: =I15+J6-J9+J12 -> 151437.68 | K15: =J15 -> 151437.68 | L15: =K15+L6-L9+L12 -> 137556.24 | M15: =L15+M6-M9+M12 -> 126596.4 | N15: =M15+N6-N9+N12 -> 117981.1 | O15: =N15+O6-O9+O12 -> 111249.05 | P15: =O15+P6-P9+P12 -> 106031.62
C16: 무형자산 | F16: =Dart_FS!C18/10^6 -> 77752.174 | G16: =Dart_FS!D18/10^6 -> 77416.232 | H16: =Dart_FS!E18/10^6 -> 77691.221 | I16: =Dart_FS!F18/10^6 -> 77322.185 | J16: =I16+J7-J10+J13 -> 76953.148 | K16: =J16 -> 76953.148 | L16: =K16+L7-L10+L13 -> 77421.111 | M16: =L16+M7-M10+M13 -> 77930.566 | N16: =M16+N7-N10+N13 -> 78483.226 | O16: =N16+O7-O10+O13 -> 79080.897 | P16: =O16+P7-P10+P13 -> 79725.481
B17: 상각비/장부가액
C18: 유형자산 | G18: =G9/AVERAGE(F15,F15+G6+G12) -> 0.18271189 | H18: =H9/AVERAGE(G15,G15+H6+H12) -> 0.20633767 | K18: =K9/AVERAGE(H15+K6+K12) -> 0.19891933 | L18: =Control!J100 -> 0.2 | M18: =Control!K100 -> 0.2 | N18: =Control!L100 -> 0.2 | O18: =Control!M100 -> 0.2 | P18: =Control!N100 -> 0.2
C19: 무형자산 | G19: =G10/AVERAGE(F16,F16+G7+G13) -> 0.016372109 | H19: =H10/AVERAGE(G16,G16+H7+H13) -> 0.021171546 | K19: =K10/AVERAGE(H16,H16+K7+K13) -> 0.023574523 | L19: =Control!J101 -> 0.02 | M19: =Control!K101 -> 0.02 | N19: =Control!L101 -> 0.02 | O19: =Control!M101 -> 0.02 | P19: =Control!N101 -> 0.02

Sheet Labor
B1: Labor | G1: Index
G3: Historical | L3: Forecast
B4: KRW in millions | G4: 2018 | H4: 2019 | I4: 2020 | J4: 2021.1H | K4: 2021.2H | L4: 2021 | M4: 2022 | N4: =M4+1 -> 2023 | O4: =N4+1 -> 2024 | P4: =O4+1 -> 2025 | Q4: =P4+1 -> 2026 | T4: 2022 | U4: 2023 | V4: 2024 | W4: 2025 | X4: 2026
B5: 중고차 판매대수 | G5: =Sales!I7 -> 52196 | H5: =Sales!J7 -> 84328 | I5: =Sales!K7 -> 90149 | J5: =Sales!L7 -> 54426 | K5: =Sales!M7 -> 54426 | L5: =Sales!N7 -> 108852 | M5: =Sales!O7 -> 111343.67 | N5: =Sales!P7 -> 131007.24 | ... Q5: =Sales!S7 -> 215003.75
B6: Total Sales | G6: =Sales!I160 -> 742803 | H6: =Sales!J160 -> 1185356 | I6: =Sales!K160 -> 1323114 | J6: =Sales!L160 -> 910585 | K6: =Sales!M160 -> 910585 | L6: =Sales!N160 -> 1821170 | M6: =Sales!O160 -> 1902459 | N6: =Sales!P160 -> 2256380 | ... Q6: =Sales!S160 -> 3792952.9
B7: 경매 | G7: =Sales!I140 -> 50546 | H7: =Sales!J140 -> 80966 | I7: =Sales!K140 -> 98049 | J7: =Sales!L140 -> 69172 | K7: =Sales!M140 -> 69172 | L7: =Sales!N140 -> 138344 | M7: =Sales!O140 -> 166012.8 | N7: =Sales!P140 -> 199215.36 | ... Q7: =Sales!S140 -> 344244.14
B8: 렌탈 | G8: =Sales!I146 -> 0 | H8: =Sales!J146 -> 0 | I8: =Sales!K146 -> 0 | J8: =Sales!L146 -> 22392 | K8: =Sales!M146 -> 22392 | L8: =Sales!N146 -> 44784 | M8: =Sales!O146 -> 53740.8 | N8: =Sales!P146 -> 64488.96 | ... Q8: =Sales!S146 -> 111436.92
B9: 종업원 급여 | G9: =Dart_Cost!C33/1000 -> 25858.31 | H9: =Dart_Cost!D33/1000 -> 40917.289 | I9: =Dart_Cost!E33/1000 -> 44758.009 | J9: =J10+J19+J28+J37+J44+J51 -> 27738.124 | K9: =K10+K19+K28+K37+K44+K51 -> 27738.124 | L9: =L10+L19+L28+L37+L44+L51 -> 55476.248 | M9: =M10+M19+M28+M37+M44+M51 -> 58729.897 | N9: =N10+N19+N28+N37+N44+N51 -> 69817.432 | O9: =O10+O19+O28+O37+O44+O51 -> 83165.445 | P9: =P10+P19+P28+P37+P44+P51 -> 99173.808 | Q9: =Q10+Q19+Q28+Q37+Q44+Q51 -> 118344.84
C10: 중고차 | J10: =J11+J15 -> 22029.607 | K10: =K11+K15 -> 22029.607 | L10: =L11+L15 -> 44059.214 | M10: =M11+M15 -> 45931.338 | N10: =N11+N15 -> 55095.958 | O10: =O11+O15 -> 66200.285 | P10: =P11+P15 -> 79675.761 | Q10: =Q11+Q15 -> 95983.975
D11: 남 | J11: =VALUE(Dart_Labor!S10)/1000 -> 20705.105 | K11: =K12*K14 -> 20705.105 | L11: =L12*L14 -> 41410.21 | M11: =M12*M14 -> 43154.298 | N11: =N12*N14 -> 51765.763 | O11: =O12*O14 -> 62217.831 | P11: =P12*P14 -> 74896.816 | Q11: =Q12*Q14 -> 90215.788
E12: 직원수 | J12: =VALUE(Dart_Labor!H10) -> 784 | K12: =J12 -> 784 | L12: =K12 -> 784 | M12: =ROUND(M$5/M13,0) -> 801 | N12: =ROUND(N$5/N13,0) -> 942 | O12: =ROUND(O$5/O13,0) -> 1110 | P12: =ROUND(P$5/P13,0) -> 1310 | Q12: =ROUND(Q$5/Q13,0) -> 1547
F13: 1인당 판매대수 | J13: =J$5/J12 -> 69.420918 | K13: =K$5/K12 -> 69.420918 | L13: =L$5/L12 -> 138.84184 | M13: =Control!J106 -> 139 | N13: =Control!K106 -> 139 | O13: =Control!L106 -> 139 | P13: =Control!M106 -> 139 | Q13: =Control!N106 -> 139
E14: 평균급여 | J14: =J11/J12 -> 26.409573 | K14: =J14 -> 26.409573 | L14: =J14+K14 -> 52.819146 | M14: =Control!J107 -> 53.875529 | N14: =Control!K107 -> 54.953039 | O14: =Control!L107 -> 56.0521 | P14: =Control!M107 -> 57.173142 | Q14: =Control!N107 -> 58.316605
D15: 여 | J15: =VALUE(Dart_Labor!S11)/1000 -> 1324.502 | K15: =K16*K18 -> 1324.502 | L15: =L16*L18 -> 2649.0041 | M15: =M16*M18 -> 2777.0393 | N15: =N16*N18 -> 3330.1955 | O15: =O16*O18 -> 3982.4544 | P15: =P16*P18 -> 4778.9453 | Q15: =Q16*Q18 -> 5768.187
E16: 직원수 | J16: =VALUE(Dart_Labor!H11) -> 72 | K16: =J16 -> 72 | L16: =K16 -> 72 | M16: =ROUND(M$5/M17,0) -> 74 | N16: =ROUND(N$5/N17,0) -> 87 | O16: =ROUND(O$5/O17,0) -> 102 | P16: =ROUND(P$5/P17,0) -> 120 | Q16: =ROUND(Q$5/Q17,0) -> 142
F17: 1인당 판매대수 | J17: =J$5/J16 -> 755.91667 | K17: =K$5/K16 -> 755.91667 | L17: =L$5/L16 -> 1511.8333 | M17: =Control!J108 -> 1511.8333 | N17: =Control!K108 -> 1511.8333 | O17: =Control!L108 -> 1511.8333 | P17: =Control!M108 -> 1511.8333 | Q17: =Control!N108 -> 1511.8333
E18: 평균급여 | J18: =J15/J16 -> 18.395862 | K18: =J18 -> 18.395862 | L18: =J18+K18 -> 36.791723 | M18: =Control!J109 -> 37.527558 | N18: =Control!K109 -> 38.278109 | O18: =Control!L109 -> 39.043671 | P18: =Control!M109 -> 39.824544 | Q18: =Control!N109 -> 40.621035
C19: 경매 | J19: =J20+J24 -> 715.81514 | K19: =K20+K24 -> 715.81514 | L19: =L20+L24 -> 1431.6303 | M19: =M20+M24 -> 1748.1387 | N19: =N20+N24 -> 2124.0897 | O19: =O20+O24 -> 2615.8305 | P19: =P20+P24 -> 3175.6593 | Q19: =Q20+Q24 -> 3912.638
D20: 남 | J20: =VALUE(Dart_Labor!S12)/1000 -> 670.2991 | K20: =K21*K23 -> 670.2991 | L20: =L21*L23 -> 1340.5982 | M20: =M21*M23 -> 1655.286 | N20: =N21*N23 -> 1982.025 | O20: =O21*O23 -> 2470.9246 | P20: =P21*P23 -> 2978.5872 | Q20: =Q21*Q23 -> 3661.3711
E21: 직원수 | J21: =VALUE(Dart_Labor!H12) -> 19 | K21: =J21 -> 19 | L21: =K21 -> 19 | M21: =ROUND(M$7/M22,0) -> 23 | N21: =ROUND(N$7/N22,0) -> 27 | O21: =ROUND(O$7/O22,0) -> 33 | P21: =ROUND(P$7/P22,0) -> 39 | Q21: =ROUND(Q$7/Q22,0) -> 47
F22: 1인당 경매매출 | J22: =J$7/J21 -> 3640.6316 | K22: =K$7/K21 -> 3640.6316 | L22: =L$7/L21 -> 7281.2632 | M22: =Control!J111 -> 7281.2632 | N22: =Control!K111 -> 7281.2632 | O22: =Control!L111 -> 7281.2632 | P22: =Control!M111 -> 7281.2632 | Q22: =Control!N111 -> 7281.2632
E23: 평균급여 | J23: =J20/J21 -> 35.2789 | K23: =J23 -> 35.2789 | L23: =J23+K23 -> 70.5578 | M23: =Control!J112 -> 71.968956 | N23: =Control!K112 -> 73.408335 | O23: =Control!L112 -> 74.876502 | P23: =Control!M112 -> 76.374032 | Q23: =Control!N112 -> 77.901512
D24: 여 | J24: =VALUE(Dart_Labor!S13)/1000 -> 45.516042 | K24: =K25*K27 -> 45.516042 | L24: =L25*L27 -> 91.032085 | M24: =M25*M27 -> 92.852727 | N24: =N25*N27 -> 142.06467 | O24: =O25*O27 -> 144.90597 | P24: =P25*P27 -> 197.07211 | Q24: =Q25*Q27 -> 251.26694
E25: 직원수 | J25: =VALUE(Dart_Labor!H13) -> 2 | K25: =J25 -> 2 | L25: =K25 -> 2 | M25: =ROUND(M$7/M26,0) -> 2 | N25: =ROUND(N$7/N26,0) -> 3 | O25: =ROUND(O$7/O26,0) -> 3 | P25: =ROUND(P$7/P26,0) -> 4 | Q25: =ROUND(Q$7/Q26,0) -> 5
F26: 1인당 경매매출 | J26: =J$7/J25 -> 34586 | K26: =K$7/K25 -> 34586 | L26: =L$7/L25 -> 69172 | M26: =Control!J113 -> 69172 | N26: =Control!K113 -> 69172 | O26: =Control!L113 -> 69172 | P26: =Control!M113 -> 69172 | Q26: =Control!N113 -> 69172
E27: 평균급여 | J27: =J24/J25 -> 22.758021 | K27: =J27 -> 22.758021 | L27: =J27+K27 -> 45.516042 | M27: =Control!J114 -> 46.426363 | N27: =Control!K114 -> 47.354891 | O27: =Control!L114 -> 48.301988 | P27: =Control!M114 -> 49.268028 | Q27: =Control!N114 -> 50.253389
C28: 렌탈 | J28: =J29+J33 -> 1202.318 | K28: =K29+K33 -> 1202.318 | L28: =L29+L33 -> 2404.6361 | M28: =M29+M33 -> 2956.9264 | N28: =N29+N33 -> 3605.353 | O28: =O29+O33 -> 4426.0576 | P28: =P29+P33 -> 5434.2217 | Q28: =Q29+Q33 -> 6560.5395
D29: 남 | J29: =VALUE(Dart_Labor!S14)/1000 -> 901.17408 | K29: =K30*K32 -> 901.17408 | L29: =L30*L32 -> 1802.3482 | M29: =M30*M32 -> 2206.0742 | N29: =N30*N32 -> 2700.2348 | O29: =O30*O32 -> 3289.786 | P29: =P30*P32 -> 4057.9128 | Q29: =Q30*Q32 -> 4935.0463
E30: 직원수 | J30: =VALUE(Dart_Labor!H14) -> 25 | K30: =J30 -> 25 | L30: =K30 -> 25 | M30: =ROUND(M$8/M31,0) -> 30 | N30: =ROUND(N$8/N31,0) -> 36 | O30: =ROUND(O$8/O31,0) -> 43 | P30: =ROUND(P$8/P31,0) -> 52 | Q30: =ROUND(Q$8/Q31,0) -> 62
F31: 1인당 렌탈매출 | J31: =J$8/J30 -> 895.68 | K31: =K$8/K30 -> 895.68 | L31: =L$8/L30 -> 1791.36 | M31: =Control!J116 -> 1791.36 | N31: =Control!K116 -> 1791.36 | O31: =Control!L116 -> 1791.36 | P31: =Control!M116 -> 1791.36 | Q31: =Control!N116 -> 1791.36
E32: 평균급여 | J32: =J29/J30 -> 36.046963 | K32: =J32 -> 36.046963 | L32: =J32+K32 -> 72.093927 | M32: =Control!J117 -> 73.535805 | N32: =Control!K117 -> 75.006521 | O32: =Control!L117 -> 76.506652 | P32: =Control!M117 -> 78.036785 | Q32: =Control!N117 -> 79.597521
D33: 여 | J33: =VALUE(Dart_Labor!S15)/1000 -> 301.14395 | K33: =K34*K36 -> 301.14395 | L33: =L34*L36 -> 602.2879 | M33: =M34*M36 -> 750.85225 | N33: =N34*N36 -> 905.11826 | O33: =O34*O36 -> 1136.2715 | P33: =P34*P36 -> 1376.3089 | Q33: =Q34*Q36 -> 1625.4932
E34: 직원수 | J34: =VALUE(Dart_Labor!H15) -> 9 | K34: =J34 -> 9 | L34: =K34 -> 9 | M34: =ROUND(M$8/M35,0) -> 11 | N34: =ROUND(N$8/N35,0) -> 13 | O34: =ROUND(O$8/O35,0) -> 16 | P34: =ROUND(P$8/P35,0) -> 19 | Q34: =ROUND(Q$8/Q35,0) -> 22
F35: 1인당 렌탈매출 | J35: =J$8/J34 -> 2488 | K35: =K$8/K34 -> 2488 | L35: =L$8/L34 -> 4976 | M35: =Control!J118 -> 4976 | N35: =Control!K118 -> 4976 | O35: =Control!L118 -> 4976 | P35: =Control!M118 -> 4976 | Q35: =Control!N118 -> 4976
E36: 평균급여 | J36: =J33/J34 -> 33.460439 | K36: =J36 -> 33.460439 | L36: =J36+K36 -> 66.920878 | M36: =Control!J119 -> 68.259295 | N36: =Control!K119 -> 69.624481 | O36: =Control!L119 -> 71.016971 | P36: =Control!M119 -> 72.43731 | Q36: =Control!N119 -> 73.886057
C37: 마케팅 | J37: =J38+J41 -> 786.11388 | K37: =K38+K41 -> 786.11388 | L37: =L38+L41 -> 1572.2278 | M37: =M38+M41 -> 1721.1217 | N37: =N38+N41 -> 1995.1408 | O37: =O38+O41 -> 2279.4323 | P37: =P38+P41 -> 2574.2974 | Q37: =Q38+Q41 -> 2880.0452
D38: 남 | J38: =VALUE(Dart_Labor!S16)/1000 -> 476.1762 | K38: =K39*K40 -> 476.1762 | L38: =L39*L40 -> 952.35241 | M38: =M39*M40 -> 1036.1594 | N38: =N39*N40 -> 1188.9929 | O38: =O39*O40 -> 1347.5253 | P38: =P39*P40 -> 1511.9234 | Q38: =Q39*Q40 -> 1682.3584
E39: 직원수 | J39: =VALUE(Dart_Labor!H16) -> 15 | K39: =J39 -> 15 | L39: =K39 -> 15 | M39: =Control!J121 -> 16 | N39: =Control!K121 -> 18 | O39: =Control!L121 -> 20 | P39: =Control!M121 -> 22 | Q39: =Control!N121 -> 24
E40: 평균급여 | J40: =J38/J39 -> 31.74508 | K40: =J40 -> 31.74508 | L40: =J40+K40 -> 63.490161 | M40: =Control!J122 -> 64.759964 | N40: =Control!K122 -> 66.055163 | O40: =Control!L122 -> 67.376266 | P40: =Control!M122 -> 68.723792 | Q40: =Control!N122 -> 70.098268
D41: 여 | J41: =VALUE(Dart_Labor!S17)/1000 -> 309.93767 | K41: =K42*K43 -> 309.93767 | L41: =L42*L43 -> 619.87535 | M41: =M42*M43 -> 684.96226 | N41: =N42*N43 -> 806.14789 | O41: =O42*O43 -> 931.90696 | P41: =P42*P43 -> 1062.3739 | Q41: =Q42*Q43 -> 1197.6868
...

Sheet NWC
B1: NWC | E1: Index
E4: Historical | J4: Forecast
B5: KRW in 100 millions | E5: 2018 | F5: 2019 | G5: 2020 | H5: 2021.1H | I5: 2021.2H | J5: 2021 | K5: 2022 | L5: 2023 | M5: 2024 | N5: 2025 | O5: 2016
B6: Sales | E6: =Sales!I160 -> 742803 | F6: =Sales!J160 -> 1185356 | G6: =Sales!K160 -> 1323114 | H6: =Sales!L160 -> 910585 | I6: =Sales!M160 -> 910585 | J6: =Sales!N160 -> 1821170 | K6: =Sales!O160 -> 1902459 | L6: =Sales!P160 -> 2256380 | ... O6: =Sales!S160 -> 3792952.9
B7: 변동비 | E7: =Cost!E19 -> 688489.81 | F7: =Cost!F19 -> 1088832.5 | G7: =Cost!G19 -> 1210703.1 | H7: =Cost!H19 -> 812768.74 | I7: =Cost!I19 -> 812768.74 | J7: =Cost!J19 -> 1625537.5 | K7: =Cost!K19 -> 1670801.7 | L7: =Cost!L19 -> 1985483.9 | ... O7: =Cost!O19 -> 3356864.7
B8: 재고자산원가 | E8: =Cost!E21 -> 663748.17 | F8: =Cost!F21 -> 1053521.7 | G8: =Cost!G21 -> 1170061.6 | H8: =Cost!H21 -> 784113.35 | I8: =Cost!I21 -> 784113.35 | J8: =Cost!J21 -> 1568226.7 | K8: =Cost!K21 -> 1604124.1 | L8: =Cost!L21 -> 1906290.6 | ... O8: =Cost!O21 -> 3223324.1
B9: 영업유동자산 | E9: =E10+E12+E14 -> 135219.49 | F9: =F10+F12+F14 -> 157121.87 | G9: =G10+G12+G14 -> 168447.6 | H9: =H10+H12+H14 -> 178547.76 | I9: =I10+I12+I14 -> 178547.76 | J9: =J10+J12+J14 -> 178547.76 | K9: =K10+K12+K14 -> 246242.93 | L9: =L10+L12+L14 -> 272616.85 | ... O9: =O10+O12+O14 -> 460045.96
C10: 매출채권 | E10: =BS!E7 -> 7325.6303 | F10: =BS!F7 -> 4038.9555 | G10: =BS!G7 -> 4665.2039 | H10: =BS!H7 -> 7961.0649 | I10: =H10 -> 7961.0649 | J10: =I10 -> 7961.0649 | K10: =AVERAGE(J$6:K$6)*Control!J141 -> 8051.0053 | L10: =AVERAGE(K$6:L$6)*Control!K141 -> 8991.99 | M10: =AVERAGE(L$6:M$6)*Control!L141 -> 10672.306 | N10: =AVERAGE(M$6:N$6)*Control!M141 -> 12682.646 | O10: =AVERAGE(N$6:O$6)*Control!N141 -> 15089.841
D11: % of Sales | F11: =F10/AVERAGE(E$6:F$6) -> 0.0041894423 | G11: =G10/AVERAGE(F$6:G$6) -> 0.0037195613 | H11: =H10/AVERAGE(G$6,H$6*2) -> 0.0050638332 | I11: =I10/AVERAGE(G$6,I$6*2) -> 0.0050638332 | J11: =J10/AVERAGE(G$6,J$6) -> 0.0050638332 | K11: =K10/AVERAGE(J$6:K$6) -> 0.0043242789 | L11: =L10/AVERAGE(K$6:L$6) -> 0.0043242789 | M11: =M10/AVERAGE(L$6:M$6) -> 0.0043242789 | N11: =N10/AVERAGE(M$6:N$6) -> 0.0043242789 | O11: =O10/AVERAGE(N$6:O$6) -> 0.0043242789
C12: 재고자산 | E12: =BS!E11 -> 125377.11 | F12: =BS!F11 -> 150417.73 | G12: =BS!G11 -> 161331.91 | H12: =BS!H11 -> 165762.87 | I12: =H12 -> 165762.87 | J12: =I12 -> 165762.87 | K12: =AVERAGE(J$8:K$8)*Control!J142 -> 233359.54 | L12: =AVERAGE(K$8:L$8)*Control!K142 -> 258227.67 | M12: =AVERAGE(L$8:M$8)*Control!L142 -> 307085.38 | N12: =AVERAGE(M$8:N$8)*Control!M142 -> 365647.51 | O12: =AVERAGE(N$8:O$8)*Control!N142 -> 435898.88
D13: % of 재고자산원가 | F13: =F12/AVERAGE(E$8:F$8) -> 0.17518241 | G13: =G12/AVERAGE(F$8:G$8) -> 0.14510984 | H13: =H12/AVERAGE(G$8,H$8*2) -> 0.12107043 | I13: =I12/AVERAGE(G$8,I$8*2) -> 0.12107043 | J13: =J12/AVERAGE(G$8,J$8) -> 0.12107043 | K13: =K12/AVERAGE(J$8:K$8) -> 0.1471209 | L13: =L12/AVERAGE(K$8:L$8) -> 0.1471209 | M13: =M12/AVERAGE(L$8:M$8) -> 0.1471209 | N13: =N12/AVERAGE(M$8:N$8) -> 0.1471209 | O13: =O12/AVERAGE(N$8:O$8) -> 0.1471209
C14: 기타유동자산 | E14: =BS!E10 -> 2516.7444 | F14: =BS!F10 -> 2665.187 | G14: =BS!G10 -> 2450.4877 | H14: =BS!H10 -> 4823.8253 | I14: =H14 -> 4823.8253 | J14: =I14 -> 4823.8253 | K14: =AVERAGE(J$6:K$6)*Control!J143 -> 4832.3853 | L14: =AVERAGE(K$6:L$6)*Control!K143 -> 5397.1844 | M14: =AVERAGE(L$6:M$6)*Control!L143 -> 6405.7462 | N14: =AVERAGE(M$6:N$6)*Control!M143 -> 7612.3949 | O14: =AVERAGE(N$6:O$6)*Control!N143 -> 9057.2448
