Workbook

Sheet 일정표
C4: 2019 | J4: 2020 | V4: 2021 | AH4: 2022 | AT4: 2023 | BF4: 2024
C5: 6 | D5: 7 | E5: 8 | F5: 9 | G5: 10 | H5: 11 | I5: 12 | J5: 1 | K5: 2 | L5: 3 | M5: 4 | N5: 5 | O5: 6 | P5: 7 | Q5: 8 | R5: 9 | S5: 10 | T5: 11 | U5: 12 | V5: 1 | W5: 2 | X5: 3 | Y5: 4 | Z5: 5 | AA5: 6 | AB5: 7 | AC5: 8 | AD5: 9 | AE5: 10 | AF5: 11 | AG5: 12 | AH5: 1 | AI5: 2 | AJ5: 3 | AK5: 4 | AL5: 5 | AM5: 6 | AN5: 7 | AO5: 8 | AP5: 9 | AQ5: 10 | AR5: 11 | AS5: 12 | AT5: 1 | AU5: 2 | AV5: 3 | AW5: 4 | AX5: 5 | AY5: 6 | AZ5: 7 | BA5: 8 | BB5: 9 | BC5: 10 | BD5: 11 | BE5: 12 | BF5: 1 | BG5: 2 | BH5: 3 | BI5: 4 | BJ5: 5 | BK5: 6 | BL5: 7 | BM5: 8 | BN5: 9 | BO5: 10 | BP5: 11 | BQ5: 12
B7: W.V 내부 보고
B8: 관계사 업무협약
B9: 주무관청 협의
B10: 건축 관련 인허가
B11: 임차인 명도
B12: 펀드 설정
B13: 지상권 설정 계약
B14: 건축물 철거
B15: 착공 준비
B16: 착공
B17: 임대차 마케팅
B18: 준공
... B24: ROLE & RESPONSIBILITIES (R&R)
B25: 월드비전 | C25: 공사 관련 내부 보고 완료
C26: 업무협약 체결
C27: 주무관청 허가 득
C28: 건축 관련 인허가 득
C29: 임차인 명도
C30: 지상권 설정 계약
C31: 공사기간 이전 사무실 확보
B34: 하나대체 | C34: 업무협약 체결
C35: 사업성 검토(감평,법률,재무,물리)
C36: 펀드 설정
C37: 지상권 설정 계약 체결
C38: 사업 진행을 위한 제반 계약 체결(PF대출, 철거&시공 등)
B41: 하나금투 | C41: 업무협약 체결
C42: 자본금 및 PF대출금(PF주선 등) 재원 마련
B45: 간삼 | C45: 업무협약 체결
C46: 건축 설계
C47: 공사 기간 사업 관리
C48: 임대 마케팅

Sheet Control Panel_개발
B2: 사업개요
B3: 사업명 | D3: 월드비전 여의도 사옥 | H3: 인허가개시일 | I3: 43708 | M3: 부가가치세율 | N3: 0.1
B4: 소재지 | D4: 서울특별시 영등포구 여의나루로 77-1 (여의도동 24-2) | H4: 펀드설정일 | I4: =I3 -> 43708 | J4: =MONTH(I4) -> 8 | M4: 부가세확정신고기간 | N4: 6
B5: 용도지역 | D5: 일반상업지역, 과밀억제권역, 가로구역별최고높이제한지역 | H5: 기간조정 | I5: =EOMONTH(I4,-J4) -> 43465 | J5: =EOMONTH(I4,-1)-$I$5 -> 212 | M5: 첫부가세납부일 | N5: 43890 | O5: =MOD(MONTH(N5),N4) -> 2
B6: 규모 | D6: 지하6층 / 지상16층 | H6: 착공일 | I6: =EOMONTH(I4,16) -> 44196 | M6: 부가세환급주기 | N6: 2
B7: 주용도 | D7: 업무시설, 근린생활시설 | H7: 공사기간 | I7: 26 | M7: 제세공과금 납부 | N7: 12
B8: 대지면적 | E8: 1547 | F8: =E8*0.3025 -> 467.9675 | H8: 준공일 | I8: =EOMONTH(I6,I7-1) -> 44957 | M8: 재산세_토지 | N8: 44104 | O8: =MOD(MONTH(N8),$N7) -> 9
B9: 건축면적 | E9: 907.9 | F9: =E9*0.3025 -> 274.63975 | H9: 사용승인일 | I9: =EOMONTH(I8,2) -> 45016 | M9: 교통유발부담금 | N9: 45230 | O9: =MOD(MONTH(N9),$N7) -> 10
B10: 연면적 | E10: =SUM(E11:E12) -> 21237.81 | F10: =SUM(F11:F12) -> 6424.4375 | H10: PF종료일 | I10: =EOMONTH(I8,7) -> 45169 | M10: 도로점용료 | N10: 45016 | O10: =MOD(MONTH(N10),$N7) -> 3
C11: 지상층 연면적 | E11: 14402.65 | F11: =E11*0.3025 -> 4356.8016 | H11: 이자지급주기 | I11: 3 | M11: 회계연도 | N11: 개시 | O11: 종료 | P11: 마지막월
C12: 지하층 연면적 | E12: 6835.16 | F12: =E12*0.3025 -> 2067.6359 | H12: 첫이자지급일(선순위) | I12: 43799 | J12: =MOD(MONTH(I12),$I$11) -> 2 | M12: 1 | N12: =I4+1 -> 43709 | O12: =EOMONTH(N12-1,$I$14) -> 43890 | P12: =MONTH(O12) -> 2
C13: 지하층 연면적(주차면적 제외) | E13: 1427.97 | F13: =E13*0.3025 -> 431.96092 | H13: 첫이자지급일(중순위) | I13: 43799 | J13: =MOD(MONTH(I13),$I$11) -> 2 | M13: 2 | N13: =O12+1 -> 43891 | O13: =EOMONTH(N13-1,$I$14) -> 44074 | P13: =MONTH(O13) -> 8
B14: 용적률 산정용 연면적 | E14: =E11 -> 14402.65 | F14: =E14*0.3025 -> 4356.8016 | H14: 배당정산주기 | I14: 6 | M14: 3 | N14: =O13+1 -> 44075 | O14: =EOMONTH(N14-1,$I$14) -> 44255 | P14: =MONTH(O14) -> 2
B15: 건폐율 | E15: =E9/E8 -> 0.58687783 | F15: 0.6 | H15: 배당첫정산일 | I15: =EOMONTH($I$4,$I$14) -> 43890 | J15: =MOD(MONTH(I15),I14) -> 2 | M15: 4 | N15: =O14+1 -> 44256 | O15: =EOMONTH(N15-1,$I$14) -> 44439 | P15: =MONTH(O15) -> 8
B16: 용적률 | E16: =E14/E8 -> 9.3100517 | F16: 9.5 | M16: 금액 단위 | N16: 1000
M17: 면적 환산 | N17: 3.3 | O17: 0.3025
B20: 재원조달 세부내역 | F20: (단위, 천원)
B21: 구분 | F21: 금액 | G21: 비율 | H21: LTV | J21: 비고
B22: 1. Dept | F22: =SUM(F23:F25) -> 48000000 | G22: =F22/$F$36 -> 0.73846154 | H22: 담보평가금액 | I22: 비율
C23: 선순위차입금(PF대출) | F23: 48000000 | G23: =F23/$F$36 -> 0.73846154 | H23: 54000000 | I23: =(F25+F23)/$H$23 -> 0.88888889 | J23: 이자율 | K23: 0.0675 | M23: 대출취급수수료 | N23: 0.01 | R23: =F23/(F31-F105) -> 3.9215686
C24: 중순위차입금(Mezz.) | F24: 0 | G24: =F24/$F$36 -> 0 | I24: =(F25+F23+F24)/$H$23 -> 0.88888889 | J24: 이자율 | K24: 0 | M24: 대출취급수수료 | N24: 0
C25: 보증금 | F25: 0 | G25: =F25/$F$36 -> 0
C27: 단기차입금(VAT) | F27: 0 | J27: 이자율 | K27: 0
B29: 2. Equity | F29: =SUM(F30,F34) -> 17000000 | G29: =F29/$F$36 -> 0.26153846
C30: 제1종수익증권 | F30: =SUM(F31:F33) -> 17000000 | G30: =F30/$F$30 -> 1 | H30: =SUM(H31:H33) -> 1 | J30: 배당률 | K30: 0.07 | M30: 원본취급수수료 | N30: 0.03
D31: 투자자A | F31: 17000000 | G31: =F31/$F$30 -> 1 | H31: 1
D32: 투자자B | F32: 0 | G32: =F32/$F$30 -> 0 | H32: 0
D33: 투자자C | F33: 0 | G33: =F33/$F$30 -> 0 | H33: 0
C34: 제2종수익증권 | F34: 0 | G34: =F34/$F$36 -> 0
B36: 총조달금액 | F36: =F22+F29 -> 65000000 | G36: =F36/$F$36 -> 1
B39: 총사업비 세부내역 | F39: (단위, 천원)
B40: 구분 | F40: 금액 | G40: 비율 | H40: 산정내역 등
B41: 1. 토지비용 | F41: =SUM(F42:F52) -> 3051100 | G41: =F41/$F$115 -> 0.04694
C42: 토지매입비(계약금) | F42: 0 | G42: =F42/$F$115 -> 0
C43: 토지매입비(중도금) | F43: 0 | G43: =F43/$F$115 -> 0
C44: 지료 선납금 | F44: 3000000 | G44: =F44/$F$115 -> 0.046153846 | H44: ='제세공과금 및 부담금_개발'!M10/'제세공과금 및 부담금_개발'!C1 -> 18523214 | J44: 당해년도 공시지가 합계액의 | K44: 0.04 | L44: 의 4년치가 해당해는 금액 | O44: =H44*K44*4 -> 2963714.3
C45: 취등록세(토지) | F45: 0 | G45: =F45/$F$115 -> 0 | H45: "제세공과금 및 부담금" Sheet 참조
C46: 지상권 설정비(토지) | F46: 50000 | G46: =F46/$F$115 -> 0.00076923077 | H46: "제세공과금 및 부담금" Sheet 참조
C47: 국민주택채권매입(소유권 이전) | F47: 0 | G47: =F47/$F$115 -> 0 | H47: "제세공과금 및 부담금" Sheet 참조
C48: 국민주택채권매입(지상권 설정) | F48: 0 | G48: =F48/$F$115 -> 0 | H48: "제세공과금 및 부담금" Sheet 참조
...

Sheet Control Panel_운영
A1: Physical Information_I | I1: Physical Information_II
B2: 건물명 | C2: 월드비전 여의도 사옥 | J2: 건물명
B3: 소재지 | C3: 서울특별시 영등포구 여의나루로 77-1 (여의도동 24-2) | J3: 소재지
B4: 건물개요 | C4: 매입 대상 | E4: 전체 | G4: 부동산수 | J4: 건물개요 | K4: 매입 대상 | M4: 건물 개요 | O4: 부동산수
B5: 대지면적 | C5: 1547 | D5: =C5*$N$95 -> 467.9675 | E5: 1547 | F5: =E5*$N$95 -> 467.9675 | G5: 4 | J5: 대지면적 | K5: 0 | L5: =K5*$N$95 -> 0 | M5: 0 | N5: =M5*$N$95 -> 0 | O5: 0
B6: 건축면적 | C6: 907.9 | D6: =C6*$N$95 -> 274.63975 | E6: 907.9 | F6: =E6*$N$95 -> 274.63975 | J6: 건축면적 | K6: 0 | L6: =K6*$N$95 -> 0 | M6: 0 | N6: =M6*$N$95 -> 0
B7: 연면적 | C7: 21237.81 | D7: =C7*$N$95 -> 6424.4375 | E7: 21237.81 | F7: =E7*$N$95 -> 6424.4375 | J7: 연면적 | K7: 0 | L7: =K7*$N$95 -> 0 | M7: 0 | N7: =M7*$N$95 -> 0
B8: 용적률연면적 | C8: 14402.65 | D8: =C8*$N$95 -> 4356.8016 | E8: 14402.65 | F8: =E8*$N$95 -> 4356.8016 | J8: 용적률연면적 | K8: 0 | L8: =K8*$N$95 -> 0 | M8: 0 | N8: =M8*$N$95 -> 0
B9: 건폐율 | C9: =IFERROR(C6/C5,0) -> 0.58687783 | E9: =IFERROR(E6/E5,0) -> 0.58687783 | J9: 건폐율 | K9: =IFERROR(K6/K5,0) -> 0 | M9: =IFERROR(M6/M5,0) -> 0
B10: 용적률 | C10: =IFERROR(C8/C5,0) -> 9.3100517 | E10: =IFERROR(E8/E5,0) -> 9.3100517 | J10: 용적률 | K10: =IFERROR(K8/K5,0) -> 0 | M10: =IFERROR(M8/M5,0) -> 0
B11: 전용률 | C11: 0.68 | E11: 0.68 | J11: 전용률 | K11: 0 | M11: 0
B12: 규모 | C12: 지하6층 / 지상16층 | E12: 지하6층 / 지상16층 | J12: 규모
B13: 용도지역 | C13: 일반상업지역 | E13: 일반상업지역 | J13: 용도지역
B14: 주용도 | C14: 업무시설, 근린생활시설 | E14: 업무시설, 근린생활시설 | J14: 주용도
B15: 구조 | C15: 철골철근콘크리트 | E15: 철골철근콘크리트 | J15: 구조
B16: 사용승인일자 | C16: 45016 | E16: 45016 | J16: 사용승인일자
B17: 주차시설 | C17: 합계 | D17: 옥내기계식 | E17: 옥내자주식 | F17: 옥외기계식 | G17: 옥외자주식 | J17: 주차시설 | K17: 합계 | L17: 옥내기계식 | M17: 옥내자주식 | N17: 옥외기계식 | O17: 옥외자주식
C18: =D18+E18+F18+G18 -> 421 | D18: 0 | E18: 421 | F18: 0 | G18: 0 | K18: =L18+M18+N18+O18 -> 0 | L18: 0 | M18: 0 | N18: 0 | O18: 0
B19: 승강기 | C19: 승용 | D19: 비상용 | J19: 승강기 | K19: 승용 | L19: 비상용
C20: 4 | D20: 0 | G20: 담보평가금액 | K20: 0 | L20: 0 | O20: 담보평가금액
B21: 매입금액 | D21: =SUM(D22:D23) -> 1 | E21: =IFERROR(F21/D7,0) -> 10039.789 | F21: 64500000 | G21: 96000000 | J21: 매입금액 | L21: =SUM(L22:L23) -> 0 | M21: =IFERROR(N21/L7,0) -> 0 | N21: 0 | O21: =N21 -> 0
C22: 토지 | D22: 0.5 | E22: =IFERROR(F22/D5,0) -> 68915.042 | F22: =F21*D22 -> 32250000 | K22: 토지 | L22: 0 | M22: =IFERROR(N22/L5,0) -> 0 | N22: =N21*L22 -> 0
C23: 건물 | D23: 0.5 | F23: =F21*D23 -> 32250000 | K23: 건물 | L23: 0 | N23: =N21*L23 -> 0
B24: 보증금 | F24: ='Rent Roll'!L4/'Rent Roll'!C48 -> 0 | J24: 보증금 | N24: 0
B25: 담보대출 | F25: =F26+F27 -> 48000000 | G25: LTV | J25: 담보대출 | N25: =N26+N27 -> 0 | O25: LTV
B26: Sr. Loan | C26: LTV 한도 | D26: =$L$151 -> 0.5 | F26: =ROUNDDOWN(G21*D26-F24,-5) -> 48000000 | G26: =IFERROR((F24+F26)/G21,0) -> 0.5 | J26: Sr. Loan | K26: LTV 한도 | L26: =$L$151 -> 0.5 | N26: =ROUNDDOWN(O21*L26-N24,-5) -> 0 | O26: =IFERROR((N24+N26)/O21,0) -> 0
B27: Jr. Loan | C27: LTV 한도 | D27: =$L$152 -> 0 | F27: =IF(ROUNDDOWN(G21*D27-F24-F26,-5)>0,ROUNDDOWN(G21*D27-F24-F26,-5),0) -> 0 | G27: =IFERROR((F24+F26+F27)/G21,0) -> 0.5 | J27: Jr. Loan | K27: LTV 한도 | L27: =$L$152 -> 0 | N27: =IF(ROUNDDOWN(O21*L27-N24-N26,-5)>0,ROUNDDOWN(O21*L27-N24-N26,-5),0) -> 0 | O27: =IFERROR((N24+N26+N27)/O21,0) -> 0
A28: Physical Information_III | I28: Physical Information_IV
B29: 건물명 | J29: 건물명
B30: 소재지 | J30: 소재지
B31: 건물개요 | C31: 매입 대상 | E31: 건물 개요 | G31: 부동산수 | J31: 건물개요 | K31: 매입 대상 | M31: 건물 개요 | O31: 부동산수
B32: 대지면적 | C32: 0 | D32: =C32*$N$95 -> 0 | E32: 0 | F32: =E32*$N$95 -> 0 | G32: 0 | J32: 대지면적 | K32: 0 | L32: =K32*$N$95 -> 0 | M32: 0 | N32: =M32*$N$95 -> 0 | O32: 0
B33: 건축면적 | C33: 0 | D33: =C33*$N$95 -> 0 | E33: 0 | F33: =E33*$N$95 -> 0 | J33: 건축면적 | K33: 0 | L33: =K33*$N$95 -> 0 | M33: 0 | N33: =M33*$N$95 -> 0
B34: 연면적 | C34: 0 | D34: =C34*$N$95 -> 0 | E34: 0 | F34: =E34*$N$95 -> 0 | J34: 연면적 | K34: 0 | L34: =K34*$N$95 -> 0 | M34: 0 | N34: =M34*$N$95 -> 0
B35: 용적률연면적 | C35: 0 | D35: =C35*$N$95 -> 0 | E35: 0 | F35: =E35*$N$95 -> 0 | J35: 용적률연면적 | K35: 0 | L35: =K35*$N$95 -> 0 | M35: 0 | N35: =M35*$N$95 -> 0
B36: 건폐율 | C36: =IFERROR(C33/C32,0) -> 0 | E36: =IFERROR(E33/E32,0) -> 0 | J36: 건폐율 | K36: =IFERROR(K33/K32,0) -> 0 | M36: =IFERROR(M33/M32,0) -> 0
B37: 용적률 | C37: =IFERROR(C35/C32,0) -> 0 | E37: =IFERROR(E35/E32,0) -> 0 | J37: 용적률 | K37: =IFERROR(K35/K32,0) -> 0 | M37: =IFERROR(M35/M32,0) -> 0
B38: 전용률 | C38: 0 | E38: 0 | J38: 전용률 | K38: 0 | M38: 0
B39: 규모 | J39: 규모
B40: 용도지역 | J40: 용도지역
...

Sheet Rent Roll
A1: Rent Roll
B2: 임차인 | C2: 계약기간 | E2: 전용률 | F2: 임대면적(㎡) | I2: 임대면적(평) | L2: 보증금 | Q2: 임대료 | X2: 관리비 | AC2: NOC | AD2: 임대대행수수료 | AI2: Fit IN | AM2: Rent-Free
C3: 개시 | D3: 종료 | F3: 전용 | G3: 공용 | H3: 합계 | I3: 전용 | J3: 공용 | K3: 합계 | L3: 금액 | M3: 평당 | N3: 상승률 | Q3: 연임대료 | R3: 월임대료 | S3: 평당 | T3: 상승률 | W3: 비고 | X3: 월관리비 | Y3: 평당 | Z3: 상승률 | AD3: 수수료율 | AE3: 금액 | AF3: 발생일 | AG3: 상각기간 | AH3: 월 상각액 | AI3: 적용기간 | AJ3: 적용월 | AM3: 적용기간 | AN3: 적용월
C4: 45169 | D4: 47361 | F4: =SUM(F5:F23) -> 12493.22 | G4: =SUM(G5:G23) -> 8744.58 | H4: =SUM(H5:H23) -> 21237.8 | I4: =SUM(I5:I23) -> 3779.19 | J4: =SUM(J5:J23) -> 2645.25 | K4: =SUM(K5:K23) -> 6424.44 | L4: =SUM(L5) -> 0 | Q4: =SUM(Q5:Q18) -> 5498482200 | R4: =SUM(R5:R18) -> 458206850 | X4: =SUM(X5:X18) -> 187568450
B5: 월드비전 | C5: 45169 | D5: 48822 | E5: =F5/H5 -> 0.59886225 | F5: 6135.2 | G5: =H5-F5 -> 4109.56 | H5: 10244.76 | I5: =ROUND(F5*$D$49,2) -> 1855.9 | J5: =ROUND(G5*$D$49,2) -> 1243.14 | K5: =ROUND(H5*$D$49,2) -> 3099.04 | L5: 0 | M5: =IFERROR(L5/K5,0) -> 0 | N5: 0 | O5: 0 | P5: 1 | Q5: =R5*12 -> 2417251200 | R5: =S5*K5 -> 201437600 | S5: 65000 | T5: 0.02 | U5: 1 | V5: 1 | W5: 월납입 | X5: =Y5*K5 -> 92971200 | Y5: 30000 | Z5: 0.02 | AA5: 1 | AB5: 1 | AC5: =(M5*$C$50/12+S5+Y5)/E5 -> 158634.14 | AD5: 0 | AE5: =AD5*R5 -> 0 | AF5: 0 | AG5: =MIN(DATEDIF(AF5,'Control Panel_운영'!$K$90,"m"),3) -> 3 | AH5: =IFERROR(AE5/AG5,0) -> 0 | AI5: =COUNTIF(AJ5:AL5,">0") -> 0 | AJ5: 0 | AK5: 0 | AL5: 0 | AM5: =COUNTIF(AN5:AS5,">0") -> 3 | AN5: 4 | AO5: 8 | AP5: 12 | AQ5: 0 | AR5: 0 | AS5: 0
B6: 16층 | C6: 45169 | D6: 47361 | E6: =F6/H6 -> 0.5988619 | F6: 771.4 | G6: =H6-F6 -> 516.71 | H6: 1288.11 | I6: =ROUND(F6*$D$49,2) -> 233.35 | J6: =ROUND(G6*$D$49,2) -> 156.3 | K6: =ROUND(H6*$D$49,2) -> 389.65 | L6: 0 | M6: =IFERROR(L6/K6,0) -> 0 | N6: 0 | O6: 0 | P6: 1 | Q6: =R6*12 -> 303927000 | R6: =S6*K6 -> 25327250 | S6: 65000 | T6: 0.02 | U6: 1 | V6: 1 | W6: 월납입 | X6: =Y6*K6 -> 11689500 | Y6: 30000 | Z6: 0.02 | AA6: 1 | AB6: 1 | AC6: =(M6*$C$50/12+S6+Y6)/E6 -> 158634.24 | AD6: 1 | AE6: =AD6*R6 -> 25327250 | AF6: =EOMONTH(C6,1) -> 45199 | AG6: =MIN(DATEDIF(AF6,'Control Panel_운영'!$K$90,"m"),3) -> 3 | AH6: =IFERROR(AE6/AG6,0) -> 8442416.7 | AI6: =COUNTIF(AJ6:AL6,">0") -> 0 | AJ6: 0 | AK6: 0 | AL6: 0 | AM6: =COUNTIF(AN6:AS6,">0") -> 2 | AN6: 2 | AO6: 8 | AP6: 0 | AQ6: 0 | AR6: 0 | AS6: 0
B7: 7층 | C7: 45169 | D7: 47361 | E7: =F7/H7 -> 0.59886332 | F7: 753.4 | G7: =H7-F7 -> 504.65 | H7: 1258.05 | I7: =ROUND(F7*$D$49,2) -> 227.9 | J7: =ROUND(G7*$D$49,2) -> 152.66 | K7: =ROUND(H7*$D$49,2) -> 380.56 | L7: 0 | M7: =IFERROR(L7/K7,0) -> 0 | N7: 0 | O7: 0 | P7: 1 | Q7: =R7*12 -> 296836800 | R7: =S7*K7 -> 24736400 | S7: 65000 | T7: 0.02 | U7: 1 | V7: 1 | W7: 월납입 | X7: =Y7*K7 -> 11416800 | Y7: 30000 | Z7: 0.02 | AA7: 1 | AB7: 1 | AC7: =(M7*$C$50/12+S7+Y7)/E7 -> 158633.86 | AD7: 1 | AE7: =AD7*R7 -> 24736400 | AF7: =EOMONTH(C7,1) -> 45199 | AG7: =MIN(DATEDIF(AF7,'Control Panel_운영'!$K$90,"m"),3) -> 3 | AH7: =IFERROR(AE7/AG7,0) -> 8245466.7 | AI7: =COUNTIF(AJ7:AL7,">0") -> 0 | AJ7: 0 | AK7: 0 | AL7: 0 | AM7: =COUNTIF(AN7:AS7,">0") -> 2 | AN7: 2 | AO7: 8 | AP7: 0 | AQ7: 0 | AR7: 0 | AS7: 0
B8: 6층 | C8: 45535 | D8: 47726 | E8: =F8/H8 -> 0.59886332 | F8: 753.4 | G8: =H8-F8 -> 504.65 | H8: 1258.05 | I8: =ROUND(F8*$D$49,2) -> 227.9 | J8: =ROUND(G8*$D$49,2) -> 152.66 | K8: =ROUND(H8*$D$49,2) -> 380.56 | L8: 0 | M8: =IFERROR(L8/K8,0) -> 0 | N8: 0 | O8: 0 | P8: 1 | Q8: =R8*12 -> 296836800 | R8: =S8*K8 -> 24736400 | S8: 65000 | T8: 0.02 | U8: 1 | V8: 1 | W8: 월납입 | X8: =Y8*K8 -> 11416800 | Y8: 30000 | Z8: 0.02 | AA8: 1 | AB8: 1 | AC8: =(M8*$C$50/12+S8+Y8)/E8 -> 158633.86 | AD8: 1 | AE8: =AD8*R8 -> 24736400 | AF8: =EOMONTH(C8,1) -> 45565 | AG8: =MIN(DATEDIF(AF8,'Control Panel_운영'!$K$90,"m"),3) -> 3 | AH8: =IFERROR(AE8/AG8,0) -> 8245466.7 | AI8: =COUNTIF(AJ8:AL8,">0") -> 0 | AJ8: 0 | AK8: 0 | AL8: 0 | AM8: =COUNTIF(AN8:AS8,">0") -> 2 | AN8: 2 | AO8: 8 | AP8: 0 | AQ8: 0 | AR8: 0 | AS8: 0
B9: 5층 | C9: 45535 | D9: 47726 | E9: =F9/H9 -> 0.59886332 | F9: 753.4 | G9: =H9-F9 -> 504.65 | H9: 1258.05 | I9: =ROUND(F9*$D$49,2) -> 227.9 | J9: =ROUND(G9*$D$49,2) -> 152.66 | K9: =ROUND(H9*$D$49,2) -> 380.56 | L9: 0 | M9: =IFERROR(L9/K9,0) -> 0 | N9: 0 | O9: 0 | P9: 1 | Q9: =R9*12 -> 296836800 | R9: =S9*K9 -> 24736400 | S9: 65000 | T9: 0.02 | U9: 1 | V9: 1 | W9: 월납입 | X9: =Y9*K9 -> 11416800 | Y9: 30000 | Z9: 0.02 | AA9: 1 | AB9: 1 | AC9: =(M9*$C$50/12+S9+Y9)/E9 -> 158633.86 | AD9: 1 | AE9: =AD9*R9 -> 24736400 | AF9: =EOMONTH(C9,1) -> 45565 | AG9: =MIN(DATEDIF(AF9,'Control Panel_운영'!$K$90,"m"),3) -> 3 | AH9: =IFERROR(AE9/AG9,0) -> 8245466.7 | AI9: =COUNTIF(AJ9:AL9,">0") -> 0 | AJ9: 0 | AK9: 0 | AL9: 0 | AM9: =COUNTIF(AN9:AS9,">0") -> 2 | AN9: 2 | AO9: 8 | AP9: 0 | AQ9: 0 | AR9: 0 | AS9: 0
B10: 4층 | C10: 45900 | D10: 48091 | E10: =F10/H10 -> 0.59886332 | F10: 753.4 | G10: =H10-F10 -> 504.65 | H10: 1258.05 | I10: =ROUND(F10*$D$49,2) -> 227.9 | J10: =ROUND(G10*$D$49,2) -> 152.66 | K10: =ROUND(H10*$D$49,2) -> 380.56 | L10: 0 | M10: =IFERROR(L10/K10,0) -> 0 | N10: 0 | O10: 0 | P10: 1 | Q10: =R10*12 -> 296836800 | R10: =S10*K10 -> 24736400 | S10: 65000 | T10: 0.02 | U10: 1 | V10: 1 | W10: 월납입 | X10: =Y10*K10 -> 11416800 | Y10: 30000 | Z10: 0.02 | AA10: 1 | AB10: 1 | AC10: =(M10*$C$50/12+S10+Y10)/E10 -> 158633.86 | AD10: 1 | AE10: =AD10*R10 -> 24736400 | AF10: =EOMONTH(C10,1) -> 45930 | AG10: =MIN(DATEDIF(AF10,'Control Panel_운영'!$K$90,"m"),3) -> 3 | AH10: =IFERROR(AE10/AG10,0) -> 8245466.7 | AI10: =COUNTIF(AJ10:AL10,">0") -> 0 | AJ10: 0 | AK10: 0 | AL10: 0 | AM10: =COUNTIF(AN10:AS10,">0") -> 2 | AN10: 2 | AO10: 8 | AP10: 0 | AQ10: 0 | AR10: 0 | AS10: 0
B11: 3층 | C11: =IF('Control Panel_운영'!$H181="사용",C$4,0) -> 0 | D11: =IF('Control Panel_운영'!$H181="사용",D$4,0) -> 0 | E11: =F11/H11 -> 0.59886332 | F11: 753.4 | G11: =H11-F11 -> 504.65 | H11: 1258.05 | I11: =ROUND(F11*$D$49,2) -> 227.9 | J11: =ROUND(G11*$D$49,2) -> 152.66 | K11: =ROUND(H11*$D$49,2) -> 380.56 | L11: 0 | M11: =IFERROR(L11/K11,0) -> 0 | N11: 0 | O11: 0 | P11: 1 | Q11: =R11*12 -> 296836800 | R11: =S11*K11 -> 24736400 | S11: 65000 | T11: 0.02 | U11: 1 | V11: 1 | W11: 월납입 | X11: =Y11*K11 -> 11416800 | Y11: 30000 | Z11: 0.02 | AA11: 1 | AB11: 1 | AC11: =(M11*$C$50/12+S11+Y11)/E11 -> 158633.86 | AD11: 1 | AE11: =AD11*R11 -> 24736400 | AF11: =EOMONTH(C11,1) -> 59 | AG11: =MIN(DATEDIF(AF11,'Control Panel_운영'!$K$90,"m"),3) -> 3 | AH11: =IFERROR(AE11/AG11,0) -> 8245466.7 | AI11: =COUNTIF(AJ11:AL11,">0") -> 0 | AJ11: 0 | AK11: 0 | AL11: 0 | AM11: =COUNTIF(AN11:AS11,">0") -> 2 | AN11: 2 | AO11: 8 | AP11: 0 | AQ11: 0 | AR11: 0 | AS11: 0
B12: 2층 | C12: 45169 | D12: 47361 | E12: =F12/H12 -> 0.53288267 | F12: 700 | G12: =H12-F12 -> 613.61 | H12: 1313.61 | I12: =ROUND(F12*$D$49,2) -> 211.75 | J12: =ROUND(G12*$D$49,2) -> 185.62 | K12: =ROUND(H12*$D$49,2) -> 397.37 | L12: 0 | M12: =IFERROR(L12/K12,0) -> 0 | N12: 0 | O12: 0 | P12: 1 | Q12: =R12*12 -> 476844000 | R12: =S12*K12 -> 39737000 | S12: 100000 | T12: 0.02 | U12: 1 | V12: 1 | W12: 월납입 | X12: =Y12*K12 -> 9934250 | Y12: 25000 | Z12: 0.02 | AA12: 1 | AB12: 1 | AC12: =(M12*$C$50/12+S12+Y12)/E12 -> 234573.21 | AD12: 1 | AE12: =AD12*R12 -> 39737000 | AF12: =EOMONTH(C12,1) -> 45199 | AG12: =MIN(DATEDIF(AF12,'Control Panel_운영'!$K$90,"m"),3) -> 3 | AH12: =IFERROR(AE12/AG12,0) -> 13245667 | AI12: =COUNTIF(AJ12:AL12,">0") -> 0 | AJ12: 0 | AK12: 0 | AL12: 0 | AM12: =COUNTIF(AN12:AS12,">0") -> 2 | AN12: 2 | AO12: 8 | AP12: 0 | AQ12: 0 | AR12: 0 | AS12: 0
B13: 1층 | C13: 45169 | D13: 47361 | E13: =F13/H13 -> 0.53287884 | F13: 432.25 | G13: =H13-F13 -> 378.91 | H13: 811.16 | I13: =ROUND(F13*$D$49,2) -> 130.76 | J13: =ROUND(G13*$D$49,2) -> 114.62 | K13: =ROUND(H13*$D$49,2) -> 245.38 | L13: 0 | M13: =IFERROR(L13/K13,0) -> 0 | N13: 0 | O13: 0 | P13: 1 | Q13: =R13*12 -> 441684000 | R13: =S13*K13 -> 36807000 | S13: 150000 | T13: 0.02 | U13: 1 | V13: 1 | W13: 월납입 | X13: =Y13*K13 -> 6134500 | Y13: 25000 | Z13: 0.02 | AA13: 1 | AB13: 1 | AC13: =(M13*$C$50/12+S13+Y13)/E13 -> 328404.86 | AD13: 1 | AE13: =AD13*R13 -> 36807000 | AF13: =EOMONTH(C13,1) -> 45199 | AG13: =MIN(DATEDIF(AF13,'Control Panel_운영'!$K$90,"m"),3) -> 3 | AH13: =IFERROR(AE13/AG13,0) -> 12269000 | AI13: =COUNTIF(AJ13:AL13,">0") -> 0 | AJ13: 0 | AK13: 0 | AL13: 0 | AM13: =COUNTIF(AN13:AS13,">0") -> 2 | AN13: 2 | AO13: 8 | AP13: 0 | AQ13: 0 | AR13: 0 | AS13: 0
B14: 지하1층 | C14: 45169 | D14: 47361 | E14: =F14/H14 -> 0.53288214 | F14: 687.37 | G14: =H14-F14 -> 602.54 | H14: 1289.91 | I14: =ROUND(F14*$D$49,2) -> 207.93 | J14: =ROUND(G14*$D$49,2) -> 182.27 | K14: =ROUND(H14*$D$49,2) -> 390.2 | L14: 0 | M14: =IFERROR(L14/K14,0) -> 0 | N14: 0 | O14: 0 | P14: 1 | Q14: =R14*12 -> 374592000 | R14: =S14*K14 -> 31216000 | S14: 80000 | T14: 0.02 | U14: 1 | V14: 1 | W14: 월납입 | X14: =Y14*K14 -> 9755000 | Y14: 25000 | Z14: 0.02 | AA14: 1 | AB14: 1 | AC14: =(M14*$C$50/12+S14+Y14)/E14 -> 197041.7 | AD14: 1 | AE14: =AD14*R14 -> 31216000 | AF14: =EOMONTH(C14,1) -> 45199 | AG14: =MIN(DATEDIF(AF14,'Control Panel_운영'!$K$90,"m"),3) -> 3 | AH14: =IFERROR(AE14/AG14,0) -> 10405333 | AI14: =COUNTIF(AJ14:AL14,">0") -> 0 | AJ14: 0 | AK14: 0 | AL14: 0 | AM14: =COUNTIF(AN14:AS14,">0") -> 2 | AN14: 2 | AO14: 8 | AP14: 0 | AQ14: 0 | AR14: 0 | AS14: 0
C15: 0 | D15: 0 | E15: =F15/H15 -> #DIV/0! | F15: 0 | G15: =H15-F15 -> 0 | H15: 0 | I15: =ROUND(F15*$D$49,2) -> 0 | J15: =ROUND(G15*$D$49,2) -> 0 | K15: =ROUND(H15*$D$49,2) -> 0 | L15: 0 | M15: =IFERROR(L15/K15,0) -> 0 | N15: 0 | O15: 0 | P15: 1 | Q15: =R15*12 -> 0 | R15: 0 | S15: =IFERROR(R15/K15,0) -> 0 | T15: 0 | U15: 0 | V15: 1 | W15: 월납입 | X15: 0 | Y15: =IFERROR(ROUND(X15/K15,-1),0) -> 0 | Z15: 0 | AA15: 0 | AB15: 1 | AC15: =(M15*$C$50/12+S15+Y15)/E15 -> #DIV/0! | AD15: 0 | AE15: =AD15*R15 -> 0 | AF15: 0 | AG15: =MIN(DATEDIF(AF15,'Control Panel_운영'!$K$90,"m"),3) -> 3 | AH15: =IFERROR(AE15/AG15,0) -> 0 | AI15: =COUNTIF(AJ15:AL15,">0") -> 0 | AJ15: 0 | AK15: 0 | AL15: 0 | AM15: =COUNTIF(AN15:AS15,">0") -> 0 | AN15: 0 | AO15: 0 | AP15: 0 | AQ15: 0 | AR15: 0 | AS15: 0
C16: 0 | D16: 0 | E16: =F16/H16 -> #DIV/0! | F16: 0 | G16: =H16-F16 -> 0 | H16: 0 | I16: =ROUND(F16*$D$49,2) -> 0 | J16: =ROUND(G16*$D$49,2) -> 0 | K16: =ROUND(H16*$D$49,2) -> 0 | L16: 0 | M16: 0 | N16: 0 | O16: 0 | P16: 1 | Q16: =R16*12 -> 0 | R16: =S16*K16 -> 0 | S16: 0 | T16: 0 | U16: 0 | V16: 1 | W16: 월납입 | X16: =Y16*K16 -> 0 | Y16: 0 | Z16: 0 | AA16: 0 | AB16: 1 | AC16: =(M16*$C$50/12+S16+Y16)/E16 -> #DIV/0! | AD16: 0 | AE16: =AD16*R16 -> 0 | AF16: 0 | AG16: =MIN(DATEDIF(AF16,'Control Panel_운영'!$K$90,"m"),3) -> 3 | AH16: =IFERROR(AE16/AG16,0) -> 0 | AI16: =COUNTIF(AJ16:AL16,">0") -> 0 | AJ16: 0 | AK16: 0 | AL16: 0 | AM16: =COUNTIF(AN16:AS16,">0") -> 0 | AN16: 0 | AO16: 0 | AP16: 0 | AQ16: 0 | AR16: 0 | AS16: 0
C17: 0 | D17: 0 | E17: =F17/H17 -> #DIV/0! | F17: 0 | G17: =H17-F17 -> 0 | H17: 0 | I17: =ROUND(F17*$D$49,2) -> 0 | J17: =ROUND(G17*$D$49,2) -> 0 | K17: =ROUND(H17*$D$49,2) -> 0 | L17: 0 | M17: =IFERROR(L17/K17,0) -> 0 | N17: 0 | O17: 0 | P17: 1 | Q17: =R17*12 -> 0 | R17: 0 | S17: =IFERROR(ROUND(R17/K17,0),0) -> 0 | T17: 0 | U17: 0 | V17: 1 | W17: 월납입 | X17: 0 | Y17: =IFERROR(X17/K17,0) -> 0 | Z17: 0 | AA17: 0 | AB17: 1 | AC17: =(M17*$C$50/12+S17+Y17)/E17 -> #DIV/0! | AD17: 0 | AE17: =AD17*R17 -> 0 | AF17: 0 | AG17: =MIN(DATEDIF(AF17,'Control Panel_운영'!$K$90,"m"),3) -> 3 | AH17: =IFERROR(AE17/AG17,0) -> 0 | AI17: =COUNTIF(AJ17:AL17,">0") -> 0 | AJ17: 0 | AK17: 0 | AL17: 0 | AM17: =COUNTIF(AN17:AS17,">0") -> 0 | AN17: 0 | AO17: 0 | AP17: 0 | AQ17: 0 | AR17: 0 | AS17: 0
C18: 0 | D18: 0 | E18: =F18/H18 -> #DIV/0! | F18: 0 | G18: =H18-F18 -> 0 | H18: 0 | I18: =ROUND(F18*$D$49,2) -> 0 | J18: =ROUND(G18*$D$49,2) -> 0 | K18: =ROUND(H18*$D$49,2) -> 0 | L18: 0 | M18: =IFERROR(L18/K18,0) -> 0 | N18: 0 | O18: 0 | P18: 1 | Q18: =R18*12 -> 0 | R18: 0 | S18: =IFERROR(R18/K18,0) -> 0 | T18: 0 | U18: 0 | V18: 1 | W18: 월납입 | X18: 0 | Y18: =IFERROR(X18/K18,0) -> 0 | Z18: 0 | AA18: 0 | AB18: 1 | AC18: =(M18*$C$50/12+S18+Y18)/E18 -> #DIV/0! | AD18: 0 | AE18: =AD18*R18 -> 0 | AF18: 0 | AG18: =MIN(DATEDIF(AF18,'Control Panel_운영'!$K$90,"m"),3) -> 3 | AH18: =IFERROR(AE18/AG18,0) -> 0 | AI18: =COUNTIF(AJ18:AL18,">0") -> 0 | AJ18: 0 | AK18: 0 | AL18: 0 | AM18: =COUNTIF(AN18:AS18,">0") -> 0 | AN18: 0 | AO18: 0 | AP18: 0 | AQ18: 0 | AR18: 0 | AS18: 0
C19: 0 | D19: 0 | E19: =F19/H19 -> #DIV/0! | F19: 0 | G19: =H19-F19 -> 0 | H19: 0 | I19: =ROUND(F19*$D$49,2) -> 0 | J19: =ROUND(G19*$D$49,2) -> 0 | K19: =ROUND(H19*$D$49,2) -> 0 | L19: 0 | M19: =IFERROR(L19/K19,0) -> 0 | N19: 0 | O19: 0 | P19: 1 | Q19: =R19*12 -> 0 | R19: 0 | S19: =IFERROR(R19/K19,0) -> 0 | T19: 0 | U19: 0 | V19: 1 | W19: 월납입 | X19: 0 | Y19: =IFERROR(X19/K19,0) -> 0 | Z19: 0 | AA19: 0 | AB19: 1 | AC19: =(M19*$C$50/12+S19+Y19)/E19 -> #DIV/0! | AD19: 0 | AE19: =AD19*R19 -> 0 | AF19: 0 | AG19: =MIN(DATEDIF(AF19,'Control Panel_운영'!$K$90,"m"),3) -> 3 | AH19: =IFERROR(AE19/AG19,0) -> 0 | AI19: =COUNTIF(AJ19:AL19,">0") -> 0 | AJ19: 0 | AK19: 0 | AL19: 0 | AM19: =COUNTIF(AN19:AS19,">0") -> 0 | AN19: 0 | AO19: 0 | AP19: 0 | AQ19: 0 | AR19: 0 | AS19: 0
C20: 0 | D20: 0 | E20: =F20/H20 -> #DIV/0! | F20: 0 | G20: =H20-F20 -> 0 | H20: 0 | I20: =ROUND(F20*$D$49,2) -> 0 | J20: =ROUND(G20*$D$49,2) -> 0 | K20: =ROUND(H20*$D$49,2) -> 0 | L20: 0 | M20: =IFERROR(L20/K20,0) -> 0 | N20: 0 | O20: 0 | P20: 1 | Q20: =R20*12 -> 0 | R20: =S20*K20 -> 0 | S20: 0 | T20: 0 | U20: 0 | V20: 1 | W20: 월납입 | X20: =Y20*K20 -> 0 | Y20: 0 | Z20: 0 | AA20: 0 | AB20: 1 | AC20: =(M20*$C$50/12+S20+Y20)/E20 -> #DIV/0! | AD20: 0 | AE20: =AD20*R20 -> 0 | AF20: 0 | AG20: =MIN(DATEDIF(AF20,'Control Panel_운영'!$K$90,"m"),3) -> 3 | AH20: =IFERROR(AE20/AG20,0) -> 0 | AI20: =COUNTIF(AJ20:AL20,">0") -> 0 | AJ20: 0 | AK20: 0 | AL20: 0 | AM20: =COUNTIF(AN20:AS20,">0") -> 0 | AN20: 0 | AO20: 0 | AP20: 0 | AQ20: 0 | AR20: 0 | AS20: 0
C21: 0 | D21: 0 | E21: =F21/H21 -> #DIV/0! | F21: 0 | G21: =H21-F21 -> 0 | H21: 0 | I21: =ROUND(F21*$D$49,2) -> 0 | J21: =ROUND(G21*$D$49,2) -> 0 | K21: =ROUND(H21*$D$49,2) -> 0 | L21: 0 | M21: =IFERROR(L21/K21,0) -> 0 | N21: 0 | O21: 0 | P21: 1 | Q21: =R21*12 -> 0 | R21: =S21*K21 -> 0 | S21: 0 | T21: 0 | U21: 0 | V21: 1 | W21: 월납입 | X21: =Y21*K21 -> 0 | Y21: 0 | Z21: 0 | AA21: 0 | AB21: 1 | AC21: =(M21*$C$50/12+S21+Y21)/E21 -> #DIV/0! | AD21: 0 | AE21: =AD21*R21 -> 0 | AF21: 0 | AG21: =MIN(DATEDIF(AF21,'Control Panel_운영'!$K$90,"m"),3) -> 3 | AH21: =IFERROR(AE21/AG21,0) -> 0 | AI21: =COUNTIF(AJ21:AL21,">0") -> 0 | AJ21: 0 | AK21: 0 | AL21: 0 | AM21: =COUNTIF(AN21:AS21,">0") -> 0 | AN21: 0 | AO21: 0 | AP21: 0 | AQ21: 0 | AR21: 0 | AS21: 0
C22: 0 | D22: 0 | E22: =F22/H22 -> #DIV/0! | F22: 0 | G22: =H22-F22 -> 0 | H22: 0 | I22: =ROUND(F22*$D$49,2) -> 0 | J22: =ROUND(G22*$D$49,2) -> 0 | K22: =ROUND(H22*$D$49,2) -> 0 | L22: 0 | M22: =IFERROR(L22/K22,0) -> 0 | N22: 0 | O22: 0 | P22: 1 | Q22: =R22*12 -> 0 | R22: =S22*K22 -> 0 | S22: 0 | T22: 0 | U22: 0 | V22: 1 | W22: 월납입 | X22: =Y22*K22 -> 0 | Y22: 0 | Z22: 0 | AA22: 0 | AB22: 1 | AC22: =(M22*$C$50/12+S22+Y22)/E22 -> #DIV/0! | AD22: 0 | AE22: =AD22*R22 -> 0 | AF22: 0 | AG22: =MIN(DATEDIF(AF22,'Control Panel_운영'!$K$90,"m"),3) -> 3 | AH22: =IFERROR(AE22/AG22,0) -> 0 | AI22: =COUNTIF(AJ22:AL22,">0") -> 0 | AJ22: 0 | AK22: 0 | AL22: 0 | AM22: =COUNTIF(AN22:AS22,">0") -> 0 | AN22: 0 | AO22: 0 | AP22: 0 | AQ22: 0 | AR22: 0 | AS22: 0
C23: 0 | D23: 0 | E23: =F23/H23 -> #DIV/0! | F23: 0 | G23: =H23-F23 -> 0 | H23: 0 | I23: =ROUND(F23*$D$49,2) -> 0 | J23: =ROUND(G23*$D$49,2) -> 0 | K23: =ROUND(H23*$D$49,2) -> 0 | L23: 0 | M23: =IFERROR(L23/K23,0) -> 0 | N23: 0 | O23: 0 | P23: 1 | Q23: =R23*12 -> 0 | R23: =S23*K23 -> 0 | S23: 0 | T23: 0 | U23: 0 | V23: 1 | W23: 월납입 | X23: =Y23*K23 -> 0 | Y23: 0 | Z23: 0 | AA23: 0 | AB23: 1 | AC23: =(M23*$C$50/12+S23+Y23)/E23 -> #DIV/0! | AD23: 0 | AE23: =AD23*R23 -> 0 | AF23: 0 | AG23: =MIN(DATEDIF(AF23,'Control Panel_운영'!$K$90,"m"),3) -> 3 | AH23: =IFERROR(AE23/AG23,0) -> 0 | AI23: =COUNTIF(AJ23:AL23,">0") -> 0 | AJ23: 0 | AK23: 0 | AL23: 0 | AM23: =COUNTIF(AN23:AS23,">0") -> 0 | AN23: 0 | AO23: 0 | AP23: 0 | AQ23: 0 | AR23: 0 | AS23: 0
C24: 0 | D24: 0 | E24: =F24/H24 -> #DIV/0! | F24: 0 | G24: =H24-F24 -> 0 | H24: 0 | I24: =ROUND(F24*$D$49,2) -> 0 | J24: =ROUND(G24*$D$49,2) -> 0 | K24: =ROUND(H24*$D$49,2) -> 0 | L24: 0 | M24: =IFERROR(L24/K24,0) -> 0 | N24: 0 | O24: 0 | P24: 1 | Q24: =R24*12 -> 0 | R24: =S24*K24 -> 0 | S24: 0 | T24: 0 | U24: 0 | V24: 1 | W24: 월납입 | X24: =Y24*K24 -> 0 | Y24: 0 | Z24: 0 | AA24: 0 | AB24: 1 | AC24: =(M24*$C$50/12+S24+Y24)/E24 -> #DIV/0! | AD24: 0 | AE24: =AD24*R24 -> 0 | AF24: 0 | AG24: =MIN(DATEDIF(AF24,'Control Panel_운영'!$K$90,"m"),3) -> 3 | AH24: =IFERROR(AE24/AG24,0) -> 0 | AI24: =COUNTIF(AJ24:AL24,">0") -> 0 | AJ24: 0 | AK24: 0 | AL24: 0 | AM24: =COUNTIF(AN24:AS24,">0") -> 0 | AN24: 0 | AO24: 0 | AP24: 0 | AQ24: 0 | AR24: 0 | AS24: 0
C25: 0 | D25: 0 | E25: =F25/H25 -> #DIV/0! | F25: 0 | G25: =H25-F25 -> 0 | H25: 0 | I25: =ROUND(F25*$D$49,2) -> 0 | J25: =ROUND(G25*$D$49,2) -> 0 | K25: =ROUND(H25*$D$49,2) -> 0 | L25: 0 | M25: =IFERROR(L25/K25,0) -> 0 | N25: 0 | O25: 0 | P25: 1 | Q25: =R25*12 -> 0 | R25: 0 | S25: =IFERROR(R25/K25,0) -> 0 | T25: 0 | U25: 0 | V25: 1 | W25: 월납입 | X25: 0 | Y25: =IFERROR(X25/K25,0) -> 0 | Z25: 0 | AA25: 0 | AB25: 1 | AC25: =(M25*$C$50/12+S25+Y25)/E25 -> #DIV/0! | AD25: 0 | AE25: =AD25*R25 -> 0 | AF25: 0 | AG25: =MIN(DATEDIF(AF25,'Control Panel_운영'!$K$90,"m"),3) -> 3 | AH25: =IFERROR(AE25/AG25,0) -> 0 | AI25: =COUNTIF(AJ25:AL25,">0") -> 0 | AJ25: 0 | AK25: 0 | AL25: 0 | AM25: =COUNTIF(AN25:AS25,">0") -> 0 | AN25: 0 | AO25: 0 | AP25: 0 | AQ25: 0 | AR25: 0 | AS25: 0
C26: 0 | D26: 0 | E26: =F26/H26 -> #DIV/0! | F26: 0 | G26: =H26-F26 -> 0 | H26: 0 | I26: =ROUND(F26*$D$49,2) -> 0 | J26: =ROUND(G26*$D$49,2) -> 0 | K26: =ROUND(H26*$D$49,2) -> 0 | L26: 0 | M26: =IFERROR(L26/K26,0) -> 0 | N26: 0 | O26: 0 | P26: 1 | Q26: =R26*12 -> 0 | R26: 0 | S26: =IFERROR(R26/K26,0) -> 0 | T26: 0 | U26: 0 | V26: 1 | W26: 월납입 | X26: 0 | Y26: =IFERROR(X26/K26,0) -> 0 | Z26: 0 | AA26: 0 | AB26: 1 | AC26: =(M26*$C$50/12+S26+Y26)/E26 -> #DIV/0! | AD26: 0 | AE26: =AD26*R26 -> 0 | AF26: 0 | AG26: =MIN(DATEDIF(AF26,'Control Panel_운영'!$K$90,"m"),3) -> 3 | AH26: =IFERROR(AE26/AG26,0) -> 0 | AI26: =COUNTIF(AJ26:AL26,">0") -> 0 | AJ26: 0 | AK26: 0 | AL26: 0 | AM26: =COUNTIF(AN26:AS26,">0") -> 0 | AN26: 0 | AO26: 0 | AP26: 0 | AQ26: 0 | AR26: 0 | AS26: 0
C27: 0 | D27: 0 | E27: =F27/H27 -> #DIV/0! | F27: 0 | G27: =H27-F27 -> 0 | H27: 0 | I27: =ROUND(F27*$D$49,2) -> 0 | J27: =ROUND(G27*$D$49,2) -> 0 | K27: =ROUND(H27*$D$49,2) -> 0 | L27: 0 | M27: =IFERROR(L27/K27,0) -> 0 | N27: 0 | O27: 0 | P27: 1 | Q27: =R27*12 -> 0 | R27: 0 | S27: =IFERROR(R27/K27,0) -> 0 | T27: 0 | U27: 0 | V27: 1 | W27: 월납입 | X27: 0 | Y27: =IFERROR(X27/K27,0) -> 0 | Z27: 0 | AA27: 0 | AB27: 1 | AC27: =(M27*$C$50/12+S27+Y27)/E27 -> #DIV/0! | AD27: 0 | AE27: =AD27*R27 -> 0 | AF27: 0 | AG27: =MIN(DATEDIF(AF27,'Control Panel_운영'!$K$90,"m"),3) -> 3 | AH27: =IFERROR(AE27/AG27,0) -> 0 | AI27: =COUNTIF(AJ27:AL27,">0") -> 0 | AJ27: 0 | AK27: 0 | AL27: 0 | AM27: =COUNTIF(AN27:AS27,">0") -> 0 | AN27: 0 | AO27: 0 | AP27: 0 | AQ27: 0 | AR27: 0 | AS27: 0
C28: 0 | D28: 0 | E28: =F28/H28 -> #DIV/0! | F28: 0 | G28: =H28-F28 -> 0 | H28: 0 | I28: =ROUND(F28*$D$49,2) -> 0 | J28: =ROUND(G28*$D$49,2) -> 0 | K28: =ROUND(H28*$D$49,2) -> 0 | L28: 0 | M28: =IFERROR(L28/K28,0) -> 0 | N28: 0 | O28: 0 | P28: 1 | Q28: =R28*12 -> 0 | R28: 0 | S28: =IFERROR(R28/K28,0) -> 0 | T28: 0 | U28: 0 | V28: 1 | W28: 월납입 | X28: 0 | Y28: =IFERROR(X28/K28,0) -> 0 | Z28: 0 | AA28: 0 | AB28: 1 | AC28: =(M28*$C$50/12+S28+Y28)/E28 -> #DIV/0! | AD28: 0 | AE28: =AD28*R28 -> 0 | AF28: 0 | AG28: =MIN(DATEDIF(AF28,'Control Panel_운영'!$K$90,"m"),3) -> 3 | AH28: =IFERROR(AE28/AG28,0) -> 0 | AI28: =COUNTIF(AJ28:AL28,">0") -> 0 | AJ28: 0 | AK28: 0 | AL28: 0 | AM28: =COUNTIF(AN28:AS28,">0") -> 0 | AN28: 0 | AO28: 0 | AP28: 0 | AQ28: 0 | AR28: 0 | AS28: 0
C29: 0 | D29: 0 | E29: =F29/H29 -> #DIV/0! | F29: 0 | G29: =H29-F29 -> 0 | H29: 0 | I29: =ROUND(F29*$D$49,2) -> 0 | J29: =ROUND(G29*$D$49,2) -> 0 | K29: =ROUND(H29*$D$49,2) -> 0 | L29: 0 | M29: =IFERROR(L29/K29,0) -> 0 | N29: 0 | O29: 0 | P29: 1 | Q29: =R29*12 -> 0 | R29: 0 | S29: =IFERROR(R29/K29,0) -> 0 | T29: 0 | U29: 0 | V29: 1 | W29: 월납입 | X29: 0 | Y29: =IFERROR(X29/K29,0) -> 0 | Z29: 0 | AA29: 0 | AB29: 1 | AC29: =(M29*$C$50/12+S29+Y29)/E29 -> #DIV/0! | AD29: 0 | AE29: =AD29*R29 -> 0 | AF29: 0 | AG29: =MIN(DATEDIF(AF29,'Control Panel_운영'!$K$90,"m"),3) -> 3 | AH29: =IFERROR(AE29/AG29,0) -> 0 | AI29: =COUNTIF(AJ29:AL29,">0") -> 0 | AJ29: 0 | AK29: 0 | AL29: 0 | AM29: =COUNTIF(AN29:AS29,">0") -> 0 | AN29: 0 | AO29: 0 | AP29: 0 | AQ29: 0 | AR29: 0 | AS29: 0
C30: 0 | D30: 0 | E30: =F30/H30 -> #DIV/0! | F30: 0 | G30: =H30-F30 -> 0 | H30: 0 | I30: =ROUND(F30*$D$49,2) -> 0 | J30: =ROUND(G30*$D$49,2) -> 0 | K30: =ROUND(H30*$D$49,2) -> 0 | L30: 0 | M30: =IFERROR(L30/K30,0) -> 0 | N30: 0 | O30: 0 | P30: 1 | Q30: =R30*12 -> 0 | R30: 0 | S30: =IFERROR(R30/K30,0) -> 0 | T30: 0 | U30: 0 | V30: 1 | W30: 월납입 | X30: 0 | Y30: =IFERROR(X30/K30,0) -> 0 | Z30: 0 | AA30: 0 | AB30: 1 | AC30: =(M30*$C$50/12+S30+Y30)/E30 -> #DIV/0! | AD30: 0 | AE30: =AD30*R30 -> 0 | AF30: 0 | AG30: =MIN(DATEDIF(AF30,'Control Panel_운영'!$K$90,"m"),3) -> 3 | AH30: =IFERROR(AE30/AG30,0) -> 0 | AI30: =COUNTIF(AJ30:AL30,">0") -> 0 | AJ30: 0 | AK30: 0 | AL30: 0 | AM30: =COUNTIF(AN30:AS30,">0") -> 0 | AN30: 0 | AO30: 0 | AP30: 0 | AQ30: 0 | AR30: 0 | AS30: 0
C31: 0 | D31: 0 | E31: =F31/H31 -> #DIV/0! | F31: 0 | G31: =H31-F31 -> 0 | H31: 0 | I31: =ROUND(F31*$D$49,2) -> 0 | J31: =ROUND(G31*$D$49,2) -> 0 | K31: =ROUND(H31*$D$49,2) -> 0 | L31: 0 | M31: =IFERROR(L31/K31,0) -> 0 | N31: 0 | O31: 0 | P31: 1 | Q31: =R31*12 -> 0 | R31: 0 | S31: =IFERROR(R31/K31,0) -> 0 | T31: 0 | U31: 0 | V31: 1 | W31: 월납입 | X31: 0 | Y31: =IFERROR(X31/K31,0) -> 0 | Z31: 0 | AA31: 0 | AB31: 1 | AC31: =(M31*$C$50/12+S31+Y31)/E31 -> #DIV/0! | AD31: 0 | AE31: =AD31*R31 -> 0 | AF31: 0 | AG31: =MIN(DATEDIF(AF31,'Control Panel_운영'!$K$90,"m"),3) -> 3 | AH31: =IFERROR(AE31/AG31,0) -> 0 | AI31: =COUNTIF(AJ31:AL31,">0") -> 0 | AJ31: 0 | AK31: 0 | AL31: 0 | AM31: =COUNTIF(AN31:AS31,">0") -> 0 | AN31: 0 | AO31: 0 | AP31: 0 | AQ31: 0 | AR31: 0 | AS31: 0
C32: 0 | D32: 0 | E32: =F32/H32 -> #DIV/0! | F32: 0 | G32: =H32-F32 -> 0 | H32: 0 | I32: =ROUND(F32*$D$49,2) -> 0 | J32: =ROUND(G32*$D$49,2) -> 0 | K32: =ROUND(H32*$D$49,2) -> 0 | L32: 0 | M32: =IFERROR(L32/K32,0) -> 0 | N32: 0 | O32: 0 | P32: 1 | Q32: =R32*12 -> 0 | R32: 0 | S32: =IFERROR(R32/K32,0) -> 0 | T32: 0 | U32: 0 | V32: 1 | W32: 월납입 | X32: 0 | Y32: =IFERROR(X32/K32,0) -> 0 | Z32: 0 | AA32: 0 | AB32: 1 | AC32: =(M32*$C$50/12+S32+Y32)/E32 -> #DIV/0! | AD32: 0 | AE32: =AD32*R32 -> 0 | AF32: 0 | AG32: =MIN(DATEDIF(AF32,'Control Panel_운영'!$K$90,"m"),3) -> 3 | AH32: =IFERROR(AE32/AG32,0) -> 0 | AI32: =COUNTIF(AJ32:AL32,">0") -> 0 | AJ32: 0 | AK32: 0 | AL32: 0 | AM32: =COUNTIF(AN32:AS32,">0") -> 0 | AN32: 0 | AO32: 0 | AP32: 0 | AQ32: 0 | AR32: 0 | AS32: 0
C33: 0 | D33: 0 | E33: =F33/H33 -> #DIV/0! | F33: 0 | G33: =H33-F33 -> 0 | H33: 0 | I33: =ROUND(F33*$D$49,2) -> 0 | J33: =ROUND(G33*$D$49,2) -> 0 | K33: =ROUND(H33*$D$49,2) -> 0 | L33: 0 | M33: =IFERROR(L33/K33,0) -> 0 | N33: 0 | O33: 0 | P33: 1 | Q33: =R33*12 -> 0 | R33: 0 | S33: =IFERROR(R33/K33,0) -> 0 | T33: 0 | U33: 0 | V33: 1 | W33: 월납입 | X33: 0 | Y33: =IFERROR(X33/K33,0) -> 0 | Z33: 0 | AA33: 0 | AB33: 1 | AC33: =(M33*$C$50/12+S33+Y33)/E33 -> #DIV/0! | AD33: 0 | AE33: =AD33*R33 -> 0 | AF33: 0 | AG33: =MIN(DATEDIF(AF33,'Control Panel_운영'!$K$90,"m"),3) -> 3 | AH33: =IFERROR(AE33/AG33,0) -> 0 | AI33: =COUNTIF(AJ33:AL33,">0") -> 0 | AJ33: 0 | AK33: 0 | AL33: 0 | AM33: =COUNTIF(AN33:AS33,">0") -> 0 | AN33: 0 | AO33: 0 | AP33: 0 | AQ33: 0 | AR33: 0 | AS33: 0
C34: 0 | D34: 0 | E34: =F34/H34 -> #DIV/0! | F34: 0 | G34: =H34-F34 -> 0 | H34: 0 | I34: =ROUND(F34*$D$49,2) -> 0 | J34: =ROUND(G34*$D$49,2) -> 0 | K34: =ROUND(H34*$D$49,2) -> 0 | L34: 0 | M34: =IFERROR(L34/K34,0) -> 0 | N34: 0 | O34: 0 | P34: 1 | Q34: =R34*12 -> 0 | R34: 0 | S34: =IFERROR(R34/K34,0) -> 0 | T34: 0 | U34: 0 | V34: 1 | W34: 월납입 | X34: 0 | Y34: =IFERROR(X34/K34,0) -> 0 | Z34: 0 | AA34: 0 | AB34: 1 | AC34: =(M34*$C$50/12+S34+Y34)/E34 -> #DIV/0! | AD34: 0 | AE34: =AD34*R34 -> 0 | AF34: 0 | AG34: =MIN(DATEDIF(AF34,'Control Panel_운영'!$K$90,"m"),3) -> 3 | AH34: =IFERROR(AE34/AG34,0) -> 0 | AI34: =COUNTIF(AJ34:AL34,">0") -> 0 | AJ34: 0 | AK34: 0 | AL34: 0 | AM34: =COUNTIF(AN34:AS34,">0") -> 0 | AN34: 0 | AO34: 0 | AP34: 0 | AQ34: 0 | AR34: 0 | AS34: 0
C35: 0 | D35: 0 | E35: =F35/H35 -> #DIV/0! | F35: 0 | G35: =H35-F35 -> 0 | H35: 0 | I35: =ROUND(F35*$D$49,2) -> 0 | J35: =ROUND(G35*$D$49,2) -> 0 | K35: =ROUND(H35*$D$49,2) -> 0 | L35: 0 | M35: =IFERROR(L35/K35,0) -> 0 | N35: 0 | O35: 0 | P35: 1 | Q35: =R35*12 -> 0 | R35: 0 | S35: =IFERROR(R35/K35,0) -> 0 | T35: 0 | U35: 0 | V35: 1 | W35: 월납입 | X35: 0 | Y35: =IFERROR(X35/K35,0) -> 0 | Z35: 0 | AA35: 0 | AB35: 1 | AC35: =(M35*$C$50/12+S35+Y35)/E35 -> #DIV/0! | AD35: 0 | AE35: =AD35*R35 -> 0 | AF35: 0 | AG35: =MIN(DATEDIF(AF35,'Control Panel_운영'!$K$90,"m"),3) -> 3 | AH35: =IFERROR(AE35/AG35,0) -> 0 | AI35: =COUNTIF(AJ35:AL35,">0") -> 0 | AJ35: 0 | AK35: 0 | AL35: 0 | AM35: =COUNTIF(AN35:AS35,">0") -> 0 | AN35: 0 | AO35: 0 | AP35: 0 | AQ35: 0 | AR35: 0 | AS35: 0
C36: 0 | D36: 0 | E36: =F36/H36 -> #DIV/0! | F36: 0 | G36: =H36-F36 -> 0 | H36: 0 | I36: =ROUND(F36*$D$49,2) -> 0 | J36: =ROUND(G36*$D$49,2) -> 0 | K36: =ROUND(H36*$D$49,2) -> 0 | L36: 0 | M36: =IFERROR(L36/K36,0) -> 0 | N36: 0 | O36: 0 | P36: 1 | Q36: =R36*12 -> 0 | R36: 0 | S36: =IFERROR(R36/K36,0) -> 0 | T36: 0 | U36: 0 | V36: 1 | W36: 월납입 | X36: 0 | Y36: =IFERROR(X36/K36,0) -> 0 | Z36: 0 | AA36: 0 | AB36: 1 | AC36: =(M36*$C$50/12+S36+Y36)/E36 -> #DIV/0! | AD36: 0 | AE36: =AD36*R36 -> 0 | AF36: 0 | AG36: =MIN(DATEDIF(AF36,'Control Panel_운영'!$K$90,"m"),3) -> 3 | AH36: =IFERROR(AE36/AG36,0) -> 0 | AI36: =COUNTIF(AJ36:AL36,">0") -> 0 | AJ36: 0 | AK36: 0 | AL36: 0 | AM36: =COUNTIF(AN36:AS36,">0") -> 0 | AN36: 0 | AO36: 0 | AP36: 0 | AQ36: 0 | AR36: 0 | AS36: 0
... C45: 0 | D45: 0 | E45: =F45/H45 -> #DIV/0! | F45: 0 | G45: =H45-F45 -> 0 | H45: 0 | I45: =ROUND(F45*$D$49,2) -> 0 | J45: =ROUND(G45*$D$49,2) -> 0 | K45: =ROUND(H45*$D$49,2) -> 0 | L45: 0 | M45: =IFERROR(L45/K45,0) -> 0 | N45: 0 | O45: 0 | P45: 1 | Q45: =R45*12 -> 0 | R45: 0 | S45: =IFERROR(R45/K45,0) -> 0 | T45: 0 | U45: 0 | V45: 1 | W45: 월납입 | X45: 0 | Y45: =IFERROR(X45/K45,0) -> 0 | Z45: 0 | AA45: 0 | AB45: 1 | AC45: =(M45*$C$50/12+S45+Y45)/E45 -> #DIV/0! | AD45: 0 | AE45: =AD45*R45 -> 0 | AF45: 0 | AG45: =MIN(DATEDIF(AF45,'Control Panel_운영'!$K$90,"m"),3) -> 3 | AH45: =IFERROR(AE45/AG45,0) -> 0 | AI45: =COUNTIF(AJ45:AL45,">0") -> 0 | AJ45: 0 | AK45: 0 | AL45: 0 | AM45: =COUNTIF(AN45:AS45,">0") -> 0 | AN45: 0 | AO45: 0 | AP45: 0 | AQ45: 0 | AR45: 0 | AS45: 0
B48: 금액 기준 단위 | C48: ='Control Panel_운영'!$N$93 -> 1000
B49: 면적 단위 환산 | C49: ='Control Panel_운영'!$N$94 -> 3.3 | D49: ='Control Panel_운영'!$N$95 -> 0.3025
B50: 보증금 적용 이율 | C50: 0.025
...

Sheet Index_개발
E1: 0 | F1: 1 | G1: 1 | H1: 1 | I1: 1 | J1: 1 | K1: 1 | L1: 1 | M1: 1 | N1: 1 | O1: 1 | P1: 1 | Q1: 1 | R1: 2 | S1: 2 | T1: 2 | U1: 2 | V1: 2 | W1: 2 | X1: 2 | Y1: 2 | Z1: 2 | AA1: 2 | AB1: 2 | AC1: 2 | AD1: 3 | AE1: 3 | AF1: 3 | AG1: 3 | AH1: 3 | AI1: 3 | AJ1: 3 | AK1: 3 | AL1: 3 | AM1: 3 | AN1: 3 | AO1: 3 | AP1: 4 | AQ1: 4 | AR1: 4 | AS1: 4 | AT1: 4 | AU1: 4 | AV1: 4 | AW1: 4 | AX1: 4 | AY1: 4 | AZ1: 4 | BA1: 4 | BB1: 5 | BC1: 5 | BD1: 5 | BE1: 5 | BF1: 5 | BG1: 5 | BH1: 5 | BI1: 5 | BJ1: 5 | BK1: 5 | BL1: 5 | BM1: 5
E2: 0 | F2: =IF(AND(F$3>='Control Panel_개발'!$N$12,F$3<='Control Panel_개발'!$O$12),'Control Panel_개발'!$M$12)+IF(OR(MONTH(E$3)='Control Panel_개발'!$P$12,MONTH(E$3)='Control Panel_개발'!$P$13,MONTH(E$3)='Control Panel_개발'!$P$14,MONTH(E$3)='Control Panel_개발'!$P$15),E$2+1,E$2)*(F$3>'Control Panel_개발'!$O$12) -> 1 | G2: =IF(AND(G$3>='Control Panel_개발'!$N$12,G$3<='Control Panel_개발'!$O$12),'Control Panel_개발'!$M$12)+IF(OR(MONTH(F$3)='Control Panel_개발'!$P$12,MONTH(F$3)='Control Panel_개발'!$P$13,MONTH(F$3)='Control Panel_개발'!$P$14,MONTH(F$3)='Control Panel_개발'!$P$15),F$2+1,F$2)*(G$3>'Control Panel_개발'!$O$12) -> 1 | H2: =IF(AND(H$3>='Control Panel_개발'!$N$12,H$3<='Control Panel_개발'!$O$12),'Control Panel_개발'!$M$12)+IF(OR(MONTH(G$3)='Control Panel_개발'!$P$12,MONTH(G$3)='Control Panel_개발'!$P$13,MONTH(G$3)='Control Panel_개발'!$P$14,MONTH(G$3)='Control Panel_개발'!$P$15),G$2+1,G$2)*(H$3>'Control Panel_개발'!$O$12) -> 1 | I2: =IF(AND(I$3>='Control Panel_개발'!$N$12,I$3<='Control Panel_개발'!$O$12),'Control Panel_개발'!$M$12)+IF(OR(MONTH(H$3)='Control Panel_개발'!$P$12,MONTH(H$3)='Control Panel_개발'!$P$13,MONTH(H$3)='Control Panel_개발'!$P$14,MONTH(H$3)='Control Panel_개발'!$P$15),H$2+1,H$2)*(I$3>'Control Panel_개발'!$O$12) -> 1 | J2: =IF(AND(J$3>='Control Panel_개발'!$N$12,J$3<='Control Panel_개발'!$O$12),'Control Panel_개발'!$M$12)+IF(OR(MONTH(I$3)='Control Panel_개발'!$P$12,MONTH(I$3)='Control Panel_개발'!$P$13,MONTH(I$3)='Control Panel_개발'!$P$14,MONTH(I$3)='Control Panel_개발'!$P$15),I$2+1,I$2)*(J$3>'Control Panel_개발'!$O$12) -> 1 | K2: =IF(AND(K$3>='Control Panel_개발'!$N$12,K$3<='Control Panel_개발'!$O$12),'Control Panel_개발'!$M$12)+IF(OR(MONTH(J$3)='Control Panel_개발'!$P$12,MONTH(J$3)='Control Panel_개발'!$P$13,MONTH(J$3)='Control Panel_개발'!$P$14,MONTH(J$3)='Control Panel_개발'!$P$15),J$2+1,J$2)*(K$3>'Control Panel_개발'!$O$12) -> 1 | L2: =IF(AND(L$3>='Control Panel_개발'!$N$12,L$3<='Control Panel_개발'!$O$12),'Control Panel_개발'!$M$12)+IF(OR(MONTH(K$3)='Control Panel_개발'!$P$12,MONTH(K$3)='Control Panel_개발'!$P$13,MONTH(K$3)='Control Panel_개발'!$P$14,MONTH(K$3)='Control Panel_개발'!$P$15),K$2+1,K$2)*(L$3>'Control Panel_개발'!$O$12) -> 2 | M2: =IF(AND(M$3>='Control Panel_개발'!$N$12,M$3<='Control Panel_개발'!$O$12),'Control Panel_개발'!$M$12)+IF(OR(MONTH(L$3)='Control Panel_개발'!$P$12,MONTH(L$3)='Control Panel_개발'!$P$13,MONTH(L$3)='Control Panel_개발'!$P$14,MONTH(L$3)='Control Panel_개발'!$P$15),L$2+1,L$2)*(M$3>'Control Panel_개발'!$O$12) -> 2 | ... BM2: =IF(AND(BM$3>='Control Panel_개발'!$N$12,BM$3<='Control Panel_개발'!$O$12),'Control Panel_개발'!$M$12)+IF(OR(MONTH(BL$3)='Control Panel_개발'!$P$12,MONTH(BL$3)='Control Panel_개발'!$P$13,MONTH(BL$3)='Control Panel_개발'!$P$14,MONTH(BL$3)='Control Panel_개발'!$P$15),BL$2+1,BL$2)*(BM$3>'Control Panel_개발'!$O$12) -> 10
E3: ='Control Panel_개발'!$I$4 -> 43708 | F3: =EOMONTH(E3,1) -> 43738 | G3: =EOMONTH(F3,1) -> 43769 | H3: =EOMONTH(G3,1) -> 43799 | I3: =EOMONTH(H3,1) -> 43830 | J3: =EOMONTH(I3,1) -> 43861 | K3: =EOMONTH(J3,1) -> 43890 | L3: =EOMONTH(K3,1) -> 43921 | M3: =EOMONTH(L3,1) -> 43951 | ... BM3: =EOMONTH(BL3,1) -> 45535
E4: =DAY(E3) -> 31 | F4: =DAY(F3) -> 30 | G4: =DAY(G3) -> 31 | H4: =DAY(H3) -> 30 | I4: =DAY(I3) -> 31 | J4: =DAY(J3) -> 31 | K4: =DAY(K3) -> 29 | L4: =DAY(L3) -> 31 | ... BM4: =DAY(BM3) -> 31
B6: 회계연도
B8: 개발기간 | E8: =IF(E$3='Control Panel_개발'!$I$4,0,IF(AND(E$3>'Control Panel_개발'!$I$4,E$3<='Control Panel_개발'!$I$10),1,0)) -> 0 | F8: =IF(F$3='Control Panel_개발'!$I$4,0,IF(AND(F$3>'Control Panel_개발'!$I$4,F$3<='Control Panel_개발'!$I$10),1,0)) -> 1 | G8: =IF(G$3='Control Panel_개발'!$I$4,0,IF(AND(G$3>'Control Panel_개발'!$I$4,G$3<='Control Panel_개발'!$I$10),1,0)) -> 1 | H8: =IF(H$3='Control Panel_개발'!$I$4,0,IF(AND(H$3>'Control Panel_개발'!$I$4,H$3<='Control Panel_개발'!$I$10),1,0)) -> 1 | I8: =IF(I$3='Control Panel_개발'!$I$4,0,IF(AND(I$3>'Control Panel_개발'!$I$4,I$3<='Control Panel_개발'!$I$10),1,0)) -> 1 | J8: =IF(J$3='Control Panel_개발'!$I$4,0,IF(AND(J$3>'Control Panel_개발'!$I$4,J$3<='Control Panel_개발'!$I$10),1,0)) -> 1 | K8: =IF(K$3='Control Panel_개발'!$I$4,0,IF(AND(K$3>'Control Panel_개발'!$I$4,K$3<='Control Panel_개발'!$I$10),1,0)) -> 1 | L8: =IF(L$3='Control Panel_개발'!$I$4,0,IF(AND(L$3>'Control Panel_개발'!$I$4,L$3<='Control Panel_개발'!$I$10),1,0)) -> 1 | ... BM8: =IF(BM$3='Control Panel_개발'!$I$4,0,IF(AND(BM$3>'Control Panel_개발'!$I$4,BM$3<='Control Panel_개발'!$I$10),1,0)) -> 0

Sheet Index_운영
F1: 0 | G1: 1 | H1: 1 | I1: 1 | J1: 1 | K1: 1 | L1: 1 | M1: 1 | N1: 1 | O1: 1 | P1: 1 | Q1: 1 | R1: 1 | S1: 2 | T1: 2 | U1: 2 | V1: 2 | W1: 2 | X1: 2 | Y1: 2 | Z1: 2 | AA1: 2 | AB1: 2 | AC1: 2 | AD1: 2 | AE1: 3 | AF1: 3 | AG1: 3 | AH1: 3 | AI1: 3 | AJ1: 3 | AK1: 3 | AL1: 3 | AM1: 3 | AN1: 3 | AO1: 3 | AP1: 3 | AQ1: 4 | AR1: 4 | AS1: 4 | AT1: 4 | AU1: 4 | AV1: 4 | AW1: 4 | AX1: 4 | AY1: 4 | AZ1: 4 | BA1: 4 | BB1: 4 | BC1: 5 | BD1: 5 | BE1: 5 | BF1: 5 | BG1: 5 | BH1: 5 | BI1: 5 | BJ1: 5 | BK1: 5 | BL1: 5 | BM1: 5 | BN1: 5 | BO1: 6 | BP1: 6 | BQ1: 6 | BR1: 6 | BS1: 6 | BT1: 6 | BU1: 6 | BV1: 6 | BW1: 6 | BX1: 6 | BY1: 6 | BZ1: 6 | CA1: 7 | CB1: 7 | CC1: 7 | CD1: 7 | CE1: 7 | CF1: 7 | CG1: 7 | CH1: 7 | CI1: 7 | CJ1: 7 | CK1: 7 | CL1: 7 | CM1: 8 | CN1: 8 | CO1: 8 | CP1: 8 | CQ1: 8 | CR1: 8 | CS1: 8 | CT1: 8 | CU1: 8 | CV1: 8 | CW1: 8 | CX1: 8 | CY1: 9 | CZ1: 9 | DA1: 9 | DB1: 9 | DC1: 9 | DD1: 9 | DE1: 9 | DF1: 9 | DG1: 9 | DH1: 9 | DI1: 9 | DJ1: 9 | DK1: 10 | DL1: 10 | DM1: 10 | DN1: 10 | DO1: 10 | DP1: 10 | DQ1: 10 | DR1: 10 | DS1: 10 | DT1: 10 | DU1: 10 | DV1: 10
F2: 0 | G2: =IF(AND(G$3>='Control Panel_운영'!$N$97,G$3<='Control Panel_운영'!$O$97),'Control Panel_운영'!$M$97)+IF(OR(MONTH(F$3)='Control Panel_운영'!$P$97,MONTH(F$3)='Control Panel_운영'!$P$98,MONTH(F$3)='Control Panel_운영'!$P$99,MONTH(F$3)='Control Panel_운영'!$P$100),F$2+1,F$2)*(Index_운영!G$3>'Control Panel_운영'!$O$97) -> 1 | H2: =IF(AND(H$3>='Control Panel_운영'!$N$97,H$3<='Control Panel_운영'!$O$97),'Control Panel_운영'!$M$97)+IF(OR(MONTH(G$3)='Control Panel_운영'!$P$97,MONTH(G$3)='Control Panel_운영'!$P$98,MONTH(G$3)='Control Panel_운영'!$P$99,MONTH(G$3)='Control Panel_운영'!$P$100),G$2+1,G$2)*(Index_운영!H$3>'Control Panel_운영'!$O$97) -> 1 | I2: =IF(AND(I$3>='Control Panel_운영'!$N$97,I$3<='Control Panel_운영'!$O$97),'Control Panel_운영'!$M$97)+IF(OR(MONTH(H$3)='Control Panel_운영'!$P$97,MONTH(H$3)='Control Panel_운영'!$P$98,MONTH(H$3)='Control Panel_운영'!$P$99,MONTH(H$3)='Control Panel_운영'!$P$100),H$2+1,H$2)*(Index_운영!I$3>'Control Panel_운영'!$O$97) -> 1 | J2: =IF(AND(J$3>='Control Panel_운영'!$N$97,J$3<='Control Panel_운영'!$O$97),'Control Panel_운영'!$M$97)+IF(OR(MONTH(I$3)='Control Panel_운영'!$P$97,MONTH(I$3)='Control Panel_운영'!$P$98,MONTH(I$3)='Control Panel_운영'!$P$99,MONTH(I$3)='Control Panel_운영'!$P$100),I$2+1,I$2)*(Index_운영!J$3>'Control Panel_운영'!$O$97) -> 2 | K2: =IF(AND(K$3>='Control Panel_운영'!$N$97,K$3<='Control Panel_운영'!$O$97),'Control Panel_운영'!$M$97)+IF(OR(MONTH(J$3)='Control Panel_운영'!$P$97,MONTH(J$3)='Control Panel_운영'!$P$98,MONTH(J$3)='Control Panel_운영'!$P$99,MONTH(J$3)='Control Panel_운영'!$P$100),J$2+1,J$2)*(Index_운영!K$3>'Control Panel_운영'!$O$97) -> 2 | L2: =IF(AND(L$3>='Control Panel_운영'!$N$97,L$3<='Control Panel_운영'!$O$97),'Control Panel_운영'!$M$97)+IF(OR(MONTH(K$3)='Control Panel_운영'!$P$97,MONTH(K$3)='Control Panel_운영'!$P$98,MONTH(K$3)='Control Panel_운영'!$P$99,MONTH(K$3)='Control Panel_운영'!$P$100),K$2+1,K$2)*(Index_운영!L$3>'Control Panel_운영'!$O$97) -> 2 | M2: =IF(AND(M$3>='Control Panel_운영'!$N$97,M$3<='Control Panel_운영'!$O$97),'Control Panel_운영'!$M$97)+IF(OR(MONTH(L$3)='Control Panel_운영'!$P$97,MONTH(L$3)='Control Panel_운영'!$P$98,MONTH(L$3)='Control Panel_운영'!$P$99,MONTH(L$3)='Control Panel_운영'!$P$100),L$2+1,L$2)*(Index_운영!M$3>'Control Panel_운영'!$O$97) -> 3 | N2: =IF(AND(N$3>='Control Panel_운영'!$N$97,N$3<='Control Panel_운영'!$O$97),'Control Panel_운영'!$M$97)+IF(OR(MONTH(M$3)='Control Panel_운영'!$P$97,MONTH(M$3)='Control Panel_운영'!$P$98,MONTH(M$3)='Control Panel_운영'!$P$99,MONTH(M$3)='Control Panel_운영'!$P$100),M$2+1,M$2)*(Index_운영!N$3>'Control Panel_운영'!$O$97) -> 3 | ... DV2: =IF(AND(DV$3>='Control Panel_운영'!$N$97,DV$3<='Control Panel_운영'!$O$97),'Control Panel_운영'!$M$97)+IF(OR(MONTH(DU$3)='Control Panel_운영'!$P$97,MONTH(DU$3)='Control Panel_운영'!$P$98,MONTH(DU$3)='Control Panel_운영'!$P$99,MONTH(DU$3)='Control Panel_운영'!$P$100),DU$2+1,DU$2)*(Index_운영!DV$3>'Control Panel_운영'!$O$97) -> 40
F3: ='Control Panel_운영'!$K$84 -> 45169 | G3: =EOMONTH(F3,1) -> 45199 | H3: =EOMONTH(G3,1) -> 45230 | I3: =EOMONTH(H3,1) -> 45260 | J3: =EOMONTH(I3,1) -> 45291 | K3: =EOMONTH(J3,1) -> 45322 | L3: =EOMONTH(K3,1) -> 45351 | M3: =EOMONTH(L3,1) -> 45382 | N3: =EOMONTH(M3,1) -> 45412 | ... DV3: =EOMONTH(DU3,1) -> 48822
F4: =DAY(F3) -> 31 | G4: =DAY(G3) -> 30 | H4: =DAY(H3) -> 31 | I4: =DAY(I3) -> 30 | J4: =DAY(J3) -> 31 | K4: =DAY(K3) -> 31 | L4: =DAY(L3) -> 29 | M4: =DAY(M3) -> 31 | ... DV4: =DAY(DV3) -> 31
A6: 매입
F7: =IF(F$3='Control Panel_운영'!$K$84,1,0) -> 1 | G7: =IF(G$3='Control Panel_운영'!$K$84,1,0) -> 0 | H7: =IF(H$3='Control Panel_운영'!$K$84,1,0) -> 0 | I7: =IF(I$3='Control Panel_운영'!$K$84,1,0) -> 0 | J7: =IF(J$3='Control Panel_운영'!$K$84,1,0) -> 0 | K7: =IF(K$3='Control Panel_운영'!$K$84,1,0) -> 0 | L7: =IF(L$3='Control Panel_운영'!$K$84,1,0) -> 0 | M7: =IF(M$3='Control Panel_운영'!$K$84,1,0) -> 0 | ... DV7: =IF(DV$3='Control Panel_운영'!$K$84,1,0) -> 0
A9: 운영기간
F10: =IF(AND(F$3>'Control Panel_운영'!$K$84,F$3<='Control Panel_운영'!$K$90),1,0) -> 0 | G10: =IF(AND(G$3>'Control Panel_운영'!$K$84,G$3<='Control Panel_운영'!$K$90),1,0) -> 1 | H10: =IF(AND(H$3>'Control Panel_운영'!$K$84,H$3<='Control Panel_운영'!$K$90),1,0) -> 1 | I10: =IF(AND(I$3>'Control Panel_운영'!$K$84,I$3<='Control Panel_운영'!$K$90),1,0) -> 1 | J10: =IF(AND(J$3>'Control Panel_운영'!$K$84,J$3<='Control Panel_운영'!$K$90),1,0) -> 1 | K10: =IF(AND(K$3>'Control Panel_운영'!$K$84,K$3<='Control Panel_운영'!$K$90),1,0) -> 1 | L10: =IF(AND(L$3>'Control Panel_운영'!$K$84,L$3<='Control Panel_운영'!$K$90),1,0) -> 1 | M10: =IF(AND(M$3>'Control Panel_운영'!$K$84,M$3<='Control Panel_운영'!$K$90),1,0) -> 1 | ... DV10: =IF(AND(DV$3>'Control Panel_운영'!$K$84,DV$3<='Control Panel_운영'!$K$90),1,0) -> 0
A12: 매각
F13: =IF(F$3='Control Panel_운영'!$K$90,1,0) -> 0 | G13: =IF(G$3='Control Panel_운영'!$K$90,1,0) -> 0 | H13: =IF(H$3='Control Panel_운영'!$K$90,1,0) -> 0 | I13: =IF(I$3='Control Panel_운영'!$K$90,1,0) -> 0 | J13: =IF(J$3='Control Panel_운영'!$K$90,1,0) -> 0 | K13: =IF(K$3='Control Panel_운영'!$K$90,1,0) -> 0 | L13: =IF(L$3='Control Panel_운영'!$K$90,1,0) -> 0 | M13: =IF(M$3='Control Panel_운영'!$K$90,1,0) -> 0 | ... DV13: =IF(DV$3='Control Panel_운영'!$K$90,1,0) -> 0
A15: 회계기간
F16: =IF(OR(F$3='Control Panel_운영'!$K$90,AND(F$3>='Control Panel_운영'!$K$93,F$2<'Control Panel_운영'!$K$95,MOD(MONTH(F$3),'Control Panel_운영'!$K$92)='Control Panel_운영'!$L$93)),1,0) -> 0 | G16: =IF(OR(G$3='Control Panel_운영'!$K$90,AND(G$3>='Control Panel_운영'!$K$93,G$2<'Control Panel_운영'!$K$95,MOD(MONTH(G$3),'Control Panel_운영'!$K$92)='Control Panel_운영'!$L$93)),1,0) -> 0 | H16: =IF(OR(H$3='Control Panel_운영'!$K$90,AND(H$3>='Control Panel_운영'!$K$93,H$2<'Control Panel_운영'!$K$95,MOD(MONTH(H$3),'Control Panel_운영'!$K$92)='Control Panel_운영'!$L$93)),1,0) -> 0 | I16: =IF(OR(I$3='Control Panel_운영'!$K$90,AND(I$3>='Control Panel_운영'!$K$93,I$2<'Control Panel_운영'!$K$95,MOD(MONTH(I$3),'Control Panel_운영'!$K$92)='Control Panel_운영'!$L$93)),1,0) -> 1 | J16: =IF(OR(J$3='Control Panel_운영'!$K$90,AND(J$3>='Control Panel_운영'!$K$93,J$2<'Control Panel_운영'!$K$95,MOD(MONTH(J$3),'Control Panel_운영'!$K$92)='Control Panel_운영'!$L$93)),1,0) -> 0 | K16: =IF(OR(K$3='Control Panel_운영'!$K$90,AND(K$3>='Control Panel_운영'!$K$93,K$2<'Control Panel_운영'!$K$95,MOD(MONTH(K$3),'Control Panel_운영'!$K$92)='Control Panel_운영'!$L$93)),1,0) -> 0 | L16: =IF(OR(L$3='Control Panel_운영'!$K$90,AND(L$3>='Control Panel_운영'!$K$93,L$2<'Control Panel_운영'!$K$95,MOD(MONTH(L$3),'Control Panel_운영'!$K$92)='Control Panel_운영'!$L$93)),1,0) -> 1 | M16: =IF(OR(M$3='Control Panel_운영'!$K$90,AND(M$3>='Control Panel_운영'!$K$93,M$2<'Control Panel_운영'!$K$95,MOD(MONTH(M$3),'Control Panel_운영'!$K$92)='Control Panel_운영'!$L$93)),1,0) -> 0 | ... DV16: =IF(OR(DV$3='Control Panel_운영'!$K$90,AND(DV$3>='Control Panel_운영'!$K$93,DV$2<'Control Panel_운영'!$K$95,MOD(MONTH(DV$3),'Control Panel_운영'!$K$92)='Control Panel_운영'!$L$93)),1,0) -> 0
A18: 기타수익&비용상승률
F19: =IF(AND(NOT(F$3='Control Panel_운영'!$K$89),MONTH(F$3)=MONTH('Control Panel_운영'!$K$89)),1,0) -> 0 | G19: =IF(AND(NOT(G$3='Control Panel_운영'!$K$89),MONTH(G$3)=MONTH('Control Panel_운영'!$K$89)),1,0) -> 0 | H19: =IF(AND(NOT(H$3='Control Panel_운영'!$K$89),MONTH(H$3)=MONTH('Control Panel_운영'!$K$89)),1,0) -> 0 | I19: =IF(AND(NOT(I$3='Control Panel_운영'!$K$89),MONTH(I$3)=MONTH('Control Panel_운영'!$K$89)),1,0) -> 0 | J19: =IF(AND(NOT(J$3='Control Panel_운영'!$K$89),MONTH(J$3)=MONTH('Control Panel_운영'!$K$89)),1,0) -> 0 | K19: =IF(AND(NOT(K$3='Control Panel_운영'!$K$89),MONTH(K$3)=MONTH('Control Panel_운영'!$K$89)),1,0) -> 0 | L19: =IF(AND(NOT(L$3='Control Panel_운영'!$K$89),MONTH(L$3)=MONTH('Control Panel_운영'!$K$89)),1,0) -> 0 | M19: =IF(AND(NOT(M$3='Control Panel_운영'!$K$89),MONTH(M$3)=MONTH('Control Panel_운영'!$K$89)),1,0) -> 0 | ... DV19: =IF(AND(NOT(DV$3='Control Panel_운영'!$K$89),MONTH(DV$3)=MONTH('Control Panel_운영'!$K$89)),1,0) -> 0
A21: 보험료
F22: =IF(MONTH(F$3)=MONTH('Control Panel_운영'!$K$84),1,0) -> 1 | G22: =IF(MONTH(G$3)=MONTH('Control Panel_운영'!$K$84),1,0) -> 0 | H22: =IF(MONTH(H$3)=MONTH('Control Panel_운영'!$K$84),1,0) -> 0 | I22: =IF(MONTH(I$3)=MONTH('Control Panel_운영'!$K$84),1,0) -> 0 | J22: =IF(MONTH(J$3)=MONTH('Control Panel_운영'!$K$84),1,0) -> 0 | K22: =IF(MONTH(K$3)=MONTH('Control Panel_운영'!$K$84),1,0) -> 0 | L22: =IF(MONTH(L$3)=MONTH('Control Panel_운영'!$K$84),1,0) -> 0 | M22: =IF(MONTH(M$3)=MONTH('Control Panel_운영'!$K$84),1,0) -> 0 | ... DV22: =IF(MONTH(DV$3)=MONTH('Control Panel_운영'!$K$84),1,0) -> 1
A24: 제세공과금
B25: 토지분 재산세 | F25: =IF('Control Panel_운영'!$P176="임차인부담",0,IF(AND(YEAR(F$3)=YEAR('Control Panel_운영'!$K$84),F$3>'Control Panel_운영'!$N$87),0,IF(MONTH(F$3)='Control Panel_운영'!$O88,1,0))) -> 0 | G25: =IF('Control Panel_운영'!$P176="임차인부담",0,IF(AND(YEAR(G$3)=YEAR('Control Panel_운영'!$K$84),G$3>'Control Panel_운영'!$N$87),0,IF(MONTH(G$3)='Control Panel_운영'!$O88,1,0))) -> 0 | H25: =IF('Control Panel_운영'!$P176="임차인부담",0,IF(AND(YEAR(H$3)=YEAR('Control Panel_운영'!$K$84),H$3>'Control Panel_운영'!$N$87),0,IF(MONTH(H$3)='Control Panel_운영'!$O88,1,0))) -> 0 | I25: =IF('Control Panel_운영'!$P176="임차인부담",0,IF(AND(YEAR(I$3)=YEAR('Control Panel_운영'!$K$84),I$3>'Control Panel_운영'!$N$87),0,IF(MONTH(I$3)='Control Panel_운영'!$O88,1,0))) -> 0 | J25: =IF('Control Panel_운영'!$P176="임차인부담",0,IF(AND(YEAR(J$3)=YEAR('Control Panel_운영'!$K$84),J$3>'Control Panel_운영'!$N$87),0,IF(MONTH(J$3)='Control Panel_운영'!$O88,1,0))) -> 0 | K25: =IF('Control Panel_운영'!$P176="임차인부담",0,IF(AND(YEAR(K$3)=YEAR('Control Panel_운영'!$K$84),K$3>'Control Panel_운영'!$N$87),0,IF(MONTH(K$3)='Control Panel_운영'!$O88,1,0))) -> 0 | L25: =IF('Control Panel_운영'!$P176="임차인부담",0,IF(AND(YEAR(L$3)=YEAR('Control Panel_운영'!$K$84),L$3>'Control Panel_운영'!$N$87),0,IF(MONTH(L$3)='Control Panel_운영'!$O88,1,0))) -> 0 | M25: =IF('Control Panel_운영'!$P176="임차인부담",0,IF(AND(YEAR(M$3)=YEAR('Control Panel_운영'!$K$84),M$3>'Control Panel_운영'!$N$87),0,IF(MONTH(M$3)='Control Panel_운영'!$O88,1,0))) -> 0 | ... DV25: =IF('Control Panel_운영'!$P176="임차인부담",0,IF(AND(YEAR(DV$3)=YEAR('Control Panel_운영'!$K$84),DV$3>'Control Panel_운영'!$N$87),0,IF(MONTH(DV$3)='Control Panel_운영'!$O88,1,0))) -> 0
B26: 건물분 재산세 | F26: =IF('Control Panel_운영'!$P177="임차인부담",0,IF(AND(YEAR(F$3)=YEAR('Control Panel_운영'!$K$84),F$3>'Control Panel_운영'!$N$87),0,IF(MONTH(F$3)='Control Panel_운영'!$O89,1,0))) -> 0 | G26: =IF('Control Panel_운영'!$P177="임차인부담",0,IF(AND(YEAR(G$3)=YEAR('Control Panel_운영'!$K$84),G$3>'Control Panel_운영'!$N$87),0,IF(MONTH(G$3)='Control Panel_운영'!$O89,1,0))) -> 0 | H26: =IF('Control Panel_운영'!$P177="임차인부담",0,IF(AND(YEAR(H$3)=YEAR('Control Panel_운영'!$K$84),H$3>'Control Panel_운영'!$N$87),0,IF(MONTH(H$3)='Control Panel_운영'!$O89,1,0))) -> 0 | I26: =IF('Control Panel_운영'!$P177="임차인부담",0,IF(AND(YEAR(I$3)=YEAR('Control Panel_운영'!$K$84),I$3>'Control Panel_운영'!$N$87),0,IF(MONTH(I$3)='Control Panel_운영'!$O89,1,0))) -> 0 | J26: =IF('Control Panel_운영'!$P177="임차인부담",0,IF(AND(YEAR(J$3)=YEAR('Control Panel_운영'!$K$84),J$3>'Control Panel_운영'!$N$87),0,IF(MONTH(J$3)='Control Panel_운영'!$O89,1,0))) -> 0 | K26: =IF('Control Panel_운영'!$P177="임차인부담",0,IF(AND(YEAR(K$3)=YEAR('Control Panel_운영'!$K$84),K$3>'Control Panel_운영'!$N$87),0,IF(MONTH(K$3)='Control Panel_운영'!$O89,1,0))) -> 0 | L26: =IF('Control Panel_운영'!$P177="임차인부담",0,IF(AND(YEAR(L$3)=YEAR('Control Panel_운영'!$K$84),L$3>'Control Panel_운영'!$N$87),0,IF(MONTH(L$3)='Control Panel_운영'!$O89,1,0))) -> 0 | M26: =IF('Control Panel_운영'!$P177="임차인부담",0,IF(AND(YEAR(M$3)=YEAR('Control Panel_운영'!$K$84),M$3>'Control Panel_운영'!$N$87),0,IF(MONTH(M$3)='Control Panel_운영'!$O89,1,0))) -> 0 | ... DV26: =IF('Control Panel_운영'!$P177="임차인부담",0,IF(AND(YEAR(DV$3)=YEAR('Control Panel_운영'!$K$84),DV$3>'Control Panel_운영'!$N$87),0,IF(MONTH(DV$3)='Control Panel_운영'!$O89,1,0))) -> 0
B27: 교통유발부담금 | F27: =IF('Control Panel_운영'!$P178="임차인부담",0,IF(MONTH(F$3)='Control Panel_운영'!$O90,1,0)) -> 0 | G27: =IF('Control Panel_운영'!$P178="임차인부담",0,IF(MONTH(G$3)='Control Panel_운영'!$O90,1,0)) -> 0 | H27: =IF('Control Panel_운영'!$P178="임차인부담",0,IF(MONTH(H$3)='Control Panel_운영'!$O90,1,0)) -> 1 | I27: =IF('Control Panel_운영'!$P178="임차인부담",0,IF(MONTH(I$3)='Control Panel_운영'!$O90,1,0)) -> 0 | J27: =IF('Control Panel_운영'!$P178="임차인부담",0,IF(MONTH(J$3)='Control Panel_운영'!$O90,1,0)) -> 0 | K27: =IF('Control Panel_운영'!$P178="임차인부담",0,IF(MONTH(K$3)='Control Panel_운영'!$O90,1,0)) -> 0 | L27: =IF('Control Panel_운영'!$P178="임차인부담",0,IF(MONTH(L$3)='Control Panel_운영'!$O90,1,0)) -> 0 | M27: =IF('Control Panel_운영'!$P178="임차인부담",0,IF(MONTH(M$3)='Control Panel_운영'!$O90,1,0)) -> 0 | ... DV27: =IF('Control Panel_운영'!$P178="임차인부담",0,IF(MONTH(DV$3)='Control Panel_운영'!$O90,1,0)) -> 0
B28: 도로점용료 | F28: =IF('Control Panel_운영'!$P179="임차인부담",0,IF(MONTH(F$3)='Control Panel_운영'!$O91,1,0)) -> 0 | G28: =IF('Control Panel_운영'!$P179="임차인부담",0,IF(MONTH(G$3)='Control Panel_운영'!$O91,1,0)) -> 0 | H28: =IF('Control Panel_운영'!$P179="임차인부담",0,IF(MONTH(H$3)='Control Panel_운영'!$O91,1,0)) -> 0 | I28: =IF('Control Panel_운영'!$P179="임차인부담",0,IF(MONTH(I$3)='Control Panel_운영'!$O91,1,0)) -> 0 | J28: =IF('Control Panel_운영'!$P179="임차인부담",0,IF(MONTH(J$3)='Control Panel_운영'!$O91,1,0)) -> 0 | K28: =IF('Control Panel_운영'!$P179="임차인부담",0,IF(MONTH(K$3)='Control Panel_운영'!$O91,1,0)) -> 0 | L28: =IF('Control Panel_운영'!$P179="임차인부담",0,IF(MONTH(L$3)='Control Panel_운영'!$O91,1,0)) -> 0 | M28: =IF('Control Panel_운영'!$P179="임차인부담",0,IF(MONTH(M$3)='Control Panel_운영'!$O91,1,0)) -> 1 | ... DV28: =IF('Control Panel_운영'!$P179="임차인부담",0,IF(MONTH(DV$3)='Control Panel_운영'!$O91,1,0)) -> 0
A30: 임대차기간
B31: ='Rent Roll'!$B5 -> 월드비전 | F31: =IF(AND(F$3>'Rent Roll'!$C5,F$3<='Rent Roll'!$D5),1,IF(AND(YEAR(F$3)=YEAR('Rent Roll'!$D5),MONTH(F$3)=MONTH('Rent Roll'!$D5)),1,0)) -> 0 | G31: =IF(AND(G$3>'Rent Roll'!$C5,G$3<='Rent Roll'!$D5),1,IF(AND(YEAR(G$3)=YEAR('Rent Roll'!$D5),MONTH(G$3)=MONTH('Rent Roll'!$D5)),1,0)) -> 1 | H31: =IF(AND(H$3>'Rent Roll'!$C5,H$3<='Rent Roll'!$D5),1,IF(AND(YEAR(H$3)=YEAR('Rent Roll'!$D5),MONTH(H$3)=MONTH('Rent Roll'!$D5)),1,0)) -> 1 | I31: =IF(AND(I$3>'Rent Roll'!$C5,I$3<='Rent Roll'!$D5),1,IF(AND(YEAR(I$3)=YEAR('Rent Roll'!$D5),MONTH(I$3)=MONTH('Rent Roll'!$D5)),1,0)) -> 1 | J31: =IF(AND(J$3>'Rent Roll'!$C5,J$3<='Rent Roll'!$D5),1,IF(AND(YEAR(J$3)=YEAR('Rent Roll'!$D5),MONTH(J$3)=MONTH('Rent Roll'!$D5)),1,0)) -> 1 | K31: =IF(AND(K$3>'Rent Roll'!$C5,K$3<='Rent Roll'!$D5),1,IF(AND(YEAR(K$3)=YEAR('Rent Roll'!$D5),MONTH(K$3)=MONTH('Rent Roll'!$D5)),1,0)) -> 1 | L31: =IF(AND(L$3>'Rent Roll'!$C5,L$3<='Rent Roll'!$D5),1,IF(AND(YEAR(L$3)=YEAR('Rent Roll'!$D5),MONTH(L$3)=MONTH('Rent Roll'!$D5)),1,0)) -> 1 | M31: =IF(AND(M$3>'Rent Roll'!$C5,M$3<='Rent Roll'!$D5),1,IF(AND(YEAR(M$3)=YEAR('Rent Roll'!$D5),MONTH(M$3)=MONTH('Rent Roll'!$D5)),1,0)) -> 1 | ... DV31: =IF(AND(DV$3>'Rent Roll'!$C5,DV$3<='Rent Roll'!$D5),1,IF(AND(YEAR(DV$3)=YEAR('Rent Roll'!$D5),MONTH(DV$3)=MONTH('Rent Roll'!$D5)),1,0)) -> 1
B32: ='Rent Roll'!$B6 -> 16층 | F32: =IF(AND(F$3>'Rent Roll'!$C6,F$3<='Rent Roll'!$D6),1,IF(AND(YEAR(F$3)=YEAR('Rent Roll'!$D6),MONTH(F$3)=MONTH('Rent Roll'!$D6)),1,0)) -> 0 | G32: =IF(AND(G$3>'Rent Roll'!$C6,G$3<='Rent Roll'!$D6),1,IF(AND(YEAR(G$3)=YEAR('Rent Roll'!$D6),MONTH(G$3)=MONTH('Rent Roll'!$D6)),1,0)) -> 1 | H32: =IF(AND(H$3>'Rent Roll'!$C6,H$3<='Rent Roll'!$D6),1,IF(AND(YEAR(H$3)=YEAR('Rent Roll'!$D6),MONTH(H$3)=MONTH('Rent Roll'!$D6)),1,0)) -> 1 | I32: =IF(AND(I$3>'Rent Roll'!$C6,I$3<='Rent Roll'!$D6),1,IF(AND(YEAR(I$3)=YEAR('Rent Roll'!$D6),MONTH(I$3)=MONTH('Rent Roll'!$D6)),1,0)) -> 1 | J32: =IF(AND(J$3>'Rent Roll'!$C6,J$3<='Rent Roll'!$D6),1,IF(AND(YEAR(J$3)=YEAR('Rent Roll'!$D6),MONTH(J$3)=MONTH('Rent Roll'!$D6)),1,0)) -> 1 | K32: =IF(AND(K$3>'Rent Roll'!$C6,K$3<='Rent Roll'!$D6),1,IF(AND(YEAR(K$3)=YEAR('Rent Roll'!$D6),MONTH(K$3)=MONTH('Rent Roll'!$D6)),1,0)) -> 1 | L32: =IF(AND(L$3>'Rent Roll'!$C6,L$3<='Rent Roll'!$D6),1,IF(AND(YEAR(L$3)=YEAR('Rent Roll'!$D6),MONTH(L$3)=MONTH('Rent Roll'!$D6)),1,0)) -> 1 | M32: =IF(AND(M$3>'Rent Roll'!$C6,M$3<='Rent Roll'!$D6),1,IF(AND(YEAR(M$3)=YEAR('Rent Roll'!$D6),MONTH(M$3)=MONTH('Rent Roll'!$D6)),1,0)) -> 1 | ... DV32: =IF(AND(DV$3>'Rent Roll'!$C6,DV$3<='Rent Roll'!$D6),1,IF(AND(YEAR(DV$3)=YEAR('Rent Roll'!$D6),MONTH(DV$3)=MONTH('Rent Roll'!$D6)),1,0)) -> 0
B33: ='Rent Roll'!$B7 -> 7층 | F33: =IF(AND(F$3>'Rent Roll'!$C7,F$3<='Rent Roll'!$D7),1,IF(AND(YEAR(F$3)=YEAR('Rent Roll'!$D7),MONTH(F$3)=MONTH('Rent Roll'!$D7)),1,0)) -> 0 | G33: =IF(AND(G$3>'Rent Roll'!$C7,G$3<='Rent Roll'!$D7),1,IF(AND(YEAR(G$3)=YEAR('Rent Roll'!$D7),MONTH(G$3)=MONTH('Rent Roll'!$D7)),1,0)) -> 1 | H33: =IF(AND(H$3>'Rent Roll'!$C7,H$3<='Rent Roll'!$D7),1,IF(AND(YEAR(H$3)=YEAR('Rent Roll'!$D7),MONTH(H$3)=MONTH('Rent Roll'!$D7)),1,0)) -> 1 | I33: =IF(AND(I$3>'Rent Roll'!$C7,I$3<='Rent Roll'!$D7),1,IF(AND(YEAR(I$3)=YEAR('Rent Roll'!$D7),MONTH(I$3)=MONTH('Rent Roll'!$D7)),1,0)) -> 1 | J33: =IF(AND(J$3>'Rent Roll'!$C7,J$3<='Rent Roll'!$D7),1,IF(AND(YEAR(J$3)=YEAR('Rent Roll'!$D7),MONTH(J$3)=MONTH('Rent Roll'!$D7)),1,0)) -> 1 | K33: =IF(AND(K$3>'Rent Roll'!$C7,K$3<='Rent Roll'!$D7),1,IF(AND(YEAR(K$3)=YEAR('Rent Roll'!$D7),MONTH(K$3)=MONTH('Rent Roll'!$D7)),1,0)) -> 1 | L33: =IF(AND(L$3>'Rent Roll'!$C7,L$3<='Rent Roll'!$D7),1,IF(AND(YEAR(L$3)=YEAR('Rent Roll'!$D7),MONTH(L$3)=MONTH('Rent Roll'!$D7)),1,0)) -> 1 | M33: =IF(AND(M$3>'Rent Roll'!$C7,M$3<='Rent Roll'!$D7),1,IF(AND(YEAR(M$3)=YEAR('Rent Roll'!$D7),MONTH(M$3)=MONTH('Rent Roll'!$D7)),1,0)) -> 1 | ... DV33: =IF(AND(DV$3>'Rent Roll'!$C7,DV$3<='Rent Roll'!$D7),1,IF(AND(YEAR(DV$3)=YEAR('Rent Roll'!$D7),MONTH(DV$3)=MONTH('Rent Roll'!$D7)),1,0)) -> 0
