Workbook

Sheet Index
B1: Index
B3: Sheet | C3: Description
B4: =HYPERLINK("#'Control'!A1","Control") | C4: 핵심 가정과 주요 결과 요약
B5: =HYPERLINK("#'Assumptions'!A1","Assumptions") | C5: 모든 하드코딩 입력값 집중 시트
B6: =HYPERLINK("#'Model'!A1","Model") | C6: HTML D 그래프를 기간별 Excel 수식으로 전개한 계산 엔진
B7: =HYPERLINK("#'Formula Audit'!A1","Formula Audit") | C7: 생성된 모든 수식 셀 감사
B8: =HYPERLINK("#'Structure'!A1","Structure") | C8: HTML 노드 ID, parent, formula, description
B9: =HYPERLINK("#'Checks'!A1","Checks") | C9: 수식/구조/정합성 검증
B10: =HYPERLINK("#'Metadata'!A1","Metadata") | C10: 생성 정보

Sheet Control
B1: Control
I3: Historical | M3: Forecast
B4: Output | C4: ID | I4: 2022 | J4: 2023 | K4: 2024 | L4: 2025 | M4: 2026 | N4: 2027 | O4: 2028 | P4: 2029 | Q4: 2030 | R4: 2031
B5: 테슬라 총매출 | C5: root | I5: ='Model'!I5 | J5: ='Model'!J5 | K5: ='Model'!K5 | L5: ='Model'!L5 | M5: ='Model'!M5 | N5: ='Model'!N5 | O5: ='Model'!O5 | P5: ='Model'!P5 | ... R5: ='Model'!R5
B6: ① Automotive | C6: auto_total | I6: ='Model'!I6 | J6: ='Model'!J6 | K6: ='Model'!K6 | L6: ='Model'!L6 | M6: ='Model'!M6 | N6: ='Model'!N6 | O6: ='Model'!O6 | P6: ='Model'!P6 | ... R6: ='Model'!R6
B7: ② Energy | C7: energy_total | I7: ='Model'!I19 | J7: ='Model'!J19 | K7: ='Model'!K19 | L7: ='Model'!L19 | M7: ='Model'!M19 | N7: ='Model'!N19 | O7: ='Model'!O19 | P7: ='Model'!P19 | ... R7: ='Model'!R19
B8: ③ Services | C8: services_total | I8: ='Model'!I22 | J8: ='Model'!J22 | K8: ='Model'!K22 | L8: ='Model'!L22 | M8: ='Model'!M22 | N8: ='Model'!N22 | O8: ='Model'!O22 | P8: ='Model'!P22 | ... R8: ='Model'!R22
B9: 차량판매 | C9: auto_sales | I9: ='Model'!I7 | J9: ='Model'!J7 | K9: ='Model'!K7 | L9: ='Model'!L7 | M9: ='Model'!M7 | N9: ='Model'!N7 | O9: ='Model'!O7 | P9: ='Model'!P7 | ... R9: ='Model'!R7
B10: Model 3/Y 매출 | C10: sales_3y | I10: ='Model'!I8 | J10: ='Model'!J8 | K10: ='Model'!K8 | L10: ='Model'!L8 | M10: ='Model'!M8 | N10: ='Model'!N8 | O10: ='Model'!O8 | P10: ='Model'!P8 | ... R10: ='Model'!R8
B11: S/X·Cybertruck 매출 | C11: sales_sxc | I11: ='Model'!I11 | J11: ='Model'!J11 | K11: ='Model'!K11 | L11: ='Model'!L11 | M11: ='Model'!M11 | N11: ='Model'!N11 | O11: ='Model'!O11 | P11: ='Model'!P11 | ... R11: ='Model'!R11
B12: 신규 저가모델 매출 | C12: sales_new | I12: ='Model'!I14 | J12: ='Model'!J14 | K12: ='Model'!K14 | L12: ='Model'!L14 | M12: ='Model'!M14 | N12: ='Model'!N14 | O12: ='Model'!O14 | P12: ='Model'!P14 | ... R12: ='Model'!R14

Sheet Assumptions
B1: Assumptions
I3: Historical | M3: Forecast
G4: ID | H4: Unit | I4: 2022 | J4: 2023 | K4: 2024 | L4: 2025 | M4: 2026 | N4: 2027 | O4: 2028 | P4: 2029 | Q4: 2030 | R4: 2031
F5: Model 3/Y 인도량 | G5: del_3y | H5: 천대 | I5: 1247.146 | J5: 1739.707 | K5: 1704.093 | L5: 1585.279 | M5: 1600 | N5: 1650 | O5: 1700 | P5: 1750 | Q5: 1800 | R5: 1850
F6: Model 3/Y ASP | G6: asp_3y | H6: 천$/대 | I6: 48.275 | J6: 41.3667 | K6: 38.5363 | L6: 39.1144 | M6: 39 | N6: 39 | O6: 39.5 | P6: 39.5 | Q6: 40 | R6: 40
F7: S/X·Cybertruck 인도량 | G7: del_sxc | H7: 천대 | I7: 66.705 | J7: 68.874 | K7: 85.133 | L7: 50.85 | M7: 60 | N7: 70 | O7: 75 | P7: 80 | Q7: 85 | R7: 90
F8: S/X·Cybertruck ASP | G8: asp_sxc | H8: 천$/대 | I8: 105 | J8: 95 | K8: 80 | L8: 75 | M8: 72 | N8: 70 | O8: 70 | P8: 70 | Q8: 70 | R8: 70
F9: 신규 저가모델 인도량 | G9: del_new | H9: 천대 | I9: 0 | J9: 0 | K9: 0 | L9: 0 | M9: 100 | N9: 350 | O9: 550 | P9: 800 | Q9: 1000 | R9: 1200
F10: 신규 저가모델 ASP | G10: asp_new | H10: 천$/대 | I10: 0 | J10: 0 | K10: 0 | L10: 0 | M10: 33 | N10: 32 | O10: 31 | P10: 31 | Q10: 30 | R10: 30
D11: 리스(Leasing) | G11: auto_leasing | H11: 백만$ | I11: 2476 | J11: 2120 | K11: 1827 | L11: 1712 | M11: 1600 | N11: 1550 | O11: 1500 | P11: 1500 | Q11: 1500 | R11: 1500
D12: 규제크레딧 | G12: reg_credits | H12: 백만$ | I12: 1776 | J12: 1790 | K12: 2763 | L12: 1993 | M12: 1200 | N12: 700 | O12: 400 | P12: 200 | Q12: 100 | R12: 0
D13: 저장 배포량 | G13: storage_gwh | H13: GWh | I13: 6.5 | J13: 14.7 | K13: 31.4 | L13: 46.7 | M13: 70 | N13: 98 | O13: 127 | P13: 160 | Q13: 195 | R13: 230
D14: 단위매출 | G14: energy_rev_per_gwh | H14: 백만$/GWh | I14: 601.38 | J14: 410.54 | K14: 321.21 | L14: 273.47 | M14: 255 | N14: 240 | O14: 230 | P14: 222 | Q14: 215 | R14: 210
D15: 누적 보유대수 | G15: installed_base | H15: 백만대 | I15: 3.6539 | J15: 5.4624 | K15: 7.2517 | L15: 8.8878 | M15: 10.6478 | N15: 12.7178 | O15: 15.0428 | P15: 17.6728 | Q15: 20.5578 | R15: 23.6978
D16: 대당 연 서비스매출 | G16: service_per_unit | H16: $/대 | I16: 1667 | J16: 1523 | K16: 1452.6 | L16: 1409.8 | M16: 1400 | N16: 1400 | O16: 1420 | P16: 1430 | Q16: 1440 | R16: 1450

Sheet Model
B1: Model
I2: Unit: source units from HTML IR
I3: Historical | M3: Forecast
G4: ID | H4: Unit | I4: 2022 | J4: 2023 | K4: 2024 | L4: 2025 | M4: 2026 | N4: 2027 | O4: 2028 | P4: 2029 | Q4: 2030 | R4: 2031
B5: 테슬라 총매출 | G5: root | H5: 백만$ | I5: =((I6+I19)+I22) | J5: =((J6+J19)+J22) | K5: =((K6+K19)+K22) | L5: =((L6+L19)+L22) | M5: =((M6+M19)+M22) | N5: =((N6+N19)+N22) | O5: =((O6+O19)+O22) | P5: =((P6+P19)+P22) | ... R5: =((R6+R19)+R22)
C6: ① Automotive | G6: auto_total | H6: 백만$ | I6: =((I7+I17)+I18) | J6: =((J7+J17)+J18) | K6: =((K7+K17)+K18) | L6: =((L7+L17)+L18) | M6: =((M7+M17)+M18) | N6: =((N7+N17)+N18) | O6: =((O7+O17)+O18) | P6: =((P7+P17)+P18) | ... R6: =((R7+R17)+R18)
D7: 차량판매 | G7: auto_sales | H7: 백만$ | I7: =((I8+I11)+I14) | J7: =((J8+J11)+J14) | K7: =((K8+K11)+K14) | L7: =((L8+L11)+L14) | M7: =((M8+M11)+M14) | N7: =((N8+N11)+N14) | O7: =((O8+O11)+O14) | P7: =((P8+P11)+P14) | ... R7: =((R8+R11)+R14)
E8: Model 3/Y 매출 | G8: sales_3y | H8: 백만$ | I8: =(I9*I10) | J8: =(J9*J10) | K8: =(K9*K10) | L8: =(L9*L10) | M8: =(M9*M10) | N8: =(N9*N10) | O8: =(O9*O10) | P8: =(P9*P10) | ... R8: =(R9*R10)
F9: Model 3/Y 인도량 | G9: del_3y | H9: 천대 | I9: ='Assumptions'!I5 | J9: ='Assumptions'!J5 | K9: ='Assumptions'!K5 | L9: ='Assumptions'!L5 | M9: ='Assumptions'!M5 | N9: ='Assumptions'!N5 | O9: ='Assumptions'!O5 | P9: ='Assumptions'!P5 | ... R9: ='Assumptions'!R5
F10: Model 3/Y ASP | G10: asp_3y | H10: 천$/대 | I10: ='Assumptions'!I6 | J10: ='Assumptions'!J6 | K10: ='Assumptions'!K6 | L10: ='Assumptions'!L6 | M10: ='Assumptions'!M6 | N10: ='Assumptions'!N6 | O10: ='Assumptions'!O6 | P10: ='Assumptions'!P6 | ... R10: ='Assumptions'!R6
E11: S/X·Cybertruck 매출 | G11: sales_sxc | H11: 백만$ | I11: =(I12*I13) | J11: =(J12*J13) | K11: =(K12*K13) | L11: =(L12*L13) | M11: =(M12*M13) | N11: =(N12*N13) | O11: =(O12*O13) | P11: =(P12*P13) | ... R11: =(R12*R13)
F12: S/X·Cybertruck 인도량 | G12: del_sxc | H12: 천대 | I12: ='Assumptions'!I7 | J12: ='Assumptions'!J7 | K12: ='Assumptions'!K7 | L12: ='Assumptions'!L7 | M12: ='Assumptions'!M7 | N12: ='Assumptions'!N7 | O12: ='Assumptions'!O7 | P12: ='Assumptions'!P7 | ... R12: ='Assumptions'!R7
F13: S/X·Cybertruck ASP | G13: asp_sxc | H13: 천$/대 | I13: ='Assumptions'!I8 | J13: ='Assumptions'!J8 | K13: ='Assumptions'!K8 | L13: ='Assumptions'!L8 | M13: ='Assumptions'!M8 | N13: ='Assumptions'!N8 | O13: ='Assumptions'!O8 | P13: ='Assumptions'!P8 | ... R13: ='Assumptions'!R8
E14: 신규 저가모델 매출 | G14: sales_new | H14: 백만$ | I14: =(I15*I16) | J14: =(J15*J16) | K14: =(K15*K16) | L14: =(L15*L16) | M14: =(M15*M16) | N14: =(N15*N16) | O14: =(O15*O16) | P14: =(P15*P16) | ... R14: =(R15*R16)
F15: 신규 저가모델 인도량 | G15: del_new | H15: 천대 | I15: ='Assumptions'!I9 | J15: ='Assumptions'!J9 | K15: ='Assumptions'!K9 | L15: ='Assumptions'!L9 | M15: ='Assumptions'!M9 | N15: ='Assumptions'!N9 | O15: ='Assumptions'!O9 | P15: ='Assumptions'!P9 | ... R15: ='Assumptions'!R9
F16: 신규 저가모델 ASP | G16: asp_new | H16: 천$/대 | I16: ='Assumptions'!I10 | J16: ='Assumptions'!J10 | K16: ='Assumptions'!K10 | L16: ='Assumptions'!L10 | M16: ='Assumptions'!M10 | N16: ='Assumptions'!N10 | O16: ='Assumptions'!O10 | P16: ='Assumptions'!P10 | ... R16: ='Assumptions'!R10
D17: 리스(Leasing) | G17: auto_leasing | H17: 백만$ | I17: ='Assumptions'!I11 | J17: ='Assumptions'!J11 | K17: ='Assumptions'!K11 | L17: ='Assumptions'!L11 | M17: ='Assumptions'!M11 | N17: ='Assumptions'!N11 | O17: ='Assumptions'!O11 | P17: ='Assumptions'!P11 | ... R17: ='Assumptions'!R11
D18: 규제크레딧 | G18: reg_credits | H18: 백만$ | I18: ='Assumptions'!I12 | J18: ='Assumptions'!J12 | K18: ='Assumptions'!K12 | L18: ='Assumptions'!L12 | M18: ='Assumptions'!M12 | N18: ='Assumptions'!N12 | O18: ='Assumptions'!O12 | P18: ='Assumptions'!P12 | ... R18: ='Assumptions'!R12
C19: ② Energy | G19: energy_total | H19: 백만$ | I19: =(I20*I21) | J19: =(J20*J21) | K19: =(K20*K21) | L19: =(L20*L21) | M19: =(M20*M21) | N19: =(N20*N21) | O19: =(O20*O21) | P19: =(P20*P21) | ... R19: =(R20*R21)
D20: 저장 배포량 | G20: storage_gwh | H20: GWh | I20: ='Assumptions'!I13 | J20: ='Assumptions'!J13 | K20: ='Assumptions'!K13 | L20: ='Assumptions'!L13 | M20: ='Assumptions'!M13 | N20: ='Assumptions'!N13 | O20: ='Assumptions'!O13 | P20: ='Assumptions'!P13 | ... R20: ='Assumptions'!R13
D21: 단위매출 | G21: energy_rev_per_gwh | H21: 백만$/GWh | I21: ='Assumptions'!I14 | J21: ='Assumptions'!J14 | K21: ='Assumptions'!K14 | L21: ='Assumptions'!L14 | M21: ='Assumptions'!M14 | N21: ='Assumptions'!N14 | O21: ='Assumptions'!O14 | P21: ='Assumptions'!P14 | ... R21: ='Assumptions'!R14
C22: ③ Services | G22: services_total | H22: 백만$ | I22: =(I23*I24) | J22: =(J23*J24) | K22: =(K23*K24) | L22: =(L23*L24) | M22: =(M23*M24) | N22: =(N23*N24) | O22: =(O23*O24) | P22: =(P23*P24) | ... R22: =(R23*R24)
D23: 누적 보유대수 | G23: installed_base | H23: 백만대 | I23: ='Assumptions'!I15 | J23: ='Assumptions'!J15 | K23: ='Assumptions'!K15 | L23: ='Assumptions'!L15 | M23: ='Assumptions'!M15 | N23: ='Assumptions'!N15 | O23: ='Assumptions'!O15 | P23: ='Assumptions'!P15 | ... R23: ='Assumptions'!R15
D24: 대당 연 서비스매출 | G24: service_per_unit | H24: $/대 | I24: ='Assumptions'!I16 | J24: ='Assumptions'!J16 | K24: ='Assumptions'!K16 | L24: ='Assumptions'!L16 | M24: ='Assumptions'!M16 | N24: ='Assumptions'!N16 | O24: ='Assumptions'!O16 | P24: ='Assumptions'!P16 | ... R24: ='Assumptions'!R16

Sheet Formula Audit
B1: Formula Audit
B3: Sheet | C3: ID | D3: Label | E3: Year | F3: Cell | G3: Formula | H3: Type
B4: Model | C4: root | D4: 테슬라 총매출 | E4: 2022 | F4: I5 | G4: =((I6+I19)+I22) | H4: calculation
B5: Model | C5: root | D5: 테슬라 총매출 | E5: 2023 | F5: J5 | G5: =((J6+J19)+J22) | H5: calculation
B6: Model | C6: root | D6: 테슬라 총매출 | E6: 2024 | F6: K5 | G6: =((K6+K19)+K22) | H6: calculation
B7: Model | C7: root | D7: 테슬라 총매출 | E7: 2025 | F7: L5 | G7: =((L6+L19)+L22) | H7: calculation
B8: Model | C8: root | D8: 테슬라 총매출 | E8: 2026 | F8: M5 | G8: =((M6+M19)+M22) | H8: calculation
B9: Model | C9: root | D9: 테슬라 총매출 | E9: 2027 | F9: N5 | G9: =((N6+N19)+N22) | H9: calculation
B10: Model | C10: root | D10: 테슬라 총매출 | E10: 2028 | F10: O5 | G10: =((O6+O19)+O22) | H10: calculation
B11: Model | C11: root | D11: 테슬라 총매출 | E11: 2029 | F11: P5 | G11: =((P6+P19)+P22) | H11: calculation
B12: Model | C12: root | D12: 테슬라 총매출 | E12: 2030 | F12: Q5 | G12: =((Q6+Q19)+Q22) | H12: calculation
B13: Model | C13: root | D13: 테슬라 총매출 | E13: 2031 | F13: R5 | G13: =((R6+R19)+R22) | H13: calculation
B14: Model | C14: auto_total | D14: ① Automotive | E14: 2022 | F14: I6 | G14: =((I7+I17)+I18) | H14: calculation
B15: Model | C15: auto_total | D15: ① Automotive | E15: 2023 | F15: J6 | G15: =((J7+J17)+J18) | H15: calculation
B16: Model | C16: auto_total | D16: ① Automotive | E16: 2024 | F16: K6 | G16: =((K7+K17)+K18) | H16: calculation
B17: Model | C17: auto_total | D17: ① Automotive | E17: 2025 | F17: L6 | G17: =((L7+L17)+L18) | H17: calculation
B18: Model | C18: auto_total | D18: ① Automotive | E18: 2026 | F18: M6 | G18: =((M7+M17)+M18) | H18: calculation
B19: Model | C19: auto_total | D19: ① Automotive | E19: 2027 | F19: N6 | G19: =((N7+N17)+N18) | H19: calculation
B20: Model | C20: auto_total | D20: ① Automotive | E20: 2028 | F20: O6 | G20: =((O7+O17)+O18) | H20: calculation
B21: Model | C21: auto_total | D21: ① Automotive | E21: 2029 | F21: P6 | G21: =((P7+P17)+P18) | H21: calculation
B22: Model | C22: auto_total | D22: ① Automotive | E22: 2030 | F22: Q6 | G22: =((Q7+Q17)+Q18) | H22: calculation
B23: Model | C23: auto_total | D23: ① Automotive | E23: 2031 | F23: R6 | G23: =((R7+R17)+R18) | H23: calculation
B24: Model | C24: auto_sales | D24: 차량판매 | E24: 2022 | F24: I7 | G24: =((I8+I11)+I14) | H24: calculation
B25: Model | C25: auto_sales | D25: 차량판매 | E25: 2023 | F25: J7 | G25: =((J8+J11)+J14) | H25: calculation
B26: Model | C26: auto_sales | D26: 차량판매 | E26: 2024 | F26: K7 | G26: =((K8+K11)+K14) | H26: calculation
B27: Model | C27: auto_sales | D27: 차량판매 | E27: 2025 | F27: L7 | G27: =((L8+L11)+L14) | H27: calculation
B28: Model | C28: auto_sales | D28: 차량판매 | E28: 2026 | F28: M7 | G28: =((M8+M11)+M14) | H28: calculation
B29: Model | C29: auto_sales | D29: 차량판매 | E29: 2027 | F29: N7 | G29: =((N8+N11)+N14) | H29: calculation
B30: Model | C30: auto_sales | D30: 차량판매 | E30: 2028 | F30: O7 | G30: =((O8+O11)+O14) | H30: calculation
B31: Model | C31: auto_sales | D31: 차량판매 | E31: 2029 | F31: P7 | G31: =((P8+P11)+P14) | H31: calculation
B32: Model | C32: auto_sales | D32: 차량판매 | E32: 2030 | F32: Q7 | G32: =((Q8+Q11)+Q14) | H32: calculation
B33: Model | C33: auto_sales | D33: 차량판매 | E33: 2031 | F33: R7 | G33: =((R8+R11)+R14) | H33: calculation
B34: Model | C34: sales_3y | D34: Model 3/Y 매출 | E34: 2022 | F34: I8 | G34: =(I9*I10) | H34: calculation
B35: Model | C35: sales_3y | D35: Model 3/Y 매출 | E35: 2023 | F35: J8 | G35: =(J9*J10) | H35: calculation
B36: Model | C36: sales_3y | D36: Model 3/Y 매출 | E36: 2024 | F36: K8 | G36: =(K9*K10) | H36: calculation
B37: Model | C37: sales_3y | D37: Model 3/Y 매출 | E37: 2025 | F37: L8 | G37: =(L9*L10) | H37: calculation
B38: Model | C38: sales_3y | D38: Model 3/Y 매출 | E38: 2026 | F38: M8 | G38: =(M9*M10) | H38: calculation
B39: Model | C39: sales_3y | D39: Model 3/Y 매출 | E39: 2027 | F39: N8 | G39: =(N9*N10) | H39: calculation
B40: Model | C40: sales_3y | D40: Model 3/Y 매출 | E40: 2028 | F40: O8 | G40: =(O9*O10) | H40: calculation
B41: Model | C41: sales_3y | D41: Model 3/Y 매출 | E41: 2029 | F41: P8 | G41: =(P9*P10) | H41: calculation
...

Sheet Structure
B1: Structure
B3: ID | C3: Label | D3: Parent | E3: Level | F3: Type | G3: Formula | H3: Unit | I3: Description
B4: root | C4: 테슬라 총매출 | E4: 0 | F4: computed | G4: auto_total + energy_total + services_total | H4: 백만$ | I4: Tesla 총매출 = ① Automotive + ② Energy + ③ Services. 2025 실적 94,827. (비용·영업이익은 별도 단계)
B5: auto_total | C5: ① Automotive | D5: root | E5: 1 | F5: computed | G5: auto_sales + auto_leasing + reg_credits | H5: 백만$ | I5: 자동차 세그먼트. 2025 실적 69,526 (차량판매 65,821 + 리스 1,712 + 크레딧 1,993).
B6: auto_sales | C6: 차량판매 | D6: auto_total | E6: 2 | F6: computed | G6: sales_3y + sales_sxc + sales_new | H6: 백만$ | I6: 차량판매 = Model 3/Y + S/X·Cybertruck + 신규 저가모델 매출. 각 모델매출 = 인도량 × ASP. 2025 실적 65,821.
B7: sales_3y | C7: Model 3/Y 매출 | D7: auto_sales | E7: 3 | F7: computed | G7: del_3y * asp_3y | H7: 백만$ | I7: Model 3/Y 매출 = 인도량 × ASP. 차량판매의 주력 볼륨(~95%). 2025 ≈ 62,007.
B8: del_3y | C8: Model 3/Y 인도량 | D8: sales_3y | E8: 4 | F8: input | H8: 천대 | I8: [주관·수요제약] Model 3/Y 인도(천대). 실적: 22) 1,247 23) 1,740 24) 1,704 25) 1,585. FY23 정점 후 둔화. 추정: 시장×점유율 또는 런레이트. 출처 Tesla 분기 인도보고.
B9: asp_3y | C9: Model 3/Y ASP | D9: sales_3y | E9: 4 | F9: input | H9: 천$/대 | I9: [주관] Model 3/Y 대당 ASP(천$). 실적값은 차량판매-기타모델 역산 내재치(가격인하로 $48K→$39K). 추정: 가격·믹스·FX.
B10: sales_sxc | C10: S/X·Cybertruck 매출 | D10: auto_sales | E10: 3 | F10: computed | G10: del_sxc * asp_sxc | H10: 백만$ | I10: S/X·Cybertruck 등 기타모델 매출 = 인도량 × ASP. 고가 틈새. 2025 ≈ 3,814.
B11: del_sxc | C11: S/X·Cybertruck 인도량 | D11: sales_sxc | E11: 4 | F11: input | H11: 천대 | I11: [주관·추세] S/X+Cybertruck 등 기타모델 인도(천대). 실적: 22) 66.7 23) 68.9 24) 85.1 25) 50.9. 틈새, 연 5~7만대.
B12: asp_sxc | C12: S/X·Cybertruck ASP | D12: sales_sxc | E12: 4 | F12: input | H12: 천$/대 | I12: [주관] 고가 모델 대당 ASP(천$). S/X 프리미엄+Cybertruck 믹스. 분해 가정값(공시 미제공).
B13: sales_new | C13: 신규 저가모델 매출 | D13: auto_sales | E13: 3 | F13: computed | G13: del_new * asp_new | H13: 백만$ | I13: 신규 저가모델/Cybercab 매출 = 인도량 × ASP. 실적 0, 출시 후 램프업. 2028 베이스 ≈ 17,050.
B14: del_new | C14: 신규 저가모델 인도량 | D14: sales_new | E14: 4 | F14: input | H14: 천대 | I14: [주관·공급제약·시나리오] 신규 저가모델/Cybercab 인도(천대). 실적 0. 추정: 출시 후 생산 램프업 곡선. 26)100 27)350 28)550(베이스).
B15: asp_new | C15: 신규 저가모델 ASP | D15: sales_new | E15: 4 | F15: input | H15: 천$/대 | I15: [주관] 신규 저가모델 ASP(천$). 저가 포지셔닝 → 블렌디드 ASP 하락 요인. 베이스 ~$32K.
B16: auto_leasing | C16: 리스(Leasing) | D16: auto_total | E16: 2 | F16: input | H16: 백만$ | I16: [주관] 자동차 리스 매출(백만$). 실적: 22) 2,476 23) 2,120 24) 1,827 25) 1,712. 감소세. 출처 10-K/8-K 손익계산서.
B17: reg_credits | C17: 규제크레딧 | D17: auto_total | E17: 2 | F17: input | H17: 백만$ | I17: [주관·외생] 탄소배출권 매출(백만$). 실적: 22) 1,776 23) 1,790 24) 2,763 25) 1,993. 마진≈100%. OBBBA 등 규제축소로 step-down 추정.
B18: energy_total | C18: ② Energy | D18: root | E18: 1 | F18: computed | G18: storage_gwh * energy_rev_per_gwh | H18: 백만$ | I18: 에너지 세그먼트 = 저장 배포량 × 블렌디드 단위매출(솔라·서비스 포함). 2025 실적 12,771. 매년 ~2배 성장축.
B19: storage_gwh | C19: 저장 배포량 | D19: energy_total | E19: 2 | F19: input | H19: GWh | I19: [주관·공급제약] 에너지 저장 배포(GWh). 실적: 22) 6.5 23) 14.7 24) 31.4 25) 46.7. Megafactory capacity×가동률. 가이던스 +50%/yr.
B20: energy_rev_per_gwh | C20: 단위매출 | D20: energy_total | E20: 2 | F20: input | H20: 백만$/GWh | I20: [주관] 블렌디드 단위매출(백만$/GWh = $/kWh). 솔라·에너지서비스 혼입. 스케일·믹스로 하락 추세($601→$273).
B21: services_total | C21: ③ Services | D21: root | E21: 1 | F21: computed | G21: installed_base * service_per_unit | H21: 백만$ | I21: 서비스·기타 = 누적 보유대수 × 대당 연매출. 중고차·부품·슈퍼차저·보험. 2025 실적 12,530. 보유대수 증가에 연동.
B22: installed_base | C22: 누적 보유대수 | D22: services_total | E22: 2 | F22: input | H22: 백만대 | I22: [계산·교차참조] 누적 보유대수(백만대) = 전년누적 + 당해 인도량(①과 연결). 2021말 2.34M 시드. 2025말 ~8.89M. (HTML은 단일패스 엔진 한계로 입력 노드로 적재 — Excel 단계에서 PREV(누적)+인도량/1000 수식으로 자동 배선)
B23: service_per_unit | C23: 대당 연 서비스매출 | D23: services_total | E23: 2 | F23: input | H23: $/대 | I23: [주관] 보유차 1대당 연 서비스매출($). 실적 내재: $1,667→$1,410. 슈퍼차저 개방·FSD 구독은 상방옵션.

Sheet Checks
B1: Checks
B3: Check | C3: Result | D3: Status
B4: Formula cells generated | C4: 80 | D4: OK
B5: Input links generated | C5: 120 | D5: OK
B6: Operating sheets generated | C6: Generic model only | D6: OK
B7: Computed nodes | C7: 8 | D7: OK
B8: Input nodes | C8: 12 | D8: OK
B9: All computed formulas parsed | C9: OK | D9: OK
B10: All inputs centralized in Assumptions | C10: OK | D10: OK
B11: HTML nodes in Structure | C11: 20 | D11: OK

Sheet Metadata
B1: Metadata
B3: Generated by | C3: financial-modeling/framework/build_excel.py
B4: IR version | C4: 1
B5: Nodes | C5: 20
B6: Input nodes | C6: 12
B7: Computed nodes | C7: 8
B8: Formula cells | C8: 80
B9: Input link cells | C9: 120
B10: Years | C10: 2022–2031 (10개)
B11: Policy | C11: Inputs are centralized in Assumptions; operating sheets and Model contain live formulas.
